2019-06-10 00:11:05,234 INFO org.apache.hadoop.yarn.server.resourcemanager.ResourceManager: STARTUP_MSG: 
/************************************************************
STARTUP_MSG: Starting ResourceManager
STARTUP_MSG:   user = hduser
STARTUP_MSG:   host = ubuntu/127.0.1.1
STARTUP_MSG:   args = []
STARTUP_MSG:   version = 2.8.5
STARTUP_MSG:   build = https://git-wip-us.apache.org/repos/asf/hadoop.git -r 0b8464d75227fcee2c6e7f2410377b3d53d3d5f8; compiled by 'jdu' on 2018-09-10T03:32Z
STARTUP_MSG:   java = 1.8.0_211
************************************************************/
2019-06-10 00:11:05,285 INFO org.apache.hadoop.yarn.server.resourcemanager.ResourceManager: registered UNIX signal handlers for [TERM, HUP, INT]
2019-06-10 00:11:06,634 INFO org.apache.hadoop.conf.Configuration: found resource core-site.xml at file:/opt/hadoop/etc/hadoop/core-site.xml
2019-06-10 00:11:07,089 WARN org.apache.hadoop.util.NativeCodeLoader: Unable to load native-hadoop library for your platform... using builtin-java classes where applicable
2019-06-10 00:11:07,245 INFO org.apache.hadoop.security.Groups: clearing userToGroupsMap cache
2019-06-10 00:11:07,846 INFO org.apache.hadoop.conf.Configuration: found resource yarn-site.xml at file:/opt/hadoop/etc/hadoop/yarn-site.xml
2019-06-10 00:11:08,911 INFO org.apache.hadoop.yarn.event.AsyncDispatcher: Registering class org.apache.hadoop.yarn.server.resourcemanager.RMFatalEventType for class org.apache.hadoop.yarn.server.resourcemanager.ResourceManager$RMFatalEventDispatcher
2019-06-10 00:11:10,950 INFO org.apache.hadoop.yarn.server.resourcemanager.security.NMTokenSecretManagerInRM: NMTokenKeyRollingInterval: 86400000ms and NMTokenKeyActivationDelay: 900000ms
2019-06-10 00:11:10,975 INFO org.apache.hadoop.yarn.server.resourcemanager.security.RMContainerTokenSecretManager: ContainerTokenKeyRollingInterval: 86400000ms and ContainerTokenKeyActivationDelay: 900000ms
2019-06-10 00:11:11,012 INFO org.apache.hadoop.yarn.server.resourcemanager.security.AMRMTokenSecretManager: AMRMTokenKeyRollingInterval: 86400000ms and AMRMTokenKeyActivationDelay: 900000 ms
2019-06-10 00:11:11,333 INFO org.apache.hadoop.yarn.event.AsyncDispatcher: Registering class org.apache.hadoop.yarn.server.resourcemanager.recovery.RMStateStoreEventType for class org.apache.hadoop.yarn.server.resourcemanager.recovery.RMStateStore$ForwardingEventHandler
2019-06-10 00:11:11,344 INFO org.apache.hadoop.yarn.event.AsyncDispatcher: Registering class org.apache.hadoop.yarn.server.resourcemanager.NodesListManagerEventType for class org.apache.hadoop.yarn.server.resourcemanager.NodesListManager
2019-06-10 00:11:11,344 INFO org.apache.hadoop.yarn.server.resourcemanager.ResourceManager: Using Scheduler: org.apache.hadoop.yarn.server.resourcemanager.scheduler.capacity.CapacityScheduler
2019-06-10 00:11:11,425 INFO org.apache.hadoop.yarn.event.AsyncDispatcher: Registering class org.apache.hadoop.yarn.server.resourcemanager.scheduler.event.SchedulerEventType for class org.apache.hadoop.yarn.server.resourcemanager.ResourceManager$SchedulerEventDispatcher
2019-06-10 00:11:11,435 INFO org.apache.hadoop.yarn.event.AsyncDispatcher: Registering class org.apache.hadoop.yarn.server.resourcemanager.rmapp.RMAppEventType for class org.apache.hadoop.yarn.server.resourcemanager.ResourceManager$ApplicationEventDispatcher
2019-06-10 00:11:11,439 INFO org.apache.hadoop.yarn.event.AsyncDispatcher: Registering class org.apache.hadoop.yarn.server.resourcemanager.rmapp.attempt.RMAppAttemptEventType for class org.apache.hadoop.yarn.server.resourcemanager.ResourceManager$ApplicationAttemptEventDispatcher
2019-06-10 00:11:11,443 INFO org.apache.hadoop.yarn.event.AsyncDispatcher: Registering class org.apache.hadoop.yarn.server.resourcemanager.rmnode.RMNodeEventType for class org.apache.hadoop.yarn.server.resourcemanager.ResourceManager$NodeEventDispatcher
2019-06-10 00:11:11,728 INFO org.apache.hadoop.metrics2.impl.MetricsConfig: loaded properties from hadoop-metrics2.properties
2019-06-10 00:11:11,987 INFO org.apache.hadoop.metrics2.impl.MetricsSystemImpl: Scheduled Metric snapshot period at 10 second(s).
2019-06-10 00:11:11,987 INFO org.apache.hadoop.metrics2.impl.MetricsSystemImpl: ResourceManager metrics system started
2019-06-10 00:11:12,085 INFO org.apache.hadoop.yarn.event.AsyncDispatcher: Registering class org.apache.hadoop.yarn.server.resourcemanager.RMAppManagerEventType for class org.apache.hadoop.yarn.server.resourcemanager.RMAppManager
2019-06-10 00:11:12,123 INFO org.apache.hadoop.yarn.event.AsyncDispatcher: Registering class org.apache.hadoop.yarn.server.resourcemanager.amlauncher.AMLauncherEventType for class org.apache.hadoop.yarn.server.resourcemanager.amlauncher.ApplicationMasterLauncher
2019-06-10 00:11:12,151 INFO org.apache.hadoop.yarn.server.resourcemanager.RMNMInfo: Registered RMNMInfo MBean
2019-06-10 00:11:12,214 INFO org.apache.hadoop.yarn.security.YarnAuthorizationProvider: org.apache.hadoop.yarn.security.ConfiguredYarnAuthorizer is instiantiated.
2019-06-10 00:11:12,233 INFO org.apache.hadoop.util.HostsFileReader: Refreshing hosts (include/exclude) list
2019-06-10 00:11:12,276 INFO org.apache.hadoop.conf.Configuration: found resource capacity-scheduler.xml at file:/opt/hadoop/etc/hadoop/capacity-scheduler.xml
2019-06-10 00:11:12,651 INFO org.apache.hadoop.yarn.server.resourcemanager.scheduler.capacity.CapacitySchedulerConfiguration: max alloc mb per queue for root is undefined
2019-06-10 00:11:12,651 INFO org.apache.hadoop.yarn.server.resourcemanager.scheduler.capacity.CapacitySchedulerConfiguration: max alloc vcore per queue for root is undefined
2019-06-10 00:11:12,710 INFO org.apache.hadoop.yarn.server.resourcemanager.scheduler.capacity.ParentQueue: root, capacity=1.0, asboluteCapacity=1.0, maxCapacity=1.0, asboluteMaxCapacity=1.0, state=RUNNING, acls=ADMINISTER_QUEUE:*SUBMIT_APP:*, labels=*,, offswitchPerHeartbeatLimit = 1, reservationsContinueLooking=true
2019-06-10 00:11:12,710 INFO org.apache.hadoop.yarn.server.resourcemanager.scheduler.capacity.ParentQueue: Initialized parent-queue root name=root, fullname=root
2019-06-10 00:11:12,761 INFO org.apache.hadoop.yarn.server.resourcemanager.scheduler.capacity.CapacitySchedulerConfiguration: max alloc mb per queue for root.default is undefined
2019-06-10 00:11:12,769 INFO org.apache.hadoop.yarn.server.resourcemanager.scheduler.capacity.CapacitySchedulerConfiguration: max alloc vcore per queue for root.default is undefined
2019-06-10 00:11:12,782 INFO org.apache.hadoop.yarn.server.resourcemanager.scheduler.capacity.LeafQueue: Initializing default
capacity = 1.0 [= (float) configuredCapacity / 100 ]
asboluteCapacity = 1.0 [= parentAbsoluteCapacity * capacity ]
maxCapacity = 1.0 [= configuredMaxCapacity ]
absoluteMaxCapacity = 1.0 [= 1.0 maximumCapacity undefined, (parentAbsoluteMaxCapacity * maximumCapacity) / 100 otherwise ]
userLimit = 100 [= configuredUserLimit ]
userLimitFactor = 1.0 [= configuredUserLimitFactor ]
maxApplications = 10000 [= configuredMaximumSystemApplicationsPerQueue or (int)(configuredMaximumSystemApplications * absoluteCapacity)]
maxApplicationsPerUser = 10000 [= (int)(maxApplications * (userLimit / 100.0f) * userLimitFactor) ]
usedCapacity = 0.0 [= usedResourcesMemory / (clusterResourceMemory * absoluteCapacity)]
absoluteUsedCapacity = 0.0 [= usedResourcesMemory / clusterResourceMemory]
maxAMResourcePerQueuePercent = 0.1 [= configuredMaximumAMResourcePercent ]
minimumAllocationFactor = 0.875 [= (float)(maximumAllocationMemory - minimumAllocationMemory) / maximumAllocationMemory ]
maximumAllocation = <memory:8192, vCores:4> [= configuredMaxAllocation ]
numContainers = 0 [= currentNumContainers ]
state = RUNNING [= configuredState ]
acls = ADMINISTER_QUEUE:*SUBMIT_APP:* [= configuredAcls ]
nodeLocalityDelay = 40
labels=*,
reservationsContinueLooking = true
preemptionDisabled = true
defaultAppPriorityPerQueue = 0
2019-06-10 00:11:12,783 INFO org.apache.hadoop.yarn.server.resourcemanager.scheduler.capacity.CapacityScheduler: Initialized queue: default: capacity=1.0, absoluteCapacity=1.0, usedResources=<memory:0, vCores:0>, usedCapacity=0.0, absoluteUsedCapacity=0.0, numApps=0, numContainers=0
2019-06-10 00:11:12,784 INFO org.apache.hadoop.yarn.server.resourcemanager.scheduler.capacity.CapacityScheduler: Initialized queue: root: numChildQueue= 1, capacity=1.0, absoluteCapacity=1.0, usedResources=<memory:0, vCores:0>usedCapacity=0.0, numApps=0, numContainers=0
2019-06-10 00:11:12,785 INFO org.apache.hadoop.yarn.server.resourcemanager.scheduler.capacity.CapacityScheduler: Initialized root queue root: numChildQueue= 1, capacity=1.0, absoluteCapacity=1.0, usedResources=<memory:0, vCores:0>usedCapacity=0.0, numApps=0, numContainers=0
2019-06-10 00:11:12,785 INFO org.apache.hadoop.yarn.server.resourcemanager.scheduler.capacity.CapacityScheduler: Initialized queue mappings, override: false
2019-06-10 00:11:12,786 INFO org.apache.hadoop.yarn.server.resourcemanager.scheduler.capacity.CapacityScheduler: Initialized CapacityScheduler with calculator=class org.apache.hadoop.yarn.util.resource.DefaultResourceCalculator, minimumAllocation=<<memory:1024, vCores:1>>, maximumAllocation=<<memory:8192, vCores:4>>, asynchronousScheduling=false, asyncScheduleInterval=5ms
2019-06-10 00:11:12,807 INFO org.apache.hadoop.conf.Configuration: dynamic-resources.xml not found
2019-06-10 00:11:12,872 INFO org.apache.hadoop.yarn.server.resourcemanager.metrics.SystemMetricsPublisher: YARN system metrics publishing service is not enabled
2019-06-10 00:11:12,872 INFO org.apache.hadoop.yarn.server.resourcemanager.ResourceManager: Transitioning to active state
2019-06-10 00:11:12,914 INFO org.apache.hadoop.util.JvmPauseMonitor: Starting JVM pause monitor
2019-06-10 00:11:12,949 INFO org.apache.hadoop.yarn.server.resourcemanager.recovery.RMStateStore: Updating AMRMToken
2019-06-10 00:11:12,950 INFO org.apache.hadoop.yarn.server.resourcemanager.security.RMContainerTokenSecretManager: Rolling master-key for container-tokens
2019-06-10 00:11:12,950 INFO org.apache.hadoop.yarn.server.resourcemanager.security.NMTokenSecretManagerInRM: Rolling master-key for nm-tokens
2019-06-10 00:11:12,953 INFO org.apache.hadoop.security.token.delegation.AbstractDelegationTokenSecretManager: Updating the current master key for generating delegation tokens
2019-06-10 00:11:12,954 INFO org.apache.hadoop.yarn.server.resourcemanager.security.RMDelegationTokenSecretManager: storing master key with keyID 1
2019-06-10 00:11:12,954 INFO org.apache.hadoop.yarn.server.resourcemanager.recovery.RMStateStore: Storing RMDTMasterKey.
2019-06-10 00:11:12,958 INFO org.apache.hadoop.security.token.delegation.AbstractDelegationTokenSecretManager: Starting expired delegation token remover thread, tokenRemoverScanInterval=60 min(s)
2019-06-10 00:11:12,958 INFO org.apache.hadoop.security.token.delegation.AbstractDelegationTokenSecretManager: Updating the current master key for generating delegation tokens
2019-06-10 00:11:12,958 INFO org.apache.hadoop.yarn.server.resourcemanager.security.RMDelegationTokenSecretManager: storing master key with keyID 2
2019-06-10 00:11:12,959 INFO org.apache.hadoop.yarn.server.resourcemanager.recovery.RMStateStore: Storing RMDTMasterKey.
2019-06-10 00:11:12,962 INFO org.apache.hadoop.yarn.event.AsyncDispatcher: Registering class org.apache.hadoop.yarn.nodelabels.event.NodeLabelsStoreEventType for class org.apache.hadoop.yarn.nodelabels.CommonNodeLabelsManager$ForwardingEventHandler
2019-06-10 00:11:13,236 INFO org.apache.hadoop.ipc.CallQueueManager: Using callQueue: class java.util.concurrent.LinkedBlockingQueue queueCapacity: 5000 scheduler: class org.apache.hadoop.ipc.DefaultRpcScheduler
2019-06-10 00:11:13,317 INFO org.apache.hadoop.ipc.Server: Starting Socket Reader #1 for port 8031
2019-06-10 00:11:14,219 INFO org.apache.hadoop.yarn.factories.impl.pb.RpcServerFactoryPBImpl: Adding protocol org.apache.hadoop.yarn.server.api.ResourceTrackerPB to the server
2019-06-10 00:11:14,287 INFO org.apache.hadoop.ipc.Server: IPC Server listener on 8031: starting
2019-06-10 00:11:14,246 INFO org.apache.hadoop.ipc.Server: IPC Server Responder: starting
2019-06-10 00:11:14,670 INFO org.apache.hadoop.ipc.CallQueueManager: Using callQueue: class java.util.concurrent.LinkedBlockingQueue queueCapacity: 5000 scheduler: class org.apache.hadoop.ipc.DefaultRpcScheduler
2019-06-10 00:11:14,704 INFO org.apache.hadoop.ipc.Server: Starting Socket Reader #1 for port 8030
2019-06-10 00:11:14,786 INFO org.apache.hadoop.yarn.factories.impl.pb.RpcServerFactoryPBImpl: Adding protocol org.apache.hadoop.yarn.api.ApplicationMasterProtocolPB to the server
2019-06-10 00:11:14,800 INFO org.apache.hadoop.ipc.Server: IPC Server Responder: starting
2019-06-10 00:11:14,838 INFO org.apache.hadoop.ipc.Server: IPC Server listener on 8030: starting
2019-06-10 00:11:16,165 INFO org.apache.hadoop.ipc.CallQueueManager: Using callQueue: class java.util.concurrent.LinkedBlockingQueue queueCapacity: 5000 scheduler: class org.apache.hadoop.ipc.DefaultRpcScheduler
2019-06-10 00:11:16,168 INFO org.apache.hadoop.ipc.Server: Starting Socket Reader #1 for port 8032
2019-06-10 00:11:16,186 INFO org.apache.hadoop.yarn.factories.impl.pb.RpcServerFactoryPBImpl: Adding protocol org.apache.hadoop.yarn.api.ApplicationClientProtocolPB to the server
2019-06-10 00:11:16,198 INFO org.apache.hadoop.ipc.Server: IPC Server Responder: starting
2019-06-10 00:11:16,207 INFO org.apache.hadoop.ipc.Server: IPC Server listener on 8032: starting
2019-06-10 00:11:16,330 INFO org.apache.hadoop.yarn.server.resourcemanager.ResourceManager: Transitioned to active state
2019-06-10 00:11:16,688 INFO org.mortbay.log: Logging to org.slf4j.impl.Log4jLoggerAdapter(org.mortbay.log) via org.mortbay.log.Slf4jLog
2019-06-10 00:11:16,709 INFO org.apache.hadoop.security.authentication.server.AuthenticationFilter: Unable to initialize FileSignerSecretProvider, falling back to use random secrets.
2019-06-10 00:11:16,738 INFO org.apache.hadoop.http.HttpRequestLog: Http request log for http.requests.resourcemanager is not defined
2019-06-10 00:11:16,765 INFO org.apache.hadoop.http.HttpServer2: Added global filter 'safety' (class=org.apache.hadoop.http.HttpServer2$QuotingInputFilter)
2019-06-10 00:11:16,784 INFO org.apache.hadoop.http.HttpServer2: Added filter RMAuthenticationFilter (class=org.apache.hadoop.yarn.server.security.http.RMAuthenticationFilter) to context cluster
2019-06-10 00:11:16,784 INFO org.apache.hadoop.http.HttpServer2: Added filter RMAuthenticationFilter (class=org.apache.hadoop.yarn.server.security.http.RMAuthenticationFilter) to context logs
2019-06-10 00:11:16,785 INFO org.apache.hadoop.http.HttpServer2: Added filter RMAuthenticationFilter (class=org.apache.hadoop.yarn.server.security.http.RMAuthenticationFilter) to context static
2019-06-10 00:11:16,786 INFO org.apache.hadoop.http.HttpServer2: Added filter static_user_filter (class=org.apache.hadoop.http.lib.StaticUserWebFilter$StaticUserFilter) to context cluster
2019-06-10 00:11:16,786 INFO org.apache.hadoop.http.HttpServer2: Added filter static_user_filter (class=org.apache.hadoop.http.lib.StaticUserWebFilter$StaticUserFilter) to context logs
2019-06-10 00:11:16,786 INFO org.apache.hadoop.http.HttpServer2: Added filter static_user_filter (class=org.apache.hadoop.http.lib.StaticUserWebFilter$StaticUserFilter) to context static
2019-06-10 00:11:16,801 INFO org.apache.hadoop.http.HttpServer2: adding path spec: /cluster/*
2019-06-10 00:11:16,801 INFO org.apache.hadoop.http.HttpServer2: adding path spec: /ws/*
2019-06-10 00:11:17,901 INFO org.apache.hadoop.yarn.webapp.WebApps: Registered webapp guice modules
2019-06-10 00:11:17,926 INFO org.apache.hadoop.http.HttpServer2: Jetty bound to port 8088
2019-06-10 00:11:17,926 INFO org.mortbay.log: jetty-6.1.26
2019-06-10 00:11:18,382 INFO org.mortbay.log: Extract jar:file:/opt/hadoop/share/hadoop/yarn/hadoop-yarn-common-2.8.5.jar!/webapps/cluster to /tmp/Jetty_0_0_0_0_8088_cluster____u0rgz3/webapp
2019-06-10 00:11:19,732 INFO org.apache.hadoop.security.token.delegation.AbstractDelegationTokenSecretManager: Updating the current master key for generating delegation tokens
2019-06-10 00:11:19,746 INFO org.apache.hadoop.security.token.delegation.AbstractDelegationTokenSecretManager: Starting expired delegation token remover thread, tokenRemoverScanInterval=60 min(s)
2019-06-10 00:11:19,762 INFO org.apache.hadoop.security.token.delegation.AbstractDelegationTokenSecretManager: Updating the current master key for generating delegation tokens
2019-06-10 00:11:27,496 INFO org.mortbay.log: Started HttpServer2$SelectChannelConnectorWithSafeStartup@0.0.0.0:8088
2019-06-10 00:11:27,522 INFO org.apache.hadoop.yarn.webapp.WebApps: Web app cluster started at 8088
2019-06-10 00:11:28,062 INFO org.apache.hadoop.ipc.CallQueueManager: Using callQueue: class java.util.concurrent.LinkedBlockingQueue queueCapacity: 100 scheduler: class org.apache.hadoop.ipc.DefaultRpcScheduler
2019-06-10 00:11:28,071 INFO org.apache.hadoop.ipc.Server: Starting Socket Reader #1 for port 8033
2019-06-10 00:11:28,106 INFO org.apache.hadoop.yarn.factories.impl.pb.RpcServerFactoryPBImpl: Adding protocol org.apache.hadoop.yarn.server.api.ResourceManagerAdministrationProtocolPB to the server
2019-06-10 00:11:28,106 INFO org.apache.hadoop.ipc.Server: IPC Server Responder: starting
2019-06-10 00:11:28,108 INFO org.apache.hadoop.ipc.Server: IPC Server listener on 8033: starting
2019-06-10 00:11:29,547 INFO org.apache.hadoop.yarn.server.resourcemanager.ResourceTrackerService: NodeManager from node ubuntu(cmPort: 40311 httpPort: 8042) registered with capability: <memory:8192, vCores:8>, assigned nodeId ubuntu:40311
2019-06-10 00:11:29,572 INFO org.apache.hadoop.yarn.server.resourcemanager.rmnode.RMNodeImpl: ubuntu:40311 Node Transitioned from NEW to RUNNING
2019-06-10 00:11:29,617 INFO org.apache.hadoop.yarn.server.resourcemanager.scheduler.capacity.CapacityScheduler: Added node ubuntu:40311 clusterResource: <memory:8192, vCores:8>
2019-06-10 00:14:02,299 INFO org.apache.hadoop.yarn.server.resourcemanager.RMAuditLogger: USER=dr.who	OPERATION=Get Applications Request	TARGET=ClientRMService	RESULT=SUCCESS
2019-06-10 00:21:12,277 INFO org.apache.hadoop.yarn.server.resourcemanager.scheduler.AbstractYarnScheduler: Release request cache is cleaned up
2019-06-10 01:47:25,704 INFO org.apache.hadoop.util.JvmPauseMonitor: Detected pause in JVM or host machine (eg GC): pause of approximately 1013ms
GC pool 'PS Scavenge' had collection(s): count=1 time=1021ms
2019-06-10 04:18:50,209 INFO org.apache.hadoop.yarn.server.resourcemanager.ClientRMService: Allocated new applicationId: 1
2019-06-10 04:19:00,602 INFO org.apache.hadoop.yarn.server.resourcemanager.scheduler.capacity.CapacityScheduler: Application 'application_1560150672880_0001' is submitted without priority hence considering default queue/cluster priority: 0
2019-06-10 04:19:00,604 INFO org.apache.hadoop.yarn.server.resourcemanager.scheduler.capacity.CapacityScheduler: Priority '0' is acceptable in queue : default for application: application_1560150672880_0001 for the user: hduser
2019-06-10 04:19:00,910 INFO org.apache.hadoop.yarn.server.resourcemanager.ClientRMService: Application with id 1 submitted by user hduser
2019-06-10 04:19:00,913 INFO org.apache.hadoop.yarn.server.resourcemanager.RMAuditLogger: USER=hduser	IP=127.0.0.1	OPERATION=Submit Application Request	TARGET=ClientRMService	RESULT=SUCCESS	APPID=application_1560150672880_0001	CALLERCONTEXT=CLI
2019-06-10 04:19:00,916 INFO org.apache.hadoop.yarn.server.resourcemanager.rmapp.RMAppImpl: Storing application with id application_1560150672880_0001
2019-06-10 04:19:01,099 INFO org.apache.hadoop.yarn.server.resourcemanager.rmapp.RMAppImpl: application_1560150672880_0001 State change from NEW to NEW_SAVING on event=START
2019-06-10 04:19:01,104 INFO org.apache.hadoop.yarn.server.resourcemanager.recovery.RMStateStore: Storing info for app: application_1560150672880_0001
2019-06-10 04:19:01,360 INFO org.apache.hadoop.yarn.server.resourcemanager.rmapp.RMAppImpl: application_1560150672880_0001 State change from NEW_SAVING to SUBMITTED on event=APP_NEW_SAVED
2019-06-10 04:19:01,404 INFO org.apache.hadoop.yarn.server.resourcemanager.scheduler.capacity.ParentQueue: Application added - appId: application_1560150672880_0001 user: hduser leaf-queue of parent: root #applications: 1
2019-06-10 04:19:01,422 INFO org.apache.hadoop.yarn.server.resourcemanager.scheduler.capacity.CapacityScheduler: Accepted application application_1560150672880_0001 from user: hduser, in queue: default
2019-06-10 04:19:01,559 INFO org.apache.hadoop.yarn.server.resourcemanager.rmapp.RMAppImpl: application_1560150672880_0001 State change from SUBMITTED to ACCEPTED on event=APP_ACCEPTED
2019-06-10 04:19:02,029 INFO org.apache.hadoop.yarn.server.resourcemanager.ApplicationMasterService: Registering app attempt : appattempt_1560150672880_0001_000001
2019-06-10 04:19:02,044 INFO org.apache.hadoop.yarn.server.resourcemanager.rmapp.attempt.RMAppAttemptImpl: appattempt_1560150672880_0001_000001 State change from NEW to SUBMITTED
2019-06-10 04:19:02,410 WARN org.apache.hadoop.yarn.server.resourcemanager.scheduler.capacity.LeafQueue: maximum-am-resource-percent is insufficient to start a single application in queue, it is likely set too low. skipping enforcement to allow at least one application to start
2019-06-10 04:19:02,412 WARN org.apache.hadoop.yarn.server.resourcemanager.scheduler.capacity.LeafQueue: maximum-am-resource-percent is insufficient to start a single application in queue for user, it is likely set too low. skipping enforcement to allow at least one application to start
2019-06-10 04:19:02,440 INFO org.apache.hadoop.yarn.server.resourcemanager.scheduler.capacity.LeafQueue: Application application_1560150672880_0001 from user: hduser activated in queue: default
2019-06-10 04:19:02,440 INFO org.apache.hadoop.yarn.server.resourcemanager.scheduler.capacity.LeafQueue: Application added - appId: application_1560150672880_0001 user: hduser, leaf-queue: default #user-pending-applications: 0 #user-active-applications: 1 #queue-pending-applications: 0 #queue-active-applications: 1
2019-06-10 04:19:02,441 INFO org.apache.hadoop.yarn.server.resourcemanager.scheduler.capacity.CapacityScheduler: Added Application Attempt appattempt_1560150672880_0001_000001 to scheduler from user hduser in queue default
2019-06-10 04:19:02,456 INFO org.apache.hadoop.yarn.server.resourcemanager.rmapp.attempt.RMAppAttemptImpl: appattempt_1560150672880_0001_000001 State change from SUBMITTED to SCHEDULED
2019-06-10 04:19:03,590 INFO org.apache.hadoop.yarn.server.resourcemanager.rmcontainer.RMContainerImpl: container_1560150672880_0001_01_000001 Container Transitioned from NEW to ALLOCATED
2019-06-10 04:19:03,590 INFO org.apache.hadoop.yarn.server.resourcemanager.RMAuditLogger: USER=hduser	OPERATION=AM Allocated Container	TARGET=SchedulerApp	RESULT=SUCCESS	APPID=application_1560150672880_0001	CONTAINERID=container_1560150672880_0001_01_000001
2019-06-10 04:19:03,595 INFO org.apache.hadoop.yarn.server.resourcemanager.scheduler.SchedulerNode: Assigned container container_1560150672880_0001_01_000001 of capacity <memory:2048, vCores:1> on host ubuntu:40311, which has 1 containers, <memory:2048, vCores:1> used and <memory:6144, vCores:7> available after allocation
2019-06-10 04:19:03,597 INFO org.apache.hadoop.yarn.server.resourcemanager.scheduler.capacity.allocator.AbstractContainerAllocator: assignedContainer application attempt=appattempt_1560150672880_0001_000001 container=container_1560150672880_0001_01_000001 queue=org.apache.hadoop.yarn.server.resourcemanager.scheduler.capacity.allocator.RegularContainerAllocator@4d651435 clusterResource=<memory:8192, vCores:8> type=OFF_SWITCH requestedPartition=
2019-06-10 04:19:03,818 INFO org.apache.hadoop.yarn.server.resourcemanager.security.NMTokenSecretManagerInRM: Sending NMToken for nodeId : ubuntu:40311 for container : container_1560150672880_0001_01_000001
2019-06-10 04:19:03,889 INFO org.apache.hadoop.yarn.server.resourcemanager.rmcontainer.RMContainerImpl: container_1560150672880_0001_01_000001 Container Transitioned from ALLOCATED to ACQUIRED
2019-06-10 04:19:03,892 INFO org.apache.hadoop.yarn.server.resourcemanager.security.NMTokenSecretManagerInRM: Clear node set for appattempt_1560150672880_0001_000001
2019-06-10 04:19:03,894 INFO org.apache.hadoop.yarn.server.resourcemanager.rmapp.attempt.RMAppAttemptImpl: Storing attempt: AppId: application_1560150672880_0001 AttemptId: appattempt_1560150672880_0001_000001 MasterContainer: Container: [ContainerId: container_1560150672880_0001_01_000001, Version: 0, NodeId: ubuntu:40311, NodeHttpAddress: ubuntu:8042, Resource: <memory:2048, vCores:1>, Priority: 0, Token: Token { kind: ContainerToken, service: 127.0.1.1:40311 }, ]
2019-06-10 04:19:03,895 INFO org.apache.hadoop.yarn.server.resourcemanager.scheduler.capacity.ParentQueue: Re-sorting assigned queue: root.default stats: default: capacity=1.0, absoluteCapacity=1.0, usedResources=<memory:2048, vCores:1>, usedCapacity=0.25, absoluteUsedCapacity=0.25, numApps=1, numContainers=1
2019-06-10 04:19:03,896 INFO org.apache.hadoop.yarn.server.resourcemanager.scheduler.capacity.ParentQueue: assignedContainer queue=root usedCapacity=0.25 absoluteUsedCapacity=0.25 used=<memory:2048, vCores:1> cluster=<memory:8192, vCores:8>
2019-06-10 04:19:04,009 INFO org.apache.hadoop.yarn.server.resourcemanager.rmapp.attempt.RMAppAttemptImpl: appattempt_1560150672880_0001_000001 State change from SCHEDULED to ALLOCATED_SAVING
2019-06-10 04:19:04,074 INFO org.apache.hadoop.yarn.server.resourcemanager.rmapp.attempt.RMAppAttemptImpl: appattempt_1560150672880_0001_000001 State change from ALLOCATED_SAVING to ALLOCATED
2019-06-10 04:19:04,116 INFO org.apache.hadoop.yarn.server.resourcemanager.amlauncher.AMLauncher: Launching masterappattempt_1560150672880_0001_000001
2019-06-10 04:19:04,935 INFO org.apache.hadoop.yarn.server.resourcemanager.amlauncher.AMLauncher: Setting up container Container: [ContainerId: container_1560150672880_0001_01_000001, Version: 0, NodeId: ubuntu:40311, NodeHttpAddress: ubuntu:8042, Resource: <memory:2048, vCores:1>, Priority: 0, Token: Token { kind: ContainerToken, service: 127.0.1.1:40311 }, ] for AM appattempt_1560150672880_0001_000001
2019-06-10 04:19:04,943 INFO org.apache.hadoop.yarn.server.resourcemanager.security.AMRMTokenSecretManager: Create AMRMToken for ApplicationAttempt: appattempt_1560150672880_0001_000001
2019-06-10 04:19:05,020 INFO org.apache.hadoop.yarn.server.resourcemanager.security.AMRMTokenSecretManager: Creating password for appattempt_1560150672880_0001_000001
2019-06-10 04:19:09,537 INFO org.apache.hadoop.yarn.server.resourcemanager.amlauncher.AMLauncher: Done launching container Container: [ContainerId: container_1560150672880_0001_01_000001, Version: 0, NodeId: ubuntu:40311, NodeHttpAddress: ubuntu:8042, Resource: <memory:2048, vCores:1>, Priority: 0, Token: Token { kind: ContainerToken, service: 127.0.1.1:40311 }, ] for AM appattempt_1560150672880_0001_000001
2019-06-10 04:19:09,538 INFO org.apache.hadoop.yarn.server.resourcemanager.rmapp.attempt.RMAppAttemptImpl: appattempt_1560150672880_0001_000001 State change from ALLOCATED to LAUNCHED
2019-06-10 04:19:12,308 INFO org.apache.hadoop.yarn.server.resourcemanager.rmcontainer.RMContainerImpl: container_1560150672880_0001_01_000001 Container Transitioned from ACQUIRED to RUNNING
2019-06-10 04:19:30,859 INFO SecurityLogger.org.apache.hadoop.ipc.Server: Auth successful for appattempt_1560150672880_0001_000001 (auth:SIMPLE)
2019-06-10 04:19:30,911 INFO org.apache.hadoop.yarn.server.resourcemanager.ApplicationMasterService: AM registration appattempt_1560150672880_0001_000001
2019-06-10 04:19:30,920 INFO org.apache.hadoop.yarn.server.resourcemanager.RMAuditLogger: USER=hduser	IP=127.0.0.1	OPERATION=Register App Master	TARGET=ApplicationMasterService	RESULT=SUCCESS	APPID=application_1560150672880_0001	APPATTEMPTID=appattempt_1560150672880_0001_000001
2019-06-10 04:19:30,921 INFO org.apache.hadoop.yarn.server.resourcemanager.rmapp.attempt.RMAppAttemptImpl: appattempt_1560150672880_0001_000001 State change from LAUNCHED to RUNNING
2019-06-10 04:19:30,921 INFO org.apache.hadoop.yarn.server.resourcemanager.rmapp.RMAppImpl: application_1560150672880_0001 State change from ACCEPTED to RUNNING on event=ATTEMPT_REGISTERED
2019-06-10 04:19:32,699 INFO org.apache.hadoop.yarn.server.resourcemanager.rmcontainer.RMContainerImpl: container_1560150672880_0001_01_000002 Container Transitioned from NEW to ALLOCATED
2019-06-10 04:19:32,700 INFO org.apache.hadoop.yarn.server.resourcemanager.RMAuditLogger: USER=hduser	OPERATION=AM Allocated Container	TARGET=SchedulerApp	RESULT=SUCCESS	APPID=application_1560150672880_0001	CONTAINERID=container_1560150672880_0001_01_000002
2019-06-10 04:19:32,701 INFO org.apache.hadoop.yarn.server.resourcemanager.scheduler.SchedulerNode: Assigned container container_1560150672880_0001_01_000002 of capacity <memory:1024, vCores:1> on host ubuntu:40311, which has 2 containers, <memory:3072, vCores:2> used and <memory:5120, vCores:6> available after allocation
2019-06-10 04:19:32,702 INFO org.apache.hadoop.yarn.server.resourcemanager.scheduler.capacity.allocator.AbstractContainerAllocator: assignedContainer application attempt=appattempt_1560150672880_0001_000001 container=container_1560150672880_0001_01_000002 queue=org.apache.hadoop.yarn.server.resourcemanager.scheduler.capacity.allocator.RegularContainerAllocator@4d651435 clusterResource=<memory:8192, vCores:8> type=OFF_SWITCH requestedPartition=
2019-06-10 04:19:32,703 INFO org.apache.hadoop.yarn.server.resourcemanager.scheduler.capacity.ParentQueue: Re-sorting assigned queue: root.default stats: default: capacity=1.0, absoluteCapacity=1.0, usedResources=<memory:3072, vCores:2>, usedCapacity=0.375, absoluteUsedCapacity=0.375, numApps=1, numContainers=2
2019-06-10 04:19:32,703 INFO org.apache.hadoop.yarn.server.resourcemanager.scheduler.capacity.ParentQueue: assignedContainer queue=root usedCapacity=0.375 absoluteUsedCapacity=0.375 used=<memory:3072, vCores:2> cluster=<memory:8192, vCores:8>
2019-06-10 04:19:33,401 INFO org.apache.hadoop.yarn.server.resourcemanager.security.NMTokenSecretManagerInRM: Sending NMToken for nodeId : ubuntu:40311 for container : container_1560150672880_0001_01_000002
2019-06-10 04:19:33,405 INFO org.apache.hadoop.yarn.server.resourcemanager.rmcontainer.RMContainerImpl: container_1560150672880_0001_01_000002 Container Transitioned from ALLOCATED to ACQUIRED
2019-06-10 04:19:33,707 INFO org.apache.hadoop.yarn.server.resourcemanager.rmcontainer.RMContainerImpl: container_1560150672880_0001_01_000003 Container Transitioned from NEW to ALLOCATED
2019-06-10 04:19:33,709 INFO org.apache.hadoop.yarn.server.resourcemanager.RMAuditLogger: USER=hduser	OPERATION=AM Allocated Container	TARGET=SchedulerApp	RESULT=SUCCESS	APPID=application_1560150672880_0001	CONTAINERID=container_1560150672880_0001_01_000003
2019-06-10 04:19:33,710 INFO org.apache.hadoop.yarn.server.resourcemanager.scheduler.SchedulerNode: Assigned container container_1560150672880_0001_01_000003 of capacity <memory:1024, vCores:1> on host ubuntu:40311, which has 3 containers, <memory:4096, vCores:3> used and <memory:4096, vCores:5> available after allocation
2019-06-10 04:19:33,710 INFO org.apache.hadoop.yarn.server.resourcemanager.scheduler.capacity.allocator.AbstractContainerAllocator: assignedContainer application attempt=appattempt_1560150672880_0001_000001 container=container_1560150672880_0001_01_000003 queue=org.apache.hadoop.yarn.server.resourcemanager.scheduler.capacity.allocator.RegularContainerAllocator@4d651435 clusterResource=<memory:8192, vCores:8> type=OFF_SWITCH requestedPartition=
2019-06-10 04:19:33,711 INFO org.apache.hadoop.yarn.server.resourcemanager.scheduler.capacity.ParentQueue: Re-sorting assigned queue: root.default stats: default: capacity=1.0, absoluteCapacity=1.0, usedResources=<memory:4096, vCores:3>, usedCapacity=0.5, absoluteUsedCapacity=0.5, numApps=1, numContainers=3
2019-06-10 04:19:33,711 INFO org.apache.hadoop.yarn.server.resourcemanager.scheduler.capacity.ParentQueue: assignedContainer queue=root usedCapacity=0.5 absoluteUsedCapacity=0.5 used=<memory:4096, vCores:3> cluster=<memory:8192, vCores:8>
2019-06-10 04:19:34,475 INFO org.apache.hadoop.yarn.server.resourcemanager.rmcontainer.RMContainerImpl: container_1560150672880_0001_01_000003 Container Transitioned from ALLOCATED to ACQUIRED
2019-06-10 04:19:34,712 INFO org.apache.hadoop.yarn.server.resourcemanager.rmcontainer.RMContainerImpl: container_1560150672880_0001_01_000004 Container Transitioned from NEW to ALLOCATED
2019-06-10 04:19:34,712 INFO org.apache.hadoop.yarn.server.resourcemanager.RMAuditLogger: USER=hduser	OPERATION=AM Allocated Container	TARGET=SchedulerApp	RESULT=SUCCESS	APPID=application_1560150672880_0001	CONTAINERID=container_1560150672880_0001_01_000004
2019-06-10 04:19:34,713 INFO org.apache.hadoop.yarn.server.resourcemanager.scheduler.SchedulerNode: Assigned container container_1560150672880_0001_01_000004 of capacity <memory:1024, vCores:1> on host ubuntu:40311, which has 4 containers, <memory:5120, vCores:4> used and <memory:3072, vCores:4> available after allocation
2019-06-10 04:19:34,713 INFO org.apache.hadoop.yarn.server.resourcemanager.scheduler.capacity.allocator.AbstractContainerAllocator: assignedContainer application attempt=appattempt_1560150672880_0001_000001 container=container_1560150672880_0001_01_000004 queue=org.apache.hadoop.yarn.server.resourcemanager.scheduler.capacity.allocator.RegularContainerAllocator@4d651435 clusterResource=<memory:8192, vCores:8> type=OFF_SWITCH requestedPartition=
2019-06-10 04:19:34,715 INFO org.apache.hadoop.yarn.server.resourcemanager.scheduler.capacity.ParentQueue: Re-sorting assigned queue: root.default stats: default: capacity=1.0, absoluteCapacity=1.0, usedResources=<memory:5120, vCores:4>, usedCapacity=0.625, absoluteUsedCapacity=0.625, numApps=1, numContainers=4
2019-06-10 04:19:34,715 INFO org.apache.hadoop.yarn.server.resourcemanager.scheduler.capacity.ParentQueue: assignedContainer queue=root usedCapacity=0.625 absoluteUsedCapacity=0.625 used=<memory:5120, vCores:4> cluster=<memory:8192, vCores:8>
2019-06-10 04:19:35,513 INFO org.apache.hadoop.yarn.server.resourcemanager.rmcontainer.RMContainerImpl: container_1560150672880_0001_01_000002 Container Transitioned from ACQUIRED to RELEASED
2019-06-10 04:19:35,515 INFO org.apache.hadoop.yarn.server.resourcemanager.RMAuditLogger: USER=hduser	IP=127.0.0.1	OPERATION=AM Released Container	TARGET=SchedulerApp	RESULT=SUCCESS	APPID=application_1560150672880_0001	CONTAINERID=container_1560150672880_0001_01_000002
2019-06-10 04:19:35,517 INFO org.apache.hadoop.yarn.server.resourcemanager.scheduler.SchedulerNode: Released container container_1560150672880_0001_01_000002 of capacity <memory:1024, vCores:1> on host ubuntu:40311, which currently has 3 containers, <memory:4096, vCores:3> used and <memory:4096, vCores:5> available, release resources=true
2019-06-10 04:19:35,528 INFO org.apache.hadoop.yarn.server.resourcemanager.rmcontainer.RMContainerImpl: container_1560150672880_0001_01_000003 Container Transitioned from ACQUIRED to RELEASED
2019-06-10 04:19:35,534 INFO org.apache.hadoop.yarn.server.resourcemanager.RMAuditLogger: USER=hduser	IP=127.0.0.1	OPERATION=AM Released Container	TARGET=SchedulerApp	RESULT=SUCCESS	APPID=application_1560150672880_0001	CONTAINERID=container_1560150672880_0001_01_000003
2019-06-10 04:19:35,535 INFO org.apache.hadoop.yarn.server.resourcemanager.scheduler.SchedulerNode: Released container container_1560150672880_0001_01_000003 of capacity <memory:1024, vCores:1> on host ubuntu:40311, which currently has 2 containers, <memory:3072, vCores:2> used and <memory:5120, vCores:6> available, release resources=true
2019-06-10 04:19:35,542 INFO org.apache.hadoop.yarn.server.resourcemanager.rmcontainer.RMContainerImpl: container_1560150672880_0001_01_000004 Container Transitioned from ALLOCATED to ACQUIRED
2019-06-10 04:19:35,720 INFO org.apache.hadoop.yarn.server.resourcemanager.rmcontainer.RMContainerImpl: container_1560150672880_0001_01_000005 Container Transitioned from NEW to ALLOCATED
2019-06-10 04:19:35,721 INFO org.apache.hadoop.yarn.server.resourcemanager.RMAuditLogger: USER=hduser	OPERATION=AM Allocated Container	TARGET=SchedulerApp	RESULT=SUCCESS	APPID=application_1560150672880_0001	CONTAINERID=container_1560150672880_0001_01_000005
2019-06-10 04:19:35,721 INFO org.apache.hadoop.yarn.server.resourcemanager.scheduler.SchedulerNode: Assigned container container_1560150672880_0001_01_000005 of capacity <memory:1024, vCores:1> on host ubuntu:40311, which has 3 containers, <memory:4096, vCores:3> used and <memory:4096, vCores:5> available after allocation
2019-06-10 04:19:35,722 INFO org.apache.hadoop.yarn.server.resourcemanager.scheduler.capacity.allocator.AbstractContainerAllocator: assignedContainer application attempt=appattempt_1560150672880_0001_000001 container=container_1560150672880_0001_01_000005 queue=org.apache.hadoop.yarn.server.resourcemanager.scheduler.capacity.allocator.RegularContainerAllocator@4d651435 clusterResource=<memory:8192, vCores:8> type=OFF_SWITCH requestedPartition=
2019-06-10 04:19:35,723 INFO org.apache.hadoop.yarn.server.resourcemanager.scheduler.capacity.ParentQueue: Re-sorting assigned queue: root.default stats: default: capacity=1.0, absoluteCapacity=1.0, usedResources=<memory:4096, vCores:3>, usedCapacity=0.5, absoluteUsedCapacity=0.5, numApps=1, numContainers=3
2019-06-10 04:19:35,723 INFO org.apache.hadoop.yarn.server.resourcemanager.scheduler.capacity.ParentQueue: assignedContainer queue=root usedCapacity=0.5 absoluteUsedCapacity=0.5 used=<memory:4096, vCores:3> cluster=<memory:8192, vCores:8>
2019-06-10 04:19:36,560 INFO org.apache.hadoop.yarn.server.resourcemanager.rmcontainer.RMContainerImpl: container_1560150672880_0001_01_000004 Container Transitioned from ACQUIRED to RELEASED
2019-06-10 04:19:36,561 INFO org.apache.hadoop.yarn.server.resourcemanager.RMAuditLogger: USER=hduser	IP=127.0.0.1	OPERATION=AM Released Container	TARGET=SchedulerApp	RESULT=SUCCESS	APPID=application_1560150672880_0001	CONTAINERID=container_1560150672880_0001_01_000004
2019-06-10 04:19:36,562 INFO org.apache.hadoop.yarn.server.resourcemanager.scheduler.SchedulerNode: Released container container_1560150672880_0001_01_000004 of capacity <memory:1024, vCores:1> on host ubuntu:40311, which currently has 2 containers, <memory:3072, vCores:2> used and <memory:5120, vCores:6> available, release resources=true
2019-06-10 04:19:36,587 INFO org.apache.hadoop.yarn.server.resourcemanager.rmcontainer.RMContainerImpl: container_1560150672880_0001_01_000005 Container Transitioned from ALLOCATED to ACQUIRED
2019-06-10 04:19:36,588 INFO org.apache.hadoop.yarn.server.resourcemanager.ApplicationMasterService: blacklist are updated in Scheduler.blacklistAdditions: [ubuntu], blacklistRemovals: []
2019-06-10 04:19:37,610 INFO org.apache.hadoop.yarn.server.resourcemanager.rmcontainer.RMContainerImpl: container_1560150672880_0001_01_000005 Container Transitioned from ACQUIRED to RELEASED
2019-06-10 04:19:37,611 INFO org.apache.hadoop.yarn.server.resourcemanager.RMAuditLogger: USER=hduser	IP=127.0.0.1	OPERATION=AM Released Container	TARGET=SchedulerApp	RESULT=SUCCESS	APPID=application_1560150672880_0001	CONTAINERID=container_1560150672880_0001_01_000005
2019-06-10 04:19:37,612 INFO org.apache.hadoop.yarn.server.resourcemanager.scheduler.SchedulerNode: Released container container_1560150672880_0001_01_000005 of capacity <memory:1024, vCores:1> on host ubuntu:40311, which currently has 1 containers, <memory:2048, vCores:1> used and <memory:6144, vCores:7> available, release resources=true
2019-06-10 04:19:37,614 INFO org.apache.hadoop.yarn.server.resourcemanager.ApplicationMasterService: blacklist are updated in Scheduler.blacklistAdditions: [], blacklistRemovals: [ubuntu]
2019-06-10 04:19:37,742 INFO org.apache.hadoop.yarn.server.resourcemanager.rmcontainer.RMContainerImpl: container_1560150672880_0001_01_000006 Container Transitioned from NEW to ALLOCATED
2019-06-10 04:19:37,743 INFO org.apache.hadoop.yarn.server.resourcemanager.RMAuditLogger: USER=hduser	OPERATION=AM Allocated Container	TARGET=SchedulerApp	RESULT=SUCCESS	APPID=application_1560150672880_0001	CONTAINERID=container_1560150672880_0001_01_000006
2019-06-10 04:19:37,743 INFO org.apache.hadoop.yarn.server.resourcemanager.scheduler.SchedulerNode: Assigned container container_1560150672880_0001_01_000006 of capacity <memory:1024, vCores:1> on host ubuntu:40311, which has 2 containers, <memory:3072, vCores:2> used and <memory:5120, vCores:6> available after allocation
2019-06-10 04:19:37,744 INFO org.apache.hadoop.yarn.server.resourcemanager.scheduler.capacity.allocator.AbstractContainerAllocator: assignedContainer application attempt=appattempt_1560150672880_0001_000001 container=container_1560150672880_0001_01_000006 queue=org.apache.hadoop.yarn.server.resourcemanager.scheduler.capacity.allocator.RegularContainerAllocator@4d651435 clusterResource=<memory:8192, vCores:8> type=OFF_SWITCH requestedPartition=
2019-06-10 04:19:37,745 INFO org.apache.hadoop.yarn.server.resourcemanager.scheduler.capacity.ParentQueue: Re-sorting assigned queue: root.default stats: default: capacity=1.0, absoluteCapacity=1.0, usedResources=<memory:3072, vCores:2>, usedCapacity=0.375, absoluteUsedCapacity=0.375, numApps=1, numContainers=2
2019-06-10 04:19:37,746 INFO org.apache.hadoop.yarn.server.resourcemanager.scheduler.capacity.ParentQueue: assignedContainer queue=root usedCapacity=0.375 absoluteUsedCapacity=0.375 used=<memory:3072, vCores:2> cluster=<memory:8192, vCores:8>
2019-06-10 04:19:38,660 INFO org.apache.hadoop.yarn.server.resourcemanager.rmcontainer.RMContainerImpl: container_1560150672880_0001_01_000006 Container Transitioned from ALLOCATED to ACQUIRED
2019-06-10 04:19:38,760 INFO org.apache.hadoop.yarn.server.resourcemanager.rmcontainer.RMContainerImpl: container_1560150672880_0001_01_000007 Container Transitioned from NEW to ALLOCATED
2019-06-10 04:19:38,760 INFO org.apache.hadoop.yarn.server.resourcemanager.RMAuditLogger: USER=hduser	OPERATION=AM Allocated Container	TARGET=SchedulerApp	RESULT=SUCCESS	APPID=application_1560150672880_0001	CONTAINERID=container_1560150672880_0001_01_000007
2019-06-10 04:19:38,760 INFO org.apache.hadoop.yarn.server.resourcemanager.scheduler.SchedulerNode: Assigned container container_1560150672880_0001_01_000007 of capacity <memory:1024, vCores:1> on host ubuntu:40311, which has 3 containers, <memory:4096, vCores:3> used and <memory:4096, vCores:5> available after allocation
2019-06-10 04:19:38,760 INFO org.apache.hadoop.yarn.server.resourcemanager.scheduler.capacity.allocator.AbstractContainerAllocator: assignedContainer application attempt=appattempt_1560150672880_0001_000001 container=container_1560150672880_0001_01_000007 queue=org.apache.hadoop.yarn.server.resourcemanager.scheduler.capacity.allocator.RegularContainerAllocator@4d651435 clusterResource=<memory:8192, vCores:8> type=OFF_SWITCH requestedPartition=
2019-06-10 04:19:38,760 INFO org.apache.hadoop.yarn.server.resourcemanager.scheduler.capacity.ParentQueue: Re-sorting assigned queue: root.default stats: default: capacity=1.0, absoluteCapacity=1.0, usedResources=<memory:4096, vCores:3>, usedCapacity=0.5, absoluteUsedCapacity=0.5, numApps=1, numContainers=3
2019-06-10 04:19:38,761 INFO org.apache.hadoop.yarn.server.resourcemanager.scheduler.capacity.ParentQueue: assignedContainer queue=root usedCapacity=0.5 absoluteUsedCapacity=0.5 used=<memory:4096, vCores:3> cluster=<memory:8192, vCores:8>
2019-06-10 04:19:39,684 INFO org.apache.hadoop.yarn.server.resourcemanager.rmcontainer.RMContainerImpl: container_1560150672880_0001_01_000006 Container Transitioned from ACQUIRED to RELEASED
2019-06-10 04:19:39,693 INFO org.apache.hadoop.yarn.server.resourcemanager.RMAuditLogger: USER=hduser	IP=127.0.0.1	OPERATION=AM Released Container	TARGET=SchedulerApp	RESULT=SUCCESS	APPID=application_1560150672880_0001	CONTAINERID=container_1560150672880_0001_01_000006
2019-06-10 04:19:39,698 INFO org.apache.hadoop.yarn.server.resourcemanager.scheduler.SchedulerNode: Released container container_1560150672880_0001_01_000006 of capacity <memory:1024, vCores:1> on host ubuntu:40311, which currently has 2 containers, <memory:3072, vCores:2> used and <memory:5120, vCores:6> available, release resources=true
2019-06-10 04:19:39,724 INFO org.apache.hadoop.yarn.server.resourcemanager.rmcontainer.RMContainerImpl: container_1560150672880_0001_01_000007 Container Transitioned from ALLOCATED to ACQUIRED
2019-06-10 04:19:39,782 INFO org.apache.hadoop.yarn.server.resourcemanager.rmcontainer.RMContainerImpl: container_1560150672880_0001_01_000008 Container Transitioned from NEW to ALLOCATED
2019-06-10 04:19:39,783 INFO org.apache.hadoop.yarn.server.resourcemanager.RMAuditLogger: USER=hduser	OPERATION=AM Allocated Container	TARGET=SchedulerApp	RESULT=SUCCESS	APPID=application_1560150672880_0001	CONTAINERID=container_1560150672880_0001_01_000008
2019-06-10 04:19:39,784 INFO org.apache.hadoop.yarn.server.resourcemanager.scheduler.SchedulerNode: Assigned container container_1560150672880_0001_01_000008 of capacity <memory:1024, vCores:1> on host ubuntu:40311, which has 3 containers, <memory:4096, vCores:3> used and <memory:4096, vCores:5> available after allocation
2019-06-10 04:19:39,785 INFO org.apache.hadoop.yarn.server.resourcemanager.scheduler.capacity.allocator.AbstractContainerAllocator: assignedContainer application attempt=appattempt_1560150672880_0001_000001 container=container_1560150672880_0001_01_000008 queue=org.apache.hadoop.yarn.server.resourcemanager.scheduler.capacity.allocator.RegularContainerAllocator@4d651435 clusterResource=<memory:8192, vCores:8> type=OFF_SWITCH requestedPartition=
2019-06-10 04:19:39,794 INFO org.apache.hadoop.yarn.server.resourcemanager.scheduler.capacity.ParentQueue: Re-sorting assigned queue: root.default stats: default: capacity=1.0, absoluteCapacity=1.0, usedResources=<memory:4096, vCores:3>, usedCapacity=0.5, absoluteUsedCapacity=0.5, numApps=1, numContainers=3
2019-06-10 04:19:39,795 INFO org.apache.hadoop.yarn.server.resourcemanager.scheduler.capacity.ParentQueue: assignedContainer queue=root usedCapacity=0.5 absoluteUsedCapacity=0.5 used=<memory:4096, vCores:3> cluster=<memory:8192, vCores:8>
2019-06-10 04:19:40,744 INFO org.apache.hadoop.yarn.server.resourcemanager.rmcontainer.RMContainerImpl: container_1560150672880_0001_01_000007 Container Transitioned from ACQUIRED to RELEASED
2019-06-10 04:19:40,746 INFO org.apache.hadoop.yarn.server.resourcemanager.RMAuditLogger: USER=hduser	IP=127.0.0.1	OPERATION=AM Released Container	TARGET=SchedulerApp	RESULT=SUCCESS	APPID=application_1560150672880_0001	CONTAINERID=container_1560150672880_0001_01_000007
2019-06-10 04:19:40,747 INFO org.apache.hadoop.yarn.server.resourcemanager.scheduler.SchedulerNode: Released container container_1560150672880_0001_01_000007 of capacity <memory:1024, vCores:1> on host ubuntu:40311, which currently has 2 containers, <memory:3072, vCores:2> used and <memory:5120, vCores:6> available, release resources=true
2019-06-10 04:19:40,875 INFO org.apache.hadoop.yarn.server.resourcemanager.rmcontainer.RMContainerImpl: container_1560150672880_0001_01_000008 Container Transitioned from ALLOCATED to ACQUIRED
2019-06-10 04:19:40,877 INFO org.apache.hadoop.yarn.server.resourcemanager.rmcontainer.RMContainerImpl: container_1560150672880_0001_01_000009 Container Transitioned from NEW to ALLOCATED
2019-06-10 04:19:40,877 INFO org.apache.hadoop.yarn.server.resourcemanager.RMAuditLogger: USER=hduser	OPERATION=AM Allocated Container	TARGET=SchedulerApp	RESULT=SUCCESS	APPID=application_1560150672880_0001	CONTAINERID=container_1560150672880_0001_01_000009
2019-06-10 04:19:40,877 INFO org.apache.hadoop.yarn.server.resourcemanager.scheduler.SchedulerNode: Assigned container container_1560150672880_0001_01_000009 of capacity <memory:1024, vCores:1> on host ubuntu:40311, which has 3 containers, <memory:4096, vCores:3> used and <memory:4096, vCores:5> available after allocation
2019-06-10 04:19:40,878 INFO org.apache.hadoop.yarn.server.resourcemanager.scheduler.capacity.allocator.AbstractContainerAllocator: assignedContainer application attempt=appattempt_1560150672880_0001_000001 container=container_1560150672880_0001_01_000009 queue=org.apache.hadoop.yarn.server.resourcemanager.scheduler.capacity.allocator.RegularContainerAllocator@4d651435 clusterResource=<memory:8192, vCores:8> type=OFF_SWITCH requestedPartition=
2019-06-10 04:19:40,880 INFO org.apache.hadoop.yarn.server.resourcemanager.scheduler.capacity.ParentQueue: Re-sorting assigned queue: root.default stats: default: capacity=1.0, absoluteCapacity=1.0, usedResources=<memory:4096, vCores:3>, usedCapacity=0.5, absoluteUsedCapacity=0.5, numApps=1, numContainers=3
2019-06-10 04:19:40,881 INFO org.apache.hadoop.yarn.server.resourcemanager.scheduler.capacity.ParentQueue: assignedContainer queue=root usedCapacity=0.5 absoluteUsedCapacity=0.5 used=<memory:4096, vCores:3> cluster=<memory:8192, vCores:8>
2019-06-10 04:19:41,840 INFO org.apache.hadoop.yarn.server.resourcemanager.rmcontainer.RMContainerImpl: container_1560150672880_0001_01_000010 Container Transitioned from NEW to ALLOCATED
2019-06-10 04:19:41,841 INFO org.apache.hadoop.yarn.server.resourcemanager.RMAuditLogger: USER=hduser	OPERATION=AM Allocated Container	TARGET=SchedulerApp	RESULT=SUCCESS	APPID=application_1560150672880_0001	CONTAINERID=container_1560150672880_0001_01_000010
2019-06-10 04:19:41,842 INFO org.apache.hadoop.yarn.server.resourcemanager.scheduler.SchedulerNode: Assigned container container_1560150672880_0001_01_000010 of capacity <memory:1024, vCores:1> on host ubuntu:40311, which has 4 containers, <memory:5120, vCores:4> used and <memory:3072, vCores:4> available after allocation
2019-06-10 04:19:41,842 INFO org.apache.hadoop.yarn.server.resourcemanager.scheduler.capacity.allocator.AbstractContainerAllocator: assignedContainer application attempt=appattempt_1560150672880_0001_000001 container=container_1560150672880_0001_01_000010 queue=org.apache.hadoop.yarn.server.resourcemanager.scheduler.capacity.allocator.RegularContainerAllocator@4d651435 clusterResource=<memory:8192, vCores:8> type=OFF_SWITCH requestedPartition=
2019-06-10 04:19:41,842 INFO org.apache.hadoop.yarn.server.resourcemanager.scheduler.capacity.ParentQueue: Re-sorting assigned queue: root.default stats: default: capacity=1.0, absoluteCapacity=1.0, usedResources=<memory:5120, vCores:4>, usedCapacity=0.625, absoluteUsedCapacity=0.625, numApps=1, numContainers=4
2019-06-10 04:19:41,842 INFO org.apache.hadoop.yarn.server.resourcemanager.scheduler.capacity.ParentQueue: assignedContainer queue=root usedCapacity=0.625 absoluteUsedCapacity=0.625 used=<memory:5120, vCores:4> cluster=<memory:8192, vCores:8>
2019-06-10 04:19:41,898 INFO org.apache.hadoop.yarn.server.resourcemanager.rmcontainer.RMContainerImpl: container_1560150672880_0001_01_000008 Container Transitioned from ACQUIRED to RELEASED
2019-06-10 04:19:41,911 INFO org.apache.hadoop.yarn.server.resourcemanager.RMAuditLogger: USER=hduser	IP=127.0.0.1	OPERATION=AM Released Container	TARGET=SchedulerApp	RESULT=SUCCESS	APPID=application_1560150672880_0001	CONTAINERID=container_1560150672880_0001_01_000008
2019-06-10 04:19:41,911 INFO org.apache.hadoop.yarn.server.resourcemanager.scheduler.SchedulerNode: Released container container_1560150672880_0001_01_000008 of capacity <memory:1024, vCores:1> on host ubuntu:40311, which currently has 3 containers, <memory:4096, vCores:3> used and <memory:4096, vCores:5> available, release resources=true
2019-06-10 04:19:41,997 INFO org.apache.hadoop.yarn.server.resourcemanager.rmcontainer.RMContainerImpl: container_1560150672880_0001_01_000009 Container Transitioned from ALLOCATED to ACQUIRED
2019-06-10 04:19:42,078 INFO org.apache.hadoop.yarn.server.resourcemanager.rmcontainer.RMContainerImpl: container_1560150672880_0001_01_000010 Container Transitioned from ALLOCATED to ACQUIRED
2019-06-10 04:19:42,897 INFO org.apache.hadoop.yarn.server.resourcemanager.rmcontainer.RMContainerImpl: container_1560150672880_0001_01_000011 Container Transitioned from NEW to ALLOCATED
2019-06-10 04:19:46,025 INFO org.apache.hadoop.yarn.server.resourcemanager.RMAuditLogger: USER=hduser	OPERATION=AM Allocated Container	TARGET=SchedulerApp	RESULT=SUCCESS	APPID=application_1560150672880_0001	CONTAINERID=container_1560150672880_0001_01_000011
2019-06-10 04:19:46,027 INFO org.apache.hadoop.yarn.server.resourcemanager.scheduler.SchedulerNode: Assigned container container_1560150672880_0001_01_000011 of capacity <memory:1024, vCores:1> on host ubuntu:40311, which has 4 containers, <memory:5120, vCores:4> used and <memory:3072, vCores:4> available after allocation
2019-06-10 04:19:46,060 INFO org.apache.hadoop.yarn.server.resourcemanager.scheduler.capacity.allocator.AbstractContainerAllocator: assignedContainer application attempt=appattempt_1560150672880_0001_000001 container=container_1560150672880_0001_01_000011 queue=org.apache.hadoop.yarn.server.resourcemanager.scheduler.capacity.allocator.RegularContainerAllocator@4d651435 clusterResource=<memory:8192, vCores:8> type=OFF_SWITCH requestedPartition=
2019-06-10 04:19:46,064 INFO org.apache.hadoop.yarn.server.resourcemanager.rmcontainer.RMContainerImpl: container_1560150672880_0001_01_000009 Container Transitioned from ACQUIRED to RELEASED
2019-06-10 04:19:46,090 INFO org.apache.hadoop.yarn.server.resourcemanager.RMAuditLogger: USER=hduser	IP=127.0.0.1	OPERATION=AM Released Container	TARGET=SchedulerApp	RESULT=SUCCESS	APPID=application_1560150672880_0001	CONTAINERID=container_1560150672880_0001_01_000009
2019-06-10 04:19:46,091 INFO org.apache.hadoop.yarn.server.resourcemanager.scheduler.SchedulerNode: Released container container_1560150672880_0001_01_000009 of capacity <memory:1024, vCores:1> on host ubuntu:40311, which currently has 3 containers, <memory:4096, vCores:3> used and <memory:4096, vCores:5> available, release resources=true
2019-06-10 04:19:46,095 INFO org.apache.hadoop.yarn.server.resourcemanager.scheduler.capacity.ParentQueue: Re-sorting assigned queue: root.default stats: default: capacity=1.0, absoluteCapacity=1.0, usedResources=<memory:5120, vCores:4>, usedCapacity=0.625, absoluteUsedCapacity=0.625, numApps=1, numContainers=3
2019-06-10 04:19:46,096 INFO org.apache.hadoop.yarn.server.resourcemanager.scheduler.capacity.ParentQueue: assignedContainer queue=root usedCapacity=0.625 absoluteUsedCapacity=0.625 used=<memory:5120, vCores:4> cluster=<memory:8192, vCores:8>
2019-06-10 04:19:46,098 INFO org.apache.hadoop.yarn.server.resourcemanager.rmcontainer.RMContainerImpl: container_1560150672880_0001_01_000012 Container Transitioned from NEW to ALLOCATED
2019-06-10 04:19:46,099 INFO org.apache.hadoop.yarn.server.resourcemanager.RMAuditLogger: USER=hduser	OPERATION=AM Allocated Container	TARGET=SchedulerApp	RESULT=SUCCESS	APPID=application_1560150672880_0001	CONTAINERID=container_1560150672880_0001_01_000012
2019-06-10 04:19:46,105 INFO org.apache.hadoop.yarn.server.resourcemanager.scheduler.SchedulerNode: Assigned container container_1560150672880_0001_01_000012 of capacity <memory:1024, vCores:1> on host ubuntu:40311, which has 4 containers, <memory:5120, vCores:4> used and <memory:3072, vCores:4> available after allocation
2019-06-10 04:19:46,106 INFO org.apache.hadoop.yarn.server.resourcemanager.scheduler.capacity.allocator.AbstractContainerAllocator: assignedContainer application attempt=appattempt_1560150672880_0001_000001 container=container_1560150672880_0001_01_000012 queue=org.apache.hadoop.yarn.server.resourcemanager.scheduler.capacity.allocator.RegularContainerAllocator@4d651435 clusterResource=<memory:8192, vCores:8> type=OFF_SWITCH requestedPartition=
2019-06-10 04:19:46,107 INFO org.apache.hadoop.yarn.server.resourcemanager.scheduler.capacity.ParentQueue: Re-sorting assigned queue: root.default stats: default: capacity=1.0, absoluteCapacity=1.0, usedResources=<memory:5120, vCores:4>, usedCapacity=0.625, absoluteUsedCapacity=0.625, numApps=1, numContainers=4
2019-06-10 04:19:46,111 INFO org.apache.hadoop.yarn.server.resourcemanager.scheduler.capacity.ParentQueue: assignedContainer queue=root usedCapacity=0.75 absoluteUsedCapacity=0.75 used=<memory:6144, vCores:5> cluster=<memory:8192, vCores:8>
2019-06-10 04:19:46,113 INFO org.apache.hadoop.yarn.server.resourcemanager.rmcontainer.RMContainerImpl: container_1560150672880_0001_01_000010 Container Transitioned from ACQUIRED to RELEASED
2019-06-10 04:19:46,113 INFO org.apache.hadoop.yarn.server.resourcemanager.RMAuditLogger: USER=hduser	IP=127.0.0.1	OPERATION=AM Released Container	TARGET=SchedulerApp	RESULT=SUCCESS	APPID=application_1560150672880_0001	CONTAINERID=container_1560150672880_0001_01_000010
2019-06-10 04:19:46,115 INFO org.apache.hadoop.yarn.server.resourcemanager.scheduler.SchedulerNode: Released container container_1560150672880_0001_01_000010 of capacity <memory:1024, vCores:1> on host ubuntu:40311, which currently has 3 containers, <memory:4096, vCores:3> used and <memory:4096, vCores:5> available, release resources=true
2019-06-10 04:19:46,144 INFO org.apache.hadoop.yarn.server.resourcemanager.rmcontainer.RMContainerImpl: container_1560150672880_0001_01_000011 Container Transitioned from ALLOCATED to ACQUIRED
2019-06-10 04:19:46,162 INFO org.apache.hadoop.yarn.server.resourcemanager.rmcontainer.RMContainerImpl: container_1560150672880_0001_01_000012 Container Transitioned from ALLOCATED to ACQUIRED
2019-06-10 04:19:47,079 INFO org.apache.hadoop.yarn.server.resourcemanager.rmcontainer.RMContainerImpl: container_1560150672880_0001_01_000013 Container Transitioned from NEW to ALLOCATED
2019-06-10 04:19:47,082 INFO org.apache.hadoop.yarn.server.resourcemanager.RMAuditLogger: USER=hduser	OPERATION=AM Allocated Container	TARGET=SchedulerApp	RESULT=SUCCESS	APPID=application_1560150672880_0001	CONTAINERID=container_1560150672880_0001_01_000013
2019-06-10 04:19:47,083 INFO org.apache.hadoop.yarn.server.resourcemanager.scheduler.SchedulerNode: Assigned container container_1560150672880_0001_01_000013 of capacity <memory:1024, vCores:1> on host ubuntu:40311, which has 4 containers, <memory:5120, vCores:4> used and <memory:3072, vCores:4> available after allocation
2019-06-10 04:19:47,084 INFO org.apache.hadoop.yarn.server.resourcemanager.scheduler.capacity.allocator.AbstractContainerAllocator: assignedContainer application attempt=appattempt_1560150672880_0001_000001 container=container_1560150672880_0001_01_000013 queue=org.apache.hadoop.yarn.server.resourcemanager.scheduler.capacity.allocator.RegularContainerAllocator@4d651435 clusterResource=<memory:8192, vCores:8> type=OFF_SWITCH requestedPartition=
2019-06-10 04:19:47,085 INFO org.apache.hadoop.yarn.server.resourcemanager.scheduler.capacity.ParentQueue: Re-sorting assigned queue: root.default stats: default: capacity=1.0, absoluteCapacity=1.0, usedResources=<memory:5120, vCores:4>, usedCapacity=0.625, absoluteUsedCapacity=0.625, numApps=1, numContainers=4
2019-06-10 04:19:47,088 INFO org.apache.hadoop.yarn.server.resourcemanager.scheduler.capacity.ParentQueue: assignedContainer queue=root usedCapacity=0.625 absoluteUsedCapacity=0.625 used=<memory:5120, vCores:4> cluster=<memory:8192, vCores:8>
2019-06-10 04:19:47,178 INFO org.apache.hadoop.yarn.server.resourcemanager.rmcontainer.RMContainerImpl: container_1560150672880_0001_01_000011 Container Transitioned from ACQUIRED to RELEASED
2019-06-10 04:19:47,190 INFO org.apache.hadoop.yarn.server.resourcemanager.RMAuditLogger: USER=hduser	IP=127.0.0.1	OPERATION=AM Released Container	TARGET=SchedulerApp	RESULT=SUCCESS	APPID=application_1560150672880_0001	CONTAINERID=container_1560150672880_0001_01_000011
2019-06-10 04:19:47,192 INFO org.apache.hadoop.yarn.server.resourcemanager.scheduler.SchedulerNode: Released container container_1560150672880_0001_01_000011 of capacity <memory:1024, vCores:1> on host ubuntu:40311, which currently has 3 containers, <memory:4096, vCores:3> used and <memory:4096, vCores:5> available, release resources=true
2019-06-10 04:19:47,195 INFO org.apache.hadoop.yarn.server.resourcemanager.scheduler.AppSchedulingInfo: checking for deactivate of application :application_1560150672880_0001
2019-06-10 04:19:47,196 INFO org.apache.hadoop.yarn.server.resourcemanager.scheduler.AppSchedulingInfo: checking for deactivate of application :application_1560150672880_0001
2019-06-10 04:19:47,209 INFO org.apache.hadoop.yarn.server.resourcemanager.rmcontainer.RMContainerImpl: container_1560150672880_0001_01_000013 Container Transitioned from ALLOCATED to ACQUIRED
2019-06-10 04:19:47,378 INFO org.apache.hadoop.yarn.server.resourcemanager.rmapp.attempt.RMAppAttemptImpl: Updating application attempt appattempt_1560150672880_0001_000001 with final state: FINISHING, and exit status: -1000
2019-06-10 04:19:47,387 INFO org.apache.hadoop.yarn.server.resourcemanager.rmapp.attempt.RMAppAttemptImpl: appattempt_1560150672880_0001_000001 State change from RUNNING to FINAL_SAVING
2019-06-10 04:19:47,388 INFO org.apache.hadoop.yarn.server.resourcemanager.rmapp.attempt.RMAppAttemptImpl: appattempt_1560150672880_0001_000001 State change from FINAL_SAVING to FINISHING
2019-06-10 04:19:47,389 INFO org.apache.hadoop.yarn.server.resourcemanager.rmapp.RMAppImpl: Updating application application_1560150672880_0001 with final state: FINISHING
2019-06-10 04:19:47,392 INFO org.apache.hadoop.yarn.server.resourcemanager.rmapp.RMAppImpl: application_1560150672880_0001 State change from RUNNING to FINAL_SAVING on event=ATTEMPT_UNREGISTERED
2019-06-10 04:19:47,393 INFO org.apache.hadoop.yarn.server.resourcemanager.recovery.RMStateStore: Updating info for app: application_1560150672880_0001
2019-06-10 04:19:47,393 INFO org.apache.hadoop.yarn.server.resourcemanager.rmapp.RMAppImpl: application_1560150672880_0001 State change from FINAL_SAVING to FINISHING on event=APP_UPDATE_SAVED
2019-06-10 04:19:48,416 INFO org.apache.hadoop.yarn.server.resourcemanager.ApplicationMasterService: application_1560150672880_0001 unregistered successfully. 
2019-06-10 04:19:53,905 INFO org.apache.hadoop.yarn.server.resourcemanager.rmcontainer.RMContainerImpl: container_1560150672880_0001_01_000001 Container Transitioned from RUNNING to COMPLETED
2019-06-10 04:19:53,905 INFO org.apache.hadoop.yarn.server.resourcemanager.ApplicationMasterService: Unregistering app attempt : appattempt_1560150672880_0001_000001
2019-06-10 04:19:53,906 INFO org.apache.hadoop.yarn.server.resourcemanager.RMAuditLogger: USER=hduser	OPERATION=AM Released Container	TARGET=SchedulerApp	RESULT=SUCCESS	APPID=application_1560150672880_0001	CONTAINERID=container_1560150672880_0001_01_000001
2019-06-10 04:19:53,909 INFO org.apache.hadoop.yarn.server.resourcemanager.scheduler.SchedulerNode: Released container container_1560150672880_0001_01_000001 of capacity <memory:2048, vCores:1> on host ubuntu:40311, which currently has 2 containers, <memory:2048, vCores:2> used and <memory:6144, vCores:6> available, release resources=true
2019-06-10 04:19:53,919 INFO org.apache.hadoop.yarn.server.resourcemanager.security.AMRMTokenSecretManager: Application finished, removing password for appattempt_1560150672880_0001_000001
2019-06-10 04:19:53,920 INFO org.apache.hadoop.yarn.server.resourcemanager.rmapp.attempt.RMAppAttemptImpl: appattempt_1560150672880_0001_000001 State change from FINISHING to FINISHED
2019-06-10 04:19:53,939 INFO org.apache.hadoop.yarn.server.resourcemanager.rmapp.RMAppImpl: application_1560150672880_0001 State change from FINISHING to FINISHED on event=ATTEMPT_FINISHED
2019-06-10 04:19:53,940 INFO org.apache.hadoop.yarn.server.resourcemanager.scheduler.capacity.CapacityScheduler: Application Attempt appattempt_1560150672880_0001_000001 is done. finalState=FINISHED
2019-06-10 04:19:53,941 INFO org.apache.hadoop.yarn.server.resourcemanager.rmcontainer.RMContainerImpl: container_1560150672880_0001_01_000012 Container Transitioned from ACQUIRED to KILLED
2019-06-10 04:19:53,941 INFO org.apache.hadoop.yarn.server.resourcemanager.amlauncher.AMLauncher: Cleaning master appattempt_1560150672880_0001_000001
2019-06-10 04:19:53,942 INFO org.apache.hadoop.yarn.server.resourcemanager.RMAuditLogger: USER=hduser	OPERATION=AM Released Container	TARGET=SchedulerApp	RESULT=SUCCESS	APPID=application_1560150672880_0001	CONTAINERID=container_1560150672880_0001_01_000012
2019-06-10 04:19:53,943 INFO org.apache.hadoop.yarn.server.resourcemanager.scheduler.SchedulerNode: Released container container_1560150672880_0001_01_000012 of capacity <memory:1024, vCores:1> on host ubuntu:40311, which currently has 1 containers, <memory:1024, vCores:1> used and <memory:7168, vCores:7> available, release resources=true
2019-06-10 04:19:53,944 INFO org.apache.hadoop.yarn.server.resourcemanager.rmcontainer.RMContainerImpl: container_1560150672880_0001_01_000013 Container Transitioned from ACQUIRED to KILLED
2019-06-10 04:19:53,945 INFO org.apache.hadoop.yarn.server.resourcemanager.RMAuditLogger: USER=hduser	OPERATION=AM Released Container	TARGET=SchedulerApp	RESULT=SUCCESS	APPID=application_1560150672880_0001	CONTAINERID=container_1560150672880_0001_01_000013
2019-06-10 04:19:53,945 INFO org.apache.hadoop.yarn.server.resourcemanager.scheduler.SchedulerNode: Released container container_1560150672880_0001_01_000013 of capacity <memory:1024, vCores:1> on host ubuntu:40311, which currently has 0 containers, <memory:0, vCores:0> used and <memory:8192, vCores:8> available, release resources=true
2019-06-10 04:19:53,949 INFO org.apache.hadoop.yarn.server.resourcemanager.scheduler.AppSchedulingInfo: Application application_1560150672880_0001 requests cleared
2019-06-10 04:19:53,958 INFO org.apache.hadoop.yarn.server.resourcemanager.RMAuditLogger: USER=hduser	OPERATION=Application Finished - Succeeded	TARGET=RMAppManager	RESULT=SUCCESS	APPID=application_1560150672880_0001
2019-06-10 04:19:53,958 INFO org.apache.hadoop.yarn.server.resourcemanager.scheduler.capacity.LeafQueue: Application removed - appId: application_1560150672880_0001 user: hduser queue: default #user-pending-applications: 0 #user-active-applications: 0 #queue-pending-applications: 0 #queue-active-applications: 0
2019-06-10 04:19:53,958 INFO org.apache.hadoop.yarn.server.resourcemanager.scheduler.capacity.ParentQueue: Application removed - appId: application_1560150672880_0001 user: hduser leaf-queue of parent: root #applications: 0
2019-06-10 04:19:53,988 INFO org.apache.hadoop.yarn.server.resourcemanager.RMAppManager$ApplicationSummary: appId=application_1560150672880_0001,name=categories.jar,user=hduser,queue=default,state=FINISHED,trackingUrl=http://ubuntu:8088/proxy/application_1560150672880_0001/,appMasterHost=ubuntu,startTime=1560165540812,finishTime=1560165587389,finalStatus=FAILED,memorySeconds=146940,vcoreSeconds=85,preemptedMemorySeconds=0,preemptedVcoreSeconds=0,preemptedAMContainers=0,preemptedNonAMContainers=0,preemptedResources=<memory:0\, vCores:0>,applicationType=MAPREDUCE
2019-06-10 04:23:41,291 INFO org.apache.hadoop.yarn.server.resourcemanager.ClientRMService: Allocated new applicationId: 2
2019-06-10 04:23:44,945 INFO org.apache.hadoop.yarn.server.resourcemanager.scheduler.capacity.CapacityScheduler: Application 'application_1560150672880_0002' is submitted without priority hence considering default queue/cluster priority: 0
2019-06-10 04:23:44,947 INFO org.apache.hadoop.yarn.server.resourcemanager.scheduler.capacity.CapacityScheduler: Priority '0' is acceptable in queue : default for application: application_1560150672880_0002 for the user: hduser
2019-06-10 04:23:44,948 INFO org.apache.hadoop.yarn.server.resourcemanager.ClientRMService: Application with id 2 submitted by user hduser
2019-06-10 04:23:44,949 INFO org.apache.hadoop.yarn.server.resourcemanager.rmapp.RMAppImpl: Storing application with id application_1560150672880_0002
2019-06-10 04:23:44,949 INFO org.apache.hadoop.yarn.server.resourcemanager.RMAuditLogger: USER=hduser	IP=127.0.0.1	OPERATION=Submit Application Request	TARGET=ClientRMService	RESULT=SUCCESS	APPID=application_1560150672880_0002	CALLERCONTEXT=CLI
2019-06-10 04:23:44,949 INFO org.apache.hadoop.yarn.server.resourcemanager.rmapp.RMAppImpl: application_1560150672880_0002 State change from NEW to NEW_SAVING on event=START
2019-06-10 04:23:44,950 INFO org.apache.hadoop.yarn.server.resourcemanager.recovery.RMStateStore: Storing info for app: application_1560150672880_0002
2019-06-10 04:23:44,950 INFO org.apache.hadoop.yarn.server.resourcemanager.rmapp.RMAppImpl: application_1560150672880_0002 State change from NEW_SAVING to SUBMITTED on event=APP_NEW_SAVED
2019-06-10 04:23:44,952 INFO org.apache.hadoop.yarn.server.resourcemanager.scheduler.capacity.ParentQueue: Application added - appId: application_1560150672880_0002 user: hduser leaf-queue of parent: root #applications: 1
2019-06-10 04:23:44,952 INFO org.apache.hadoop.yarn.server.resourcemanager.scheduler.capacity.CapacityScheduler: Accepted application application_1560150672880_0002 from user: hduser, in queue: default
2019-06-10 04:23:44,955 INFO org.apache.hadoop.yarn.server.resourcemanager.rmapp.RMAppImpl: application_1560150672880_0002 State change from SUBMITTED to ACCEPTED on event=APP_ACCEPTED
2019-06-10 04:23:44,956 INFO org.apache.hadoop.yarn.server.resourcemanager.ApplicationMasterService: Registering app attempt : appattempt_1560150672880_0002_000001
2019-06-10 04:23:44,956 INFO org.apache.hadoop.yarn.server.resourcemanager.rmapp.attempt.RMAppAttemptImpl: appattempt_1560150672880_0002_000001 State change from NEW to SUBMITTED
2019-06-10 04:23:44,959 WARN org.apache.hadoop.yarn.server.resourcemanager.scheduler.capacity.LeafQueue: maximum-am-resource-percent is insufficient to start a single application in queue, it is likely set too low. skipping enforcement to allow at least one application to start
2019-06-10 04:23:44,959 WARN org.apache.hadoop.yarn.server.resourcemanager.scheduler.capacity.LeafQueue: maximum-am-resource-percent is insufficient to start a single application in queue for user, it is likely set too low. skipping enforcement to allow at least one application to start
2019-06-10 04:23:44,964 INFO org.apache.hadoop.yarn.server.resourcemanager.scheduler.capacity.LeafQueue: Application application_1560150672880_0002 from user: hduser activated in queue: default
2019-06-10 04:23:44,965 INFO org.apache.hadoop.yarn.server.resourcemanager.scheduler.capacity.LeafQueue: Application added - appId: application_1560150672880_0002 user: hduser, leaf-queue: default #user-pending-applications: 0 #user-active-applications: 1 #queue-pending-applications: 0 #queue-active-applications: 1
2019-06-10 04:23:44,965 INFO org.apache.hadoop.yarn.server.resourcemanager.scheduler.capacity.CapacityScheduler: Added Application Attempt appattempt_1560150672880_0002_000001 to scheduler from user hduser in queue default
2019-06-10 04:23:44,970 INFO org.apache.hadoop.yarn.server.resourcemanager.rmapp.attempt.RMAppAttemptImpl: appattempt_1560150672880_0002_000001 State change from SUBMITTED to SCHEDULED
2019-06-10 04:23:45,297 INFO org.apache.hadoop.yarn.server.resourcemanager.rmcontainer.RMContainerImpl: container_1560150672880_0002_01_000001 Container Transitioned from NEW to ALLOCATED
2019-06-10 04:23:45,297 INFO org.apache.hadoop.yarn.server.resourcemanager.RMAuditLogger: USER=hduser	OPERATION=AM Allocated Container	TARGET=SchedulerApp	RESULT=SUCCESS	APPID=application_1560150672880_0002	CONTAINERID=container_1560150672880_0002_01_000001
2019-06-10 04:23:45,298 INFO org.apache.hadoop.yarn.server.resourcemanager.scheduler.SchedulerNode: Assigned container container_1560150672880_0002_01_000001 of capacity <memory:2048, vCores:1> on host ubuntu:40311, which has 1 containers, <memory:2048, vCores:1> used and <memory:6144, vCores:7> available after allocation
2019-06-10 04:23:45,299 INFO org.apache.hadoop.yarn.server.resourcemanager.scheduler.capacity.allocator.AbstractContainerAllocator: assignedContainer application attempt=appattempt_1560150672880_0002_000001 container=container_1560150672880_0002_01_000001 queue=org.apache.hadoop.yarn.server.resourcemanager.scheduler.capacity.allocator.RegularContainerAllocator@16998a69 clusterResource=<memory:8192, vCores:8> type=OFF_SWITCH requestedPartition=
2019-06-10 04:23:45,307 INFO org.apache.hadoop.yarn.server.resourcemanager.security.NMTokenSecretManagerInRM: Sending NMToken for nodeId : ubuntu:40311 for container : container_1560150672880_0002_01_000001
2019-06-10 04:23:45,313 INFO org.apache.hadoop.yarn.server.resourcemanager.rmcontainer.RMContainerImpl: container_1560150672880_0002_01_000001 Container Transitioned from ALLOCATED to ACQUIRED
2019-06-10 04:23:45,314 INFO org.apache.hadoop.yarn.server.resourcemanager.security.NMTokenSecretManagerInRM: Clear node set for appattempt_1560150672880_0002_000001
2019-06-10 04:23:45,314 INFO org.apache.hadoop.yarn.server.resourcemanager.scheduler.capacity.ParentQueue: Re-sorting assigned queue: root.default stats: default: capacity=1.0, absoluteCapacity=1.0, usedResources=<memory:2048, vCores:1>, usedCapacity=0.25, absoluteUsedCapacity=0.25, numApps=1, numContainers=1
2019-06-10 04:23:45,316 INFO org.apache.hadoop.yarn.server.resourcemanager.scheduler.capacity.ParentQueue: assignedContainer queue=root usedCapacity=0.25 absoluteUsedCapacity=0.25 used=<memory:2048, vCores:1> cluster=<memory:8192, vCores:8>
2019-06-10 04:23:45,315 INFO org.apache.hadoop.yarn.server.resourcemanager.rmapp.attempt.RMAppAttemptImpl: Storing attempt: AppId: application_1560150672880_0002 AttemptId: appattempt_1560150672880_0002_000001 MasterContainer: Container: [ContainerId: container_1560150672880_0002_01_000001, Version: 0, NodeId: ubuntu:40311, NodeHttpAddress: ubuntu:8042, Resource: <memory:2048, vCores:1>, Priority: 0, Token: Token { kind: ContainerToken, service: 127.0.1.1:40311 }, ]
2019-06-10 04:23:45,317 INFO org.apache.hadoop.yarn.server.resourcemanager.rmapp.attempt.RMAppAttemptImpl: appattempt_1560150672880_0002_000001 State change from SCHEDULED to ALLOCATED_SAVING
2019-06-10 04:23:45,318 INFO org.apache.hadoop.yarn.server.resourcemanager.rmapp.attempt.RMAppAttemptImpl: appattempt_1560150672880_0002_000001 State change from ALLOCATED_SAVING to ALLOCATED
2019-06-10 04:23:45,319 INFO org.apache.hadoop.yarn.server.resourcemanager.amlauncher.AMLauncher: Launching masterappattempt_1560150672880_0002_000001
2019-06-10 04:23:45,328 INFO org.apache.hadoop.yarn.server.resourcemanager.amlauncher.AMLauncher: Setting up container Container: [ContainerId: container_1560150672880_0002_01_000001, Version: 0, NodeId: ubuntu:40311, NodeHttpAddress: ubuntu:8042, Resource: <memory:2048, vCores:1>, Priority: 0, Token: Token { kind: ContainerToken, service: 127.0.1.1:40311 }, ] for AM appattempt_1560150672880_0002_000001
2019-06-10 04:23:45,330 INFO org.apache.hadoop.yarn.server.resourcemanager.security.AMRMTokenSecretManager: Create AMRMToken for ApplicationAttempt: appattempt_1560150672880_0002_000001
2019-06-10 04:23:45,330 INFO org.apache.hadoop.yarn.server.resourcemanager.security.AMRMTokenSecretManager: Creating password for appattempt_1560150672880_0002_000001
2019-06-10 04:23:45,373 INFO org.apache.hadoop.yarn.server.resourcemanager.amlauncher.AMLauncher: Done launching container Container: [ContainerId: container_1560150672880_0002_01_000001, Version: 0, NodeId: ubuntu:40311, NodeHttpAddress: ubuntu:8042, Resource: <memory:2048, vCores:1>, Priority: 0, Token: Token { kind: ContainerToken, service: 127.0.1.1:40311 }, ] for AM appattempt_1560150672880_0002_000001
2019-06-10 04:23:45,375 INFO org.apache.hadoop.yarn.server.resourcemanager.rmapp.attempt.RMAppAttemptImpl: appattempt_1560150672880_0002_000001 State change from ALLOCATED to LAUNCHED
2019-06-10 04:23:46,299 INFO org.apache.hadoop.yarn.server.resourcemanager.rmcontainer.RMContainerImpl: container_1560150672880_0002_01_000001 Container Transitioned from ACQUIRED to RUNNING
2019-06-10 04:23:57,936 INFO SecurityLogger.org.apache.hadoop.ipc.Server: Auth successful for appattempt_1560150672880_0002_000001 (auth:SIMPLE)
2019-06-10 04:23:57,952 INFO org.apache.hadoop.yarn.server.resourcemanager.ApplicationMasterService: AM registration appattempt_1560150672880_0002_000001
2019-06-10 04:23:57,953 INFO org.apache.hadoop.yarn.server.resourcemanager.RMAuditLogger: USER=hduser	IP=127.0.0.1	OPERATION=Register App Master	TARGET=ApplicationMasterService	RESULT=SUCCESS	APPID=application_1560150672880_0002	APPATTEMPTID=appattempt_1560150672880_0002_000001
2019-06-10 04:23:57,954 INFO org.apache.hadoop.yarn.server.resourcemanager.rmapp.attempt.RMAppAttemptImpl: appattempt_1560150672880_0002_000001 State change from LAUNCHED to RUNNING
2019-06-10 04:23:57,955 INFO org.apache.hadoop.yarn.server.resourcemanager.rmapp.RMAppImpl: application_1560150672880_0002 State change from ACCEPTED to RUNNING on event=ATTEMPT_REGISTERED
2019-06-10 04:23:59,354 INFO org.apache.hadoop.yarn.server.resourcemanager.rmcontainer.RMContainerImpl: container_1560150672880_0002_01_000002 Container Transitioned from NEW to ALLOCATED
2019-06-10 04:23:59,354 INFO org.apache.hadoop.yarn.server.resourcemanager.RMAuditLogger: USER=hduser	OPERATION=AM Allocated Container	TARGET=SchedulerApp	RESULT=SUCCESS	APPID=application_1560150672880_0002	CONTAINERID=container_1560150672880_0002_01_000002
2019-06-10 04:23:59,355 INFO org.apache.hadoop.yarn.server.resourcemanager.scheduler.SchedulerNode: Assigned container container_1560150672880_0002_01_000002 of capacity <memory:1024, vCores:1> on host ubuntu:40311, which has 2 containers, <memory:3072, vCores:2> used and <memory:5120, vCores:6> available after allocation
2019-06-10 04:23:59,356 INFO org.apache.hadoop.yarn.server.resourcemanager.scheduler.capacity.allocator.AbstractContainerAllocator: assignedContainer application attempt=appattempt_1560150672880_0002_000001 container=container_1560150672880_0002_01_000002 queue=org.apache.hadoop.yarn.server.resourcemanager.scheduler.capacity.allocator.RegularContainerAllocator@16998a69 clusterResource=<memory:8192, vCores:8> type=OFF_SWITCH requestedPartition=
2019-06-10 04:23:59,357 INFO org.apache.hadoop.yarn.server.resourcemanager.scheduler.capacity.ParentQueue: Re-sorting assigned queue: root.default stats: default: capacity=1.0, absoluteCapacity=1.0, usedResources=<memory:3072, vCores:2>, usedCapacity=0.375, absoluteUsedCapacity=0.375, numApps=1, numContainers=2
2019-06-10 04:23:59,357 INFO org.apache.hadoop.yarn.server.resourcemanager.scheduler.capacity.ParentQueue: assignedContainer queue=root usedCapacity=0.375 absoluteUsedCapacity=0.375 used=<memory:3072, vCores:2> cluster=<memory:8192, vCores:8>
2019-06-10 04:24:00,221 INFO org.apache.hadoop.yarn.server.resourcemanager.security.NMTokenSecretManagerInRM: Sending NMToken for nodeId : ubuntu:40311 for container : container_1560150672880_0002_01_000002
2019-06-10 04:24:00,225 INFO org.apache.hadoop.yarn.server.resourcemanager.rmcontainer.RMContainerImpl: container_1560150672880_0002_01_000002 Container Transitioned from ALLOCATED to ACQUIRED
2019-06-10 04:24:00,364 INFO org.apache.hadoop.yarn.server.resourcemanager.rmcontainer.RMContainerImpl: container_1560150672880_0002_01_000003 Container Transitioned from NEW to ALLOCATED
2019-06-10 04:24:00,364 INFO org.apache.hadoop.yarn.server.resourcemanager.RMAuditLogger: USER=hduser	OPERATION=AM Allocated Container	TARGET=SchedulerApp	RESULT=SUCCESS	APPID=application_1560150672880_0002	CONTAINERID=container_1560150672880_0002_01_000003
2019-06-10 04:24:00,365 INFO org.apache.hadoop.yarn.server.resourcemanager.scheduler.SchedulerNode: Assigned container container_1560150672880_0002_01_000003 of capacity <memory:1024, vCores:1> on host ubuntu:40311, which has 3 containers, <memory:4096, vCores:3> used and <memory:4096, vCores:5> available after allocation
2019-06-10 04:24:00,366 INFO org.apache.hadoop.yarn.server.resourcemanager.scheduler.capacity.allocator.AbstractContainerAllocator: assignedContainer application attempt=appattempt_1560150672880_0002_000001 container=container_1560150672880_0002_01_000003 queue=org.apache.hadoop.yarn.server.resourcemanager.scheduler.capacity.allocator.RegularContainerAllocator@16998a69 clusterResource=<memory:8192, vCores:8> type=OFF_SWITCH requestedPartition=
2019-06-10 04:24:00,368 INFO org.apache.hadoop.yarn.server.resourcemanager.scheduler.capacity.ParentQueue: Re-sorting assigned queue: root.default stats: default: capacity=1.0, absoluteCapacity=1.0, usedResources=<memory:4096, vCores:3>, usedCapacity=0.5, absoluteUsedCapacity=0.5, numApps=1, numContainers=3
2019-06-10 04:24:00,369 INFO org.apache.hadoop.yarn.server.resourcemanager.scheduler.capacity.ParentQueue: assignedContainer queue=root usedCapacity=0.5 absoluteUsedCapacity=0.5 used=<memory:4096, vCores:3> cluster=<memory:8192, vCores:8>
2019-06-10 04:24:01,309 INFO org.apache.hadoop.yarn.server.resourcemanager.rmcontainer.RMContainerImpl: container_1560150672880_0002_01_000003 Container Transitioned from ALLOCATED to ACQUIRED
2019-06-10 04:24:01,384 INFO org.apache.hadoop.yarn.server.resourcemanager.rmcontainer.RMContainerImpl: container_1560150672880_0002_01_000004 Container Transitioned from NEW to ALLOCATED
2019-06-10 04:24:01,388 INFO org.apache.hadoop.yarn.server.resourcemanager.RMAuditLogger: USER=hduser	OPERATION=AM Allocated Container	TARGET=SchedulerApp	RESULT=SUCCESS	APPID=application_1560150672880_0002	CONTAINERID=container_1560150672880_0002_01_000004
2019-06-10 04:24:01,389 INFO org.apache.hadoop.yarn.server.resourcemanager.scheduler.SchedulerNode: Assigned container container_1560150672880_0002_01_000004 of capacity <memory:1024, vCores:1> on host ubuntu:40311, which has 4 containers, <memory:5120, vCores:4> used and <memory:3072, vCores:4> available after allocation
2019-06-10 04:24:01,396 INFO org.apache.hadoop.yarn.server.resourcemanager.scheduler.capacity.allocator.AbstractContainerAllocator: assignedContainer application attempt=appattempt_1560150672880_0002_000001 container=container_1560150672880_0002_01_000004 queue=org.apache.hadoop.yarn.server.resourcemanager.scheduler.capacity.allocator.RegularContainerAllocator@16998a69 clusterResource=<memory:8192, vCores:8> type=OFF_SWITCH requestedPartition=
2019-06-10 04:24:01,430 INFO org.apache.hadoop.yarn.server.resourcemanager.scheduler.capacity.ParentQueue: Re-sorting assigned queue: root.default stats: default: capacity=1.0, absoluteCapacity=1.0, usedResources=<memory:5120, vCores:4>, usedCapacity=0.625, absoluteUsedCapacity=0.625, numApps=1, numContainers=4
2019-06-10 04:24:01,432 INFO org.apache.hadoop.yarn.server.resourcemanager.scheduler.capacity.ParentQueue: assignedContainer queue=root usedCapacity=0.625 absoluteUsedCapacity=0.625 used=<memory:5120, vCores:4> cluster=<memory:8192, vCores:8>
2019-06-10 04:24:02,361 INFO org.apache.hadoop.yarn.server.resourcemanager.rmcontainer.RMContainerImpl: container_1560150672880_0002_01_000002 Container Transitioned from ACQUIRED to RELEASED
2019-06-10 04:24:02,382 INFO org.apache.hadoop.yarn.server.resourcemanager.RMAuditLogger: USER=hduser	IP=127.0.0.1	OPERATION=AM Released Container	TARGET=SchedulerApp	RESULT=SUCCESS	APPID=application_1560150672880_0002	CONTAINERID=container_1560150672880_0002_01_000002
2019-06-10 04:24:02,391 INFO org.apache.hadoop.yarn.server.resourcemanager.scheduler.SchedulerNode: Released container container_1560150672880_0002_01_000002 of capacity <memory:1024, vCores:1> on host ubuntu:40311, which currently has 3 containers, <memory:4096, vCores:3> used and <memory:4096, vCores:5> available, release resources=true
2019-06-10 04:24:02,424 INFO org.apache.hadoop.yarn.server.resourcemanager.rmcontainer.RMContainerImpl: container_1560150672880_0002_01_000005 Container Transitioned from NEW to ALLOCATED
2019-06-10 04:24:02,426 INFO org.apache.hadoop.yarn.server.resourcemanager.RMAuditLogger: USER=hduser	OPERATION=AM Allocated Container	TARGET=SchedulerApp	RESULT=SUCCESS	APPID=application_1560150672880_0002	CONTAINERID=container_1560150672880_0002_01_000005
2019-06-10 04:24:02,428 INFO org.apache.hadoop.yarn.server.resourcemanager.scheduler.SchedulerNode: Assigned container container_1560150672880_0002_01_000005 of capacity <memory:1024, vCores:1> on host ubuntu:40311, which has 4 containers, <memory:5120, vCores:4> used and <memory:3072, vCores:4> available after allocation
2019-06-10 04:24:02,434 INFO org.apache.hadoop.yarn.server.resourcemanager.scheduler.capacity.allocator.AbstractContainerAllocator: assignedContainer application attempt=appattempt_1560150672880_0002_000001 container=container_1560150672880_0002_01_000005 queue=org.apache.hadoop.yarn.server.resourcemanager.scheduler.capacity.allocator.RegularContainerAllocator@16998a69 clusterResource=<memory:8192, vCores:8> type=OFF_SWITCH requestedPartition=
2019-06-10 04:24:02,438 INFO org.apache.hadoop.yarn.server.resourcemanager.scheduler.capacity.ParentQueue: Re-sorting assigned queue: root.default stats: default: capacity=1.0, absoluteCapacity=1.0, usedResources=<memory:5120, vCores:4>, usedCapacity=0.625, absoluteUsedCapacity=0.625, numApps=1, numContainers=4
2019-06-10 04:24:02,439 INFO org.apache.hadoop.yarn.server.resourcemanager.scheduler.capacity.ParentQueue: assignedContainer queue=root usedCapacity=0.75 absoluteUsedCapacity=0.75 used=<memory:6144, vCores:5> cluster=<memory:8192, vCores:8>
2019-06-10 04:24:02,445 INFO org.apache.hadoop.yarn.server.resourcemanager.rmcontainer.RMContainerImpl: container_1560150672880_0002_01_000003 Container Transitioned from ACQUIRED to RELEASED
2019-06-10 04:24:02,450 INFO org.apache.hadoop.yarn.server.resourcemanager.RMAuditLogger: USER=hduser	IP=127.0.0.1	OPERATION=AM Released Container	TARGET=SchedulerApp	RESULT=SUCCESS	APPID=application_1560150672880_0002	CONTAINERID=container_1560150672880_0002_01_000003
2019-06-10 04:24:02,453 INFO org.apache.hadoop.yarn.server.resourcemanager.scheduler.SchedulerNode: Released container container_1560150672880_0002_01_000003 of capacity <memory:1024, vCores:1> on host ubuntu:40311, which currently has 3 containers, <memory:4096, vCores:3> used and <memory:4096, vCores:5> available, release resources=true
2019-06-10 04:24:02,539 INFO org.apache.hadoop.yarn.server.resourcemanager.rmcontainer.RMContainerImpl: container_1560150672880_0002_01_000004 Container Transitioned from ALLOCATED to ACQUIRED
2019-06-10 04:24:02,567 INFO org.apache.hadoop.yarn.server.resourcemanager.rmcontainer.RMContainerImpl: container_1560150672880_0002_01_000005 Container Transitioned from ALLOCATED to ACQUIRED
2019-06-10 04:24:03,415 INFO org.apache.hadoop.yarn.server.resourcemanager.rmcontainer.RMContainerImpl: container_1560150672880_0002_01_000006 Container Transitioned from NEW to ALLOCATED
2019-06-10 04:24:03,417 INFO org.apache.hadoop.yarn.server.resourcemanager.RMAuditLogger: USER=hduser	OPERATION=AM Allocated Container	TARGET=SchedulerApp	RESULT=SUCCESS	APPID=application_1560150672880_0002	CONTAINERID=container_1560150672880_0002_01_000006
2019-06-10 04:24:03,418 INFO org.apache.hadoop.yarn.server.resourcemanager.scheduler.SchedulerNode: Assigned container container_1560150672880_0002_01_000006 of capacity <memory:1024, vCores:1> on host ubuntu:40311, which has 4 containers, <memory:5120, vCores:4> used and <memory:3072, vCores:4> available after allocation
2019-06-10 04:24:03,420 INFO org.apache.hadoop.yarn.server.resourcemanager.scheduler.capacity.allocator.AbstractContainerAllocator: assignedContainer application attempt=appattempt_1560150672880_0002_000001 container=container_1560150672880_0002_01_000006 queue=org.apache.hadoop.yarn.server.resourcemanager.scheduler.capacity.allocator.RegularContainerAllocator@16998a69 clusterResource=<memory:8192, vCores:8> type=OFF_SWITCH requestedPartition=
2019-06-10 04:24:03,423 INFO org.apache.hadoop.yarn.server.resourcemanager.scheduler.capacity.ParentQueue: Re-sorting assigned queue: root.default stats: default: capacity=1.0, absoluteCapacity=1.0, usedResources=<memory:5120, vCores:4>, usedCapacity=0.625, absoluteUsedCapacity=0.625, numApps=1, numContainers=4
2019-06-10 04:24:03,431 INFO org.apache.hadoop.yarn.server.resourcemanager.scheduler.capacity.ParentQueue: assignedContainer queue=root usedCapacity=0.625 absoluteUsedCapacity=0.625 used=<memory:5120, vCores:4> cluster=<memory:8192, vCores:8>
2019-06-10 04:24:03,639 INFO org.apache.hadoop.yarn.server.resourcemanager.rmcontainer.RMContainerImpl: container_1560150672880_0002_01_000004 Container Transitioned from ACQUIRED to RELEASED
2019-06-10 04:24:03,639 INFO org.apache.hadoop.yarn.server.resourcemanager.RMAuditLogger: USER=hduser	IP=127.0.0.1	OPERATION=AM Released Container	TARGET=SchedulerApp	RESULT=SUCCESS	APPID=application_1560150672880_0002	CONTAINERID=container_1560150672880_0002_01_000004
2019-06-10 04:24:03,654 INFO org.apache.hadoop.yarn.server.resourcemanager.scheduler.SchedulerNode: Released container container_1560150672880_0002_01_000004 of capacity <memory:1024, vCores:1> on host ubuntu:40311, which currently has 3 containers, <memory:4096, vCores:3> used and <memory:4096, vCores:5> available, release resources=true
2019-06-10 04:24:03,690 INFO org.apache.hadoop.yarn.server.resourcemanager.rmcontainer.RMContainerImpl: container_1560150672880_0002_01_000005 Container Transitioned from ACQUIRED to RELEASED
2019-06-10 04:24:03,707 INFO org.apache.hadoop.yarn.server.resourcemanager.RMAuditLogger: USER=hduser	IP=127.0.0.1	OPERATION=AM Released Container	TARGET=SchedulerApp	RESULT=SUCCESS	APPID=application_1560150672880_0002	CONTAINERID=container_1560150672880_0002_01_000005
2019-06-10 04:24:03,709 INFO org.apache.hadoop.yarn.server.resourcemanager.scheduler.SchedulerNode: Released container container_1560150672880_0002_01_000005 of capacity <memory:1024, vCores:1> on host ubuntu:40311, which currently has 2 containers, <memory:3072, vCores:2> used and <memory:5120, vCores:6> available, release resources=true
2019-06-10 04:24:03,717 INFO org.apache.hadoop.yarn.server.resourcemanager.scheduler.AppSchedulingInfo: checking for deactivate of application :application_1560150672880_0002
2019-06-10 04:24:03,753 INFO org.apache.hadoop.yarn.server.resourcemanager.rmcontainer.RMContainerImpl: container_1560150672880_0002_01_000006 Container Transitioned from ALLOCATED to ACQUIRED
2019-06-10 04:24:03,758 INFO org.apache.hadoop.yarn.server.resourcemanager.ApplicationMasterService: blacklist are updated in Scheduler.blacklistAdditions: [ubuntu], blacklistRemovals: []
2019-06-10 04:24:04,816 INFO org.apache.hadoop.yarn.server.resourcemanager.rmcontainer.RMContainerImpl: container_1560150672880_0002_01_000006 Container Transitioned from ACQUIRED to RELEASED
2019-06-10 04:24:04,824 INFO org.apache.hadoop.yarn.server.resourcemanager.RMAuditLogger: USER=hduser	IP=127.0.0.1	OPERATION=AM Released Container	TARGET=SchedulerApp	RESULT=SUCCESS	APPID=application_1560150672880_0002	CONTAINERID=container_1560150672880_0002_01_000006
2019-06-10 04:24:04,825 INFO org.apache.hadoop.yarn.server.resourcemanager.scheduler.SchedulerNode: Released container container_1560150672880_0002_01_000006 of capacity <memory:1024, vCores:1> on host ubuntu:40311, which currently has 1 containers, <memory:2048, vCores:1> used and <memory:6144, vCores:7> available, release resources=true
2019-06-10 04:24:04,859 INFO org.apache.hadoop.yarn.server.resourcemanager.ApplicationMasterService: blacklist are updated in Scheduler.blacklistAdditions: [], blacklistRemovals: [ubuntu]
2019-06-10 04:24:05,429 INFO org.apache.hadoop.yarn.server.resourcemanager.rmcontainer.RMContainerImpl: container_1560150672880_0002_01_000007 Container Transitioned from NEW to ALLOCATED
2019-06-10 04:24:05,430 INFO org.apache.hadoop.yarn.server.resourcemanager.RMAuditLogger: USER=hduser	OPERATION=AM Allocated Container	TARGET=SchedulerApp	RESULT=SUCCESS	APPID=application_1560150672880_0002	CONTAINERID=container_1560150672880_0002_01_000007
2019-06-10 04:24:05,430 INFO org.apache.hadoop.yarn.server.resourcemanager.scheduler.SchedulerNode: Assigned container container_1560150672880_0002_01_000007 of capacity <memory:1024, vCores:1> on host ubuntu:40311, which has 2 containers, <memory:3072, vCores:2> used and <memory:5120, vCores:6> available after allocation
2019-06-10 04:24:05,431 INFO org.apache.hadoop.yarn.server.resourcemanager.scheduler.capacity.allocator.AbstractContainerAllocator: assignedContainer application attempt=appattempt_1560150672880_0002_000001 container=container_1560150672880_0002_01_000007 queue=org.apache.hadoop.yarn.server.resourcemanager.scheduler.capacity.allocator.RegularContainerAllocator@16998a69 clusterResource=<memory:8192, vCores:8> type=OFF_SWITCH requestedPartition=
2019-06-10 04:24:05,433 INFO org.apache.hadoop.yarn.server.resourcemanager.scheduler.capacity.ParentQueue: Re-sorting assigned queue: root.default stats: default: capacity=1.0, absoluteCapacity=1.0, usedResources=<memory:3072, vCores:2>, usedCapacity=0.375, absoluteUsedCapacity=0.375, numApps=1, numContainers=2
2019-06-10 04:24:05,434 INFO org.apache.hadoop.yarn.server.resourcemanager.scheduler.capacity.ParentQueue: assignedContainer queue=root usedCapacity=0.375 absoluteUsedCapacity=0.375 used=<memory:3072, vCores:2> cluster=<memory:8192, vCores:8>
2019-06-10 04:24:05,878 INFO org.apache.hadoop.yarn.server.resourcemanager.rmcontainer.RMContainerImpl: container_1560150672880_0002_01_000007 Container Transitioned from ALLOCATED to ACQUIRED
2019-06-10 04:24:06,443 INFO org.apache.hadoop.yarn.server.resourcemanager.rmcontainer.RMContainerImpl: container_1560150672880_0002_01_000008 Container Transitioned from NEW to ALLOCATED
2019-06-10 04:24:06,443 INFO org.apache.hadoop.yarn.server.resourcemanager.RMAuditLogger: USER=hduser	OPERATION=AM Allocated Container	TARGET=SchedulerApp	RESULT=SUCCESS	APPID=application_1560150672880_0002	CONTAINERID=container_1560150672880_0002_01_000008
2019-06-10 04:24:06,444 INFO org.apache.hadoop.yarn.server.resourcemanager.scheduler.SchedulerNode: Assigned container container_1560150672880_0002_01_000008 of capacity <memory:1024, vCores:1> on host ubuntu:40311, which has 3 containers, <memory:4096, vCores:3> used and <memory:4096, vCores:5> available after allocation
2019-06-10 04:24:06,445 INFO org.apache.hadoop.yarn.server.resourcemanager.scheduler.capacity.allocator.AbstractContainerAllocator: assignedContainer application attempt=appattempt_1560150672880_0002_000001 container=container_1560150672880_0002_01_000008 queue=org.apache.hadoop.yarn.server.resourcemanager.scheduler.capacity.allocator.RegularContainerAllocator@16998a69 clusterResource=<memory:8192, vCores:8> type=OFF_SWITCH requestedPartition=
2019-06-10 04:24:06,447 INFO org.apache.hadoop.yarn.server.resourcemanager.scheduler.capacity.ParentQueue: Re-sorting assigned queue: root.default stats: default: capacity=1.0, absoluteCapacity=1.0, usedResources=<memory:4096, vCores:3>, usedCapacity=0.5, absoluteUsedCapacity=0.5, numApps=1, numContainers=3
2019-06-10 04:24:06,448 INFO org.apache.hadoop.yarn.server.resourcemanager.scheduler.capacity.ParentQueue: assignedContainer queue=root usedCapacity=0.5 absoluteUsedCapacity=0.5 used=<memory:4096, vCores:3> cluster=<memory:8192, vCores:8>
2019-06-10 04:24:06,895 INFO org.apache.hadoop.yarn.server.resourcemanager.rmcontainer.RMContainerImpl: container_1560150672880_0002_01_000007 Container Transitioned from ACQUIRED to RELEASED
2019-06-10 04:24:06,896 INFO org.apache.hadoop.yarn.server.resourcemanager.RMAuditLogger: USER=hduser	IP=127.0.0.1	OPERATION=AM Released Container	TARGET=SchedulerApp	RESULT=SUCCESS	APPID=application_1560150672880_0002	CONTAINERID=container_1560150672880_0002_01_000007
2019-06-10 04:24:06,897 INFO org.apache.hadoop.yarn.server.resourcemanager.scheduler.SchedulerNode: Released container container_1560150672880_0002_01_000007 of capacity <memory:1024, vCores:1> on host ubuntu:40311, which currently has 2 containers, <memory:3072, vCores:2> used and <memory:5120, vCores:6> available, release resources=true
2019-06-10 04:24:06,904 INFO org.apache.hadoop.yarn.server.resourcemanager.rmcontainer.RMContainerImpl: container_1560150672880_0002_01_000008 Container Transitioned from ALLOCATED to ACQUIRED
2019-06-10 04:24:07,444 INFO org.apache.hadoop.yarn.server.resourcemanager.rmcontainer.RMContainerImpl: container_1560150672880_0002_01_000009 Container Transitioned from NEW to ALLOCATED
2019-06-10 04:24:07,445 INFO org.apache.hadoop.yarn.server.resourcemanager.RMAuditLogger: USER=hduser	OPERATION=AM Allocated Container	TARGET=SchedulerApp	RESULT=SUCCESS	APPID=application_1560150672880_0002	CONTAINERID=container_1560150672880_0002_01_000009
2019-06-10 04:24:07,445 INFO org.apache.hadoop.yarn.server.resourcemanager.scheduler.SchedulerNode: Assigned container container_1560150672880_0002_01_000009 of capacity <memory:1024, vCores:1> on host ubuntu:40311, which has 3 containers, <memory:4096, vCores:3> used and <memory:4096, vCores:5> available after allocation
2019-06-10 04:24:07,446 INFO org.apache.hadoop.yarn.server.resourcemanager.scheduler.capacity.allocator.AbstractContainerAllocator: assignedContainer application attempt=appattempt_1560150672880_0002_000001 container=container_1560150672880_0002_01_000009 queue=org.apache.hadoop.yarn.server.resourcemanager.scheduler.capacity.allocator.RegularContainerAllocator@16998a69 clusterResource=<memory:8192, vCores:8> type=OFF_SWITCH requestedPartition=
2019-06-10 04:24:07,448 INFO org.apache.hadoop.yarn.server.resourcemanager.scheduler.capacity.ParentQueue: Re-sorting assigned queue: root.default stats: default: capacity=1.0, absoluteCapacity=1.0, usedResources=<memory:4096, vCores:3>, usedCapacity=0.5, absoluteUsedCapacity=0.5, numApps=1, numContainers=3
2019-06-10 04:24:07,449 INFO org.apache.hadoop.yarn.server.resourcemanager.scheduler.capacity.ParentQueue: assignedContainer queue=root usedCapacity=0.5 absoluteUsedCapacity=0.5 used=<memory:4096, vCores:3> cluster=<memory:8192, vCores:8>
2019-06-10 04:24:07,926 INFO org.apache.hadoop.yarn.server.resourcemanager.rmcontainer.RMContainerImpl: container_1560150672880_0002_01_000008 Container Transitioned from ACQUIRED to RELEASED
2019-06-10 04:24:07,927 INFO org.apache.hadoop.yarn.server.resourcemanager.RMAuditLogger: USER=hduser	IP=127.0.0.1	OPERATION=AM Released Container	TARGET=SchedulerApp	RESULT=SUCCESS	APPID=application_1560150672880_0002	CONTAINERID=container_1560150672880_0002_01_000008
2019-06-10 04:24:07,929 INFO org.apache.hadoop.yarn.server.resourcemanager.scheduler.SchedulerNode: Released container container_1560150672880_0002_01_000008 of capacity <memory:1024, vCores:1> on host ubuntu:40311, which currently has 2 containers, <memory:3072, vCores:2> used and <memory:5120, vCores:6> available, release resources=true
2019-06-10 04:24:07,960 INFO org.apache.hadoop.yarn.server.resourcemanager.rmcontainer.RMContainerImpl: container_1560150672880_0002_01_000009 Container Transitioned from ALLOCATED to ACQUIRED
2019-06-10 04:24:08,448 INFO org.apache.hadoop.yarn.server.resourcemanager.rmcontainer.RMContainerImpl: container_1560150672880_0002_01_000010 Container Transitioned from NEW to ALLOCATED
2019-06-10 04:24:08,449 INFO org.apache.hadoop.yarn.server.resourcemanager.RMAuditLogger: USER=hduser	OPERATION=AM Allocated Container	TARGET=SchedulerApp	RESULT=SUCCESS	APPID=application_1560150672880_0002	CONTAINERID=container_1560150672880_0002_01_000010
2019-06-10 04:24:08,450 INFO org.apache.hadoop.yarn.server.resourcemanager.scheduler.SchedulerNode: Assigned container container_1560150672880_0002_01_000010 of capacity <memory:1024, vCores:1> on host ubuntu:40311, which has 3 containers, <memory:4096, vCores:3> used and <memory:4096, vCores:5> available after allocation
2019-06-10 04:24:08,450 INFO org.apache.hadoop.yarn.server.resourcemanager.scheduler.capacity.allocator.AbstractContainerAllocator: assignedContainer application attempt=appattempt_1560150672880_0002_000001 container=container_1560150672880_0002_01_000010 queue=org.apache.hadoop.yarn.server.resourcemanager.scheduler.capacity.allocator.RegularContainerAllocator@16998a69 clusterResource=<memory:8192, vCores:8> type=OFF_SWITCH requestedPartition=
2019-06-10 04:24:08,452 INFO org.apache.hadoop.yarn.server.resourcemanager.scheduler.capacity.ParentQueue: Re-sorting assigned queue: root.default stats: default: capacity=1.0, absoluteCapacity=1.0, usedResources=<memory:4096, vCores:3>, usedCapacity=0.5, absoluteUsedCapacity=0.5, numApps=1, numContainers=3
2019-06-10 04:24:08,452 INFO org.apache.hadoop.yarn.server.resourcemanager.scheduler.capacity.ParentQueue: assignedContainer queue=root usedCapacity=0.5 absoluteUsedCapacity=0.5 used=<memory:4096, vCores:3> cluster=<memory:8192, vCores:8>
2019-06-10 04:24:12,365 INFO org.apache.hadoop.yarn.server.resourcemanager.rmcontainer.RMContainerImpl: container_1560150672880_0002_01_000011 Container Transitioned from NEW to ALLOCATED
2019-06-10 04:24:12,371 INFO org.apache.hadoop.yarn.server.resourcemanager.RMAuditLogger: USER=hduser	OPERATION=AM Allocated Container	TARGET=SchedulerApp	RESULT=SUCCESS	APPID=application_1560150672880_0002	CONTAINERID=container_1560150672880_0002_01_000011
2019-06-10 04:24:12,378 INFO org.apache.hadoop.yarn.server.resourcemanager.scheduler.SchedulerNode: Assigned container container_1560150672880_0002_01_000011 of capacity <memory:1024, vCores:1> on host ubuntu:40311, which has 4 containers, <memory:5120, vCores:4> used and <memory:3072, vCores:4> available after allocation
2019-06-10 04:24:12,387 INFO org.apache.hadoop.yarn.server.resourcemanager.scheduler.capacity.allocator.AbstractContainerAllocator: assignedContainer application attempt=appattempt_1560150672880_0002_000001 container=container_1560150672880_0002_01_000011 queue=org.apache.hadoop.yarn.server.resourcemanager.scheduler.capacity.allocator.RegularContainerAllocator@16998a69 clusterResource=<memory:8192, vCores:8> type=OFF_SWITCH requestedPartition=
2019-06-10 04:24:12,425 INFO org.apache.hadoop.yarn.server.resourcemanager.rmcontainer.RMContainerImpl: container_1560150672880_0002_01_000009 Container Transitioned from ACQUIRED to RELEASED
2019-06-10 04:24:12,426 INFO org.apache.hadoop.yarn.server.resourcemanager.scheduler.capacity.ParentQueue: Re-sorting assigned queue: root.default stats: default: capacity=1.0, absoluteCapacity=1.0, usedResources=<memory:5120, vCores:4>, usedCapacity=0.625, absoluteUsedCapacity=0.625, numApps=1, numContainers=4
2019-06-10 04:24:12,438 INFO org.apache.hadoop.yarn.server.resourcemanager.RMAuditLogger: USER=hduser	IP=127.0.0.1	OPERATION=AM Released Container	TARGET=SchedulerApp	RESULT=SUCCESS	APPID=application_1560150672880_0002	CONTAINERID=container_1560150672880_0002_01_000009
2019-06-10 04:24:12,441 INFO org.apache.hadoop.yarn.server.resourcemanager.scheduler.SchedulerNode: Released container container_1560150672880_0002_01_000009 of capacity <memory:1024, vCores:1> on host ubuntu:40311, which currently has 3 containers, <memory:4096, vCores:3> used and <memory:4096, vCores:5> available, release resources=true
2019-06-10 04:24:12,444 INFO org.apache.hadoop.yarn.server.resourcemanager.scheduler.capacity.ParentQueue: assignedContainer queue=root usedCapacity=0.625 absoluteUsedCapacity=0.625 used=<memory:5120, vCores:4> cluster=<memory:8192, vCores:8>
2019-06-10 04:24:12,495 INFO org.apache.hadoop.yarn.server.resourcemanager.rmcontainer.RMContainerImpl: container_1560150672880_0002_01_000010 Container Transitioned from ALLOCATED to ACQUIRED
2019-06-10 04:24:12,511 INFO org.apache.hadoop.yarn.server.resourcemanager.rmcontainer.RMContainerImpl: container_1560150672880_0002_01_000011 Container Transitioned from ALLOCATED to ACQUIRED
2019-06-10 04:24:13,353 INFO org.apache.hadoop.yarn.server.resourcemanager.rmcontainer.RMContainerImpl: container_1560150672880_0002_01_000012 Container Transitioned from NEW to ALLOCATED
2019-06-10 04:24:13,354 INFO org.apache.hadoop.yarn.server.resourcemanager.RMAuditLogger: USER=hduser	OPERATION=AM Allocated Container	TARGET=SchedulerApp	RESULT=SUCCESS	APPID=application_1560150672880_0002	CONTAINERID=container_1560150672880_0002_01_000012
2019-06-10 04:24:13,354 INFO org.apache.hadoop.yarn.server.resourcemanager.scheduler.SchedulerNode: Assigned container container_1560150672880_0002_01_000012 of capacity <memory:1024, vCores:1> on host ubuntu:40311, which has 4 containers, <memory:5120, vCores:4> used and <memory:3072, vCores:4> available after allocation
2019-06-10 04:24:13,356 INFO org.apache.hadoop.yarn.server.resourcemanager.scheduler.capacity.allocator.AbstractContainerAllocator: assignedContainer application attempt=appattempt_1560150672880_0002_000001 container=container_1560150672880_0002_01_000012 queue=org.apache.hadoop.yarn.server.resourcemanager.scheduler.capacity.allocator.RegularContainerAllocator@16998a69 clusterResource=<memory:8192, vCores:8> type=OFF_SWITCH requestedPartition=
2019-06-10 04:24:13,358 INFO org.apache.hadoop.yarn.server.resourcemanager.scheduler.capacity.ParentQueue: Re-sorting assigned queue: root.default stats: default: capacity=1.0, absoluteCapacity=1.0, usedResources=<memory:5120, vCores:4>, usedCapacity=0.625, absoluteUsedCapacity=0.625, numApps=1, numContainers=4
2019-06-10 04:24:13,359 INFO org.apache.hadoop.yarn.server.resourcemanager.scheduler.capacity.ParentQueue: assignedContainer queue=root usedCapacity=0.625 absoluteUsedCapacity=0.625 used=<memory:5120, vCores:4> cluster=<memory:8192, vCores:8>
2019-06-10 04:24:13,554 INFO org.apache.hadoop.yarn.server.resourcemanager.rmcontainer.RMContainerImpl: container_1560150672880_0002_01_000010 Container Transitioned from ACQUIRED to RELEASED
2019-06-10 04:24:13,556 INFO org.apache.hadoop.yarn.server.resourcemanager.RMAuditLogger: USER=hduser	IP=127.0.0.1	OPERATION=AM Released Container	TARGET=SchedulerApp	RESULT=SUCCESS	APPID=application_1560150672880_0002	CONTAINERID=container_1560150672880_0002_01_000010
2019-06-10 04:24:13,557 INFO org.apache.hadoop.yarn.server.resourcemanager.scheduler.SchedulerNode: Released container container_1560150672880_0002_01_000010 of capacity <memory:1024, vCores:1> on host ubuntu:40311, which currently has 3 containers, <memory:4096, vCores:3> used and <memory:4096, vCores:5> available, release resources=true
2019-06-10 04:24:13,558 INFO org.apache.hadoop.yarn.server.resourcemanager.rmcontainer.RMContainerImpl: container_1560150672880_0002_01_000011 Container Transitioned from ACQUIRED to RELEASED
2019-06-10 04:24:13,558 INFO org.apache.hadoop.yarn.server.resourcemanager.RMAuditLogger: USER=hduser	IP=127.0.0.1	OPERATION=AM Released Container	TARGET=SchedulerApp	RESULT=SUCCESS	APPID=application_1560150672880_0002	CONTAINERID=container_1560150672880_0002_01_000011
2019-06-10 04:24:13,559 INFO org.apache.hadoop.yarn.server.resourcemanager.scheduler.SchedulerNode: Released container container_1560150672880_0002_01_000011 of capacity <memory:1024, vCores:1> on host ubuntu:40311, which currently has 2 containers, <memory:3072, vCores:2> used and <memory:5120, vCores:6> available, release resources=true
2019-06-10 04:24:13,568 INFO org.apache.hadoop.yarn.server.resourcemanager.rmcontainer.RMContainerImpl: container_1560150672880_0002_01_000012 Container Transitioned from ALLOCATED to ACQUIRED
2019-06-10 04:24:14,396 INFO org.apache.hadoop.yarn.server.resourcemanager.rmcontainer.RMContainerImpl: container_1560150672880_0002_01_000013 Container Transitioned from NEW to ALLOCATED
2019-06-10 04:24:14,399 INFO org.apache.hadoop.yarn.server.resourcemanager.RMAuditLogger: USER=hduser	OPERATION=AM Allocated Container	TARGET=SchedulerApp	RESULT=SUCCESS	APPID=application_1560150672880_0002	CONTAINERID=container_1560150672880_0002_01_000013
2019-06-10 04:24:14,404 INFO org.apache.hadoop.yarn.server.resourcemanager.scheduler.SchedulerNode: Assigned container container_1560150672880_0002_01_000013 of capacity <memory:1024, vCores:1> on host ubuntu:40311, which has 3 containers, <memory:4096, vCores:3> used and <memory:4096, vCores:5> available after allocation
2019-06-10 04:24:14,405 INFO org.apache.hadoop.yarn.server.resourcemanager.scheduler.capacity.allocator.AbstractContainerAllocator: assignedContainer application attempt=appattempt_1560150672880_0002_000001 container=container_1560150672880_0002_01_000013 queue=org.apache.hadoop.yarn.server.resourcemanager.scheduler.capacity.allocator.RegularContainerAllocator@16998a69 clusterResource=<memory:8192, vCores:8> type=OFF_SWITCH requestedPartition=
2019-06-10 04:24:14,409 INFO org.apache.hadoop.yarn.server.resourcemanager.scheduler.capacity.ParentQueue: Re-sorting assigned queue: root.default stats: default: capacity=1.0, absoluteCapacity=1.0, usedResources=<memory:4096, vCores:3>, usedCapacity=0.5, absoluteUsedCapacity=0.5, numApps=1, numContainers=3
2019-06-10 04:24:14,412 INFO org.apache.hadoop.yarn.server.resourcemanager.scheduler.capacity.ParentQueue: assignedContainer queue=root usedCapacity=0.5 absoluteUsedCapacity=0.5 used=<memory:4096, vCores:3> cluster=<memory:8192, vCores:8>
2019-06-10 04:24:14,599 INFO org.apache.hadoop.yarn.server.resourcemanager.rmcontainer.RMContainerImpl: container_1560150672880_0002_01_000012 Container Transitioned from ACQUIRED to RELEASED
2019-06-10 04:24:14,602 INFO org.apache.hadoop.yarn.server.resourcemanager.RMAuditLogger: USER=hduser	IP=127.0.0.1	OPERATION=AM Released Container	TARGET=SchedulerApp	RESULT=SUCCESS	APPID=application_1560150672880_0002	CONTAINERID=container_1560150672880_0002_01_000012
2019-06-10 04:24:14,603 INFO org.apache.hadoop.yarn.server.resourcemanager.scheduler.SchedulerNode: Released container container_1560150672880_0002_01_000012 of capacity <memory:1024, vCores:1> on host ubuntu:40311, which currently has 2 containers, <memory:3072, vCores:2> used and <memory:5120, vCores:6> available, release resources=true
2019-06-10 04:24:14,619 INFO org.apache.hadoop.yarn.server.resourcemanager.rmcontainer.RMContainerImpl: container_1560150672880_0002_01_000013 Container Transitioned from ALLOCATED to ACQUIRED
2019-06-10 04:24:15,314 INFO org.apache.hadoop.yarn.server.resourcemanager.RMAuditLogger: USER=dr.who	OPERATION=Get Applications Request	TARGET=ClientRMService	RESULT=SUCCESS
2019-06-10 04:24:15,396 INFO org.apache.hadoop.yarn.server.resourcemanager.rmcontainer.RMContainerImpl: container_1560150672880_0002_01_000014 Container Transitioned from NEW to ALLOCATED
2019-06-10 04:24:15,398 INFO org.apache.hadoop.yarn.server.resourcemanager.RMAuditLogger: USER=hduser	OPERATION=AM Allocated Container	TARGET=SchedulerApp	RESULT=SUCCESS	APPID=application_1560150672880_0002	CONTAINERID=container_1560150672880_0002_01_000014
2019-06-10 04:24:15,399 INFO org.apache.hadoop.yarn.server.resourcemanager.scheduler.SchedulerNode: Assigned container container_1560150672880_0002_01_000014 of capacity <memory:1024, vCores:1> on host ubuntu:40311, which has 3 containers, <memory:4096, vCores:3> used and <memory:4096, vCores:5> available after allocation
2019-06-10 04:24:15,414 INFO org.apache.hadoop.yarn.server.resourcemanager.scheduler.capacity.allocator.AbstractContainerAllocator: assignedContainer application attempt=appattempt_1560150672880_0002_000001 container=container_1560150672880_0002_01_000014 queue=org.apache.hadoop.yarn.server.resourcemanager.scheduler.capacity.allocator.RegularContainerAllocator@16998a69 clusterResource=<memory:8192, vCores:8> type=OFF_SWITCH requestedPartition=
2019-06-10 04:24:15,422 INFO org.apache.hadoop.yarn.server.resourcemanager.scheduler.capacity.ParentQueue: Re-sorting assigned queue: root.default stats: default: capacity=1.0, absoluteCapacity=1.0, usedResources=<memory:4096, vCores:3>, usedCapacity=0.5, absoluteUsedCapacity=0.5, numApps=1, numContainers=3
2019-06-10 04:24:15,423 INFO org.apache.hadoop.yarn.server.resourcemanager.scheduler.capacity.ParentQueue: assignedContainer queue=root usedCapacity=0.5 absoluteUsedCapacity=0.5 used=<memory:4096, vCores:3> cluster=<memory:8192, vCores:8>
2019-06-10 04:24:15,652 INFO org.apache.hadoop.yarn.server.resourcemanager.rmcontainer.RMContainerImpl: container_1560150672880_0002_01_000013 Container Transitioned from ACQUIRED to RELEASED
2019-06-10 04:24:15,653 INFO org.apache.hadoop.yarn.server.resourcemanager.RMAuditLogger: USER=hduser	IP=127.0.0.1	OPERATION=AM Released Container	TARGET=SchedulerApp	RESULT=SUCCESS	APPID=application_1560150672880_0002	CONTAINERID=container_1560150672880_0002_01_000013
2019-06-10 04:24:15,653 INFO org.apache.hadoop.yarn.server.resourcemanager.scheduler.SchedulerNode: Released container container_1560150672880_0002_01_000013 of capacity <memory:1024, vCores:1> on host ubuntu:40311, which currently has 2 containers, <memory:3072, vCores:2> used and <memory:5120, vCores:6> available, release resources=true
2019-06-10 04:24:15,666 INFO org.apache.hadoop.yarn.server.resourcemanager.rmcontainer.RMContainerImpl: container_1560150672880_0002_01_000014 Container Transitioned from ALLOCATED to ACQUIRED
2019-06-10 04:24:16,389 INFO org.apache.hadoop.yarn.server.resourcemanager.rmcontainer.RMContainerImpl: container_1560150672880_0002_01_000015 Container Transitioned from NEW to ALLOCATED
2019-06-10 04:24:16,391 INFO org.apache.hadoop.yarn.server.resourcemanager.RMAuditLogger: USER=hduser	OPERATION=AM Allocated Container	TARGET=SchedulerApp	RESULT=SUCCESS	APPID=application_1560150672880_0002	CONTAINERID=container_1560150672880_0002_01_000015
2019-06-10 04:24:16,392 INFO org.apache.hadoop.yarn.server.resourcemanager.scheduler.SchedulerNode: Assigned container container_1560150672880_0002_01_000015 of capacity <memory:1024, vCores:1> on host ubuntu:40311, which has 3 containers, <memory:4096, vCores:3> used and <memory:4096, vCores:5> available after allocation
2019-06-10 04:24:16,393 INFO org.apache.hadoop.yarn.server.resourcemanager.scheduler.capacity.allocator.AbstractContainerAllocator: assignedContainer application attempt=appattempt_1560150672880_0002_000001 container=container_1560150672880_0002_01_000015 queue=org.apache.hadoop.yarn.server.resourcemanager.scheduler.capacity.allocator.RegularContainerAllocator@16998a69 clusterResource=<memory:8192, vCores:8> type=OFF_SWITCH requestedPartition=
2019-06-10 04:24:16,398 INFO org.apache.hadoop.yarn.server.resourcemanager.scheduler.capacity.ParentQueue: Re-sorting assigned queue: root.default stats: default: capacity=1.0, absoluteCapacity=1.0, usedResources=<memory:4096, vCores:3>, usedCapacity=0.5, absoluteUsedCapacity=0.5, numApps=1, numContainers=3
2019-06-10 04:24:16,401 INFO org.apache.hadoop.yarn.server.resourcemanager.scheduler.capacity.ParentQueue: assignedContainer queue=root usedCapacity=0.5 absoluteUsedCapacity=0.5 used=<memory:4096, vCores:3> cluster=<memory:8192, vCores:8>
2019-06-10 04:24:16,722 INFO org.apache.hadoop.yarn.server.resourcemanager.rmcontainer.RMContainerImpl: container_1560150672880_0002_01_000014 Container Transitioned from ACQUIRED to RELEASED
2019-06-10 04:24:16,722 INFO org.apache.hadoop.yarn.server.resourcemanager.RMAuditLogger: USER=hduser	IP=127.0.0.1	OPERATION=AM Released Container	TARGET=SchedulerApp	RESULT=SUCCESS	APPID=application_1560150672880_0002	CONTAINERID=container_1560150672880_0002_01_000014
2019-06-10 04:24:16,723 INFO org.apache.hadoop.yarn.server.resourcemanager.scheduler.SchedulerNode: Released container container_1560150672880_0002_01_000014 of capacity <memory:1024, vCores:1> on host ubuntu:40311, which currently has 2 containers, <memory:3072, vCores:2> used and <memory:5120, vCores:6> available, release resources=true
2019-06-10 04:24:16,724 INFO org.apache.hadoop.yarn.server.resourcemanager.scheduler.AppSchedulingInfo: checking for deactivate of application :application_1560150672880_0002
2019-06-10 04:24:16,754 INFO org.apache.hadoop.yarn.server.resourcemanager.rmcontainer.RMContainerImpl: container_1560150672880_0002_01_000015 Container Transitioned from ALLOCATED to ACQUIRED
2019-06-10 04:24:17,442 INFO org.apache.hadoop.yarn.server.resourcemanager.rmapp.attempt.RMAppAttemptImpl: Updating application attempt appattempt_1560150672880_0002_000001 with final state: FINISHING, and exit status: -1000
2019-06-10 04:24:17,443 INFO org.apache.hadoop.yarn.server.resourcemanager.rmapp.attempt.RMAppAttemptImpl: appattempt_1560150672880_0002_000001 State change from RUNNING to FINAL_SAVING
2019-06-10 04:24:17,445 INFO org.apache.hadoop.yarn.server.resourcemanager.rmapp.RMAppImpl: Updating application application_1560150672880_0002 with final state: FINISHING
2019-06-10 04:24:17,447 INFO org.apache.hadoop.yarn.server.resourcemanager.rmapp.RMAppImpl: application_1560150672880_0002 State change from RUNNING to FINAL_SAVING on event=ATTEMPT_UNREGISTERED
2019-06-10 04:24:17,447 INFO org.apache.hadoop.yarn.server.resourcemanager.recovery.RMStateStore: Updating info for app: application_1560150672880_0002
2019-06-10 04:24:17,448 INFO org.apache.hadoop.yarn.server.resourcemanager.rmapp.attempt.RMAppAttemptImpl: appattempt_1560150672880_0002_000001 State change from FINAL_SAVING to FINISHING
2019-06-10 04:24:17,452 INFO org.apache.hadoop.yarn.server.resourcemanager.rmapp.RMAppImpl: application_1560150672880_0002 State change from FINAL_SAVING to FINISHING on event=APP_UPDATE_SAVED
2019-06-10 04:24:18,464 INFO org.apache.hadoop.yarn.server.resourcemanager.ApplicationMasterService: application_1560150672880_0002 unregistered successfully. 
2019-06-10 04:24:24,273 INFO org.apache.hadoop.yarn.server.resourcemanager.rmcontainer.RMContainerImpl: container_1560150672880_0002_01_000001 Container Transitioned from RUNNING to COMPLETED
2019-06-10 04:24:24,274 INFO org.apache.hadoop.yarn.server.resourcemanager.ApplicationMasterService: Unregistering app attempt : appattempt_1560150672880_0002_000001
2019-06-10 04:24:24,274 INFO org.apache.hadoop.yarn.server.resourcemanager.RMAuditLogger: USER=hduser	OPERATION=AM Released Container	TARGET=SchedulerApp	RESULT=SUCCESS	APPID=application_1560150672880_0002	CONTAINERID=container_1560150672880_0002_01_000001
2019-06-10 04:24:24,275 INFO org.apache.hadoop.yarn.server.resourcemanager.security.AMRMTokenSecretManager: Application finished, removing password for appattempt_1560150672880_0002_000001
2019-06-10 04:24:24,276 INFO org.apache.hadoop.yarn.server.resourcemanager.rmapp.attempt.RMAppAttemptImpl: appattempt_1560150672880_0002_000001 State change from FINISHING to FINISHED
2019-06-10 04:24:24,278 INFO org.apache.hadoop.yarn.server.resourcemanager.scheduler.SchedulerNode: Released container container_1560150672880_0002_01_000001 of capacity <memory:2048, vCores:1> on host ubuntu:40311, which currently has 1 containers, <memory:1024, vCores:1> used and <memory:7168, vCores:7> available, release resources=true
2019-06-10 04:24:24,279 INFO org.apache.hadoop.yarn.server.resourcemanager.rmapp.RMAppImpl: application_1560150672880_0002 State change from FINISHING to FINISHED on event=ATTEMPT_FINISHED
2019-06-10 04:24:24,281 INFO org.apache.hadoop.yarn.server.resourcemanager.scheduler.capacity.CapacityScheduler: Application Attempt appattempt_1560150672880_0002_000001 is done. finalState=FINISHED
2019-06-10 04:24:24,284 INFO org.apache.hadoop.yarn.server.resourcemanager.rmcontainer.RMContainerImpl: container_1560150672880_0002_01_000015 Container Transitioned from ACQUIRED to KILLED
2019-06-10 04:24:24,284 INFO org.apache.hadoop.yarn.server.resourcemanager.amlauncher.AMLauncher: Cleaning master appattempt_1560150672880_0002_000001
2019-06-10 04:24:24,285 INFO org.apache.hadoop.yarn.server.resourcemanager.RMAuditLogger: USER=hduser	OPERATION=AM Released Container	TARGET=SchedulerApp	RESULT=SUCCESS	APPID=application_1560150672880_0002	CONTAINERID=container_1560150672880_0002_01_000015
2019-06-10 04:24:24,285 INFO org.apache.hadoop.yarn.server.resourcemanager.RMAuditLogger: USER=hduser	OPERATION=Application Finished - Succeeded	TARGET=RMAppManager	RESULT=SUCCESS	APPID=application_1560150672880_0002
2019-06-10 04:24:24,286 INFO org.apache.hadoop.yarn.server.resourcemanager.scheduler.SchedulerNode: Released container container_1560150672880_0002_01_000015 of capacity <memory:1024, vCores:1> on host ubuntu:40311, which currently has 0 containers, <memory:0, vCores:0> used and <memory:8192, vCores:8> available, release resources=true
2019-06-10 04:24:24,309 INFO org.apache.hadoop.yarn.server.resourcemanager.scheduler.AppSchedulingInfo: Application application_1560150672880_0002 requests cleared
2019-06-10 04:24:24,315 INFO org.apache.hadoop.yarn.server.resourcemanager.scheduler.capacity.LeafQueue: Application removed - appId: application_1560150672880_0002 user: hduser queue: default #user-pending-applications: 0 #user-active-applications: 0 #queue-pending-applications: 0 #queue-active-applications: 0
2019-06-10 04:24:24,315 INFO org.apache.hadoop.yarn.server.resourcemanager.RMAppManager$ApplicationSummary: appId=application_1560150672880_0002,name=categories.jar,user=hduser,queue=default,state=FINISHED,trackingUrl=http://ubuntu:8088/proxy/application_1560150672880_0002/,appMasterHost=ubuntu,startTime=1560165824947,finishTime=1560165857444,finalStatus=FAILED,memorySeconds=116633,vcoreSeconds=69,preemptedMemorySeconds=0,preemptedVcoreSeconds=0,preemptedAMContainers=0,preemptedNonAMContainers=0,preemptedResources=<memory:0\, vCores:0>,applicationType=MAPREDUCE
2019-06-10 04:24:24,315 INFO org.apache.hadoop.yarn.server.resourcemanager.scheduler.capacity.ParentQueue: Application removed - appId: application_1560150672880_0002 user: hduser leaf-queue of parent: root #applications: 0
2019-06-10 04:28:23,455 INFO org.apache.hadoop.yarn.server.resourcemanager.ClientRMService: Allocated new applicationId: 3
2019-06-10 04:28:28,741 INFO org.apache.hadoop.yarn.server.resourcemanager.scheduler.capacity.CapacityScheduler: Application 'application_1560150672880_0003' is submitted without priority hence considering default queue/cluster priority: 0
2019-06-10 04:28:28,741 INFO org.apache.hadoop.yarn.server.resourcemanager.scheduler.capacity.CapacityScheduler: Priority '0' is acceptable in queue : default for application: application_1560150672880_0003 for the user: hduser
2019-06-10 04:28:28,743 INFO org.apache.hadoop.yarn.server.resourcemanager.ClientRMService: Application with id 3 submitted by user hduser
2019-06-10 04:28:28,743 INFO org.apache.hadoop.yarn.server.resourcemanager.rmapp.RMAppImpl: Storing application with id application_1560150672880_0003
2019-06-10 04:28:28,743 INFO org.apache.hadoop.yarn.server.resourcemanager.RMAuditLogger: USER=hduser	IP=127.0.0.1	OPERATION=Submit Application Request	TARGET=ClientRMService	RESULT=SUCCESS	APPID=application_1560150672880_0003	CALLERCONTEXT=CLI
2019-06-10 04:28:28,744 INFO org.apache.hadoop.yarn.server.resourcemanager.rmapp.RMAppImpl: application_1560150672880_0003 State change from NEW to NEW_SAVING on event=START
2019-06-10 04:28:28,744 INFO org.apache.hadoop.yarn.server.resourcemanager.recovery.RMStateStore: Storing info for app: application_1560150672880_0003
2019-06-10 04:28:28,747 INFO org.apache.hadoop.yarn.server.resourcemanager.rmapp.RMAppImpl: application_1560150672880_0003 State change from NEW_SAVING to SUBMITTED on event=APP_NEW_SAVED
2019-06-10 04:28:28,748 INFO org.apache.hadoop.yarn.server.resourcemanager.scheduler.capacity.ParentQueue: Application added - appId: application_1560150672880_0003 user: hduser leaf-queue of parent: root #applications: 1
2019-06-10 04:28:28,748 INFO org.apache.hadoop.yarn.server.resourcemanager.scheduler.capacity.CapacityScheduler: Accepted application application_1560150672880_0003 from user: hduser, in queue: default
2019-06-10 04:28:28,751 INFO org.apache.hadoop.yarn.server.resourcemanager.rmapp.RMAppImpl: application_1560150672880_0003 State change from SUBMITTED to ACCEPTED on event=APP_ACCEPTED
2019-06-10 04:28:28,753 INFO org.apache.hadoop.yarn.server.resourcemanager.ApplicationMasterService: Registering app attempt : appattempt_1560150672880_0003_000001
2019-06-10 04:28:28,754 INFO org.apache.hadoop.yarn.server.resourcemanager.rmapp.attempt.RMAppAttemptImpl: appattempt_1560150672880_0003_000001 State change from NEW to SUBMITTED
2019-06-10 04:28:28,755 WARN org.apache.hadoop.yarn.server.resourcemanager.scheduler.capacity.LeafQueue: maximum-am-resource-percent is insufficient to start a single application in queue, it is likely set too low. skipping enforcement to allow at least one application to start
2019-06-10 04:28:28,755 WARN org.apache.hadoop.yarn.server.resourcemanager.scheduler.capacity.LeafQueue: maximum-am-resource-percent is insufficient to start a single application in queue for user, it is likely set too low. skipping enforcement to allow at least one application to start
2019-06-10 04:28:28,757 INFO org.apache.hadoop.yarn.server.resourcemanager.scheduler.capacity.LeafQueue: Application application_1560150672880_0003 from user: hduser activated in queue: default
2019-06-10 04:28:28,757 INFO org.apache.hadoop.yarn.server.resourcemanager.scheduler.capacity.LeafQueue: Application added - appId: application_1560150672880_0003 user: hduser, leaf-queue: default #user-pending-applications: 0 #user-active-applications: 1 #queue-pending-applications: 0 #queue-active-applications: 1
2019-06-10 04:28:28,758 INFO org.apache.hadoop.yarn.server.resourcemanager.scheduler.capacity.CapacityScheduler: Added Application Attempt appattempt_1560150672880_0003_000001 to scheduler from user hduser in queue default
2019-06-10 04:28:28,761 INFO org.apache.hadoop.yarn.server.resourcemanager.rmapp.attempt.RMAppAttemptImpl: appattempt_1560150672880_0003_000001 State change from SUBMITTED to SCHEDULED
2019-06-10 04:28:29,385 INFO org.apache.hadoop.yarn.server.resourcemanager.rmcontainer.RMContainerImpl: container_1560150672880_0003_01_000001 Container Transitioned from NEW to ALLOCATED
2019-06-10 04:28:29,386 INFO org.apache.hadoop.yarn.server.resourcemanager.RMAuditLogger: USER=hduser	OPERATION=AM Allocated Container	TARGET=SchedulerApp	RESULT=SUCCESS	APPID=application_1560150672880_0003	CONTAINERID=container_1560150672880_0003_01_000001
2019-06-10 04:28:29,386 INFO org.apache.hadoop.yarn.server.resourcemanager.scheduler.SchedulerNode: Assigned container container_1560150672880_0003_01_000001 of capacity <memory:2048, vCores:1> on host ubuntu:40311, which has 1 containers, <memory:2048, vCores:1> used and <memory:6144, vCores:7> available after allocation
2019-06-10 04:28:29,389 INFO org.apache.hadoop.yarn.server.resourcemanager.scheduler.capacity.allocator.AbstractContainerAllocator: assignedContainer application attempt=appattempt_1560150672880_0003_000001 container=container_1560150672880_0003_01_000001 queue=org.apache.hadoop.yarn.server.resourcemanager.scheduler.capacity.allocator.RegularContainerAllocator@2d9a25b0 clusterResource=<memory:8192, vCores:8> type=OFF_SWITCH requestedPartition=
2019-06-10 04:28:29,400 INFO org.apache.hadoop.yarn.server.resourcemanager.security.NMTokenSecretManagerInRM: Sending NMToken for nodeId : ubuntu:40311 for container : container_1560150672880_0003_01_000001
2019-06-10 04:28:29,406 INFO org.apache.hadoop.yarn.server.resourcemanager.rmcontainer.RMContainerImpl: container_1560150672880_0003_01_000001 Container Transitioned from ALLOCATED to ACQUIRED
2019-06-10 04:28:29,407 INFO org.apache.hadoop.yarn.server.resourcemanager.security.NMTokenSecretManagerInRM: Clear node set for appattempt_1560150672880_0003_000001
2019-06-10 04:28:29,408 INFO org.apache.hadoop.yarn.server.resourcemanager.scheduler.capacity.ParentQueue: Re-sorting assigned queue: root.default stats: default: capacity=1.0, absoluteCapacity=1.0, usedResources=<memory:2048, vCores:1>, usedCapacity=0.25, absoluteUsedCapacity=0.25, numApps=1, numContainers=1
2019-06-10 04:28:29,409 INFO org.apache.hadoop.yarn.server.resourcemanager.scheduler.capacity.ParentQueue: assignedContainer queue=root usedCapacity=0.25 absoluteUsedCapacity=0.25 used=<memory:2048, vCores:1> cluster=<memory:8192, vCores:8>
2019-06-10 04:28:29,409 INFO org.apache.hadoop.yarn.server.resourcemanager.rmapp.attempt.RMAppAttemptImpl: Storing attempt: AppId: application_1560150672880_0003 AttemptId: appattempt_1560150672880_0003_000001 MasterContainer: Container: [ContainerId: container_1560150672880_0003_01_000001, Version: 0, NodeId: ubuntu:40311, NodeHttpAddress: ubuntu:8042, Resource: <memory:2048, vCores:1>, Priority: 0, Token: Token { kind: ContainerToken, service: 127.0.1.1:40311 }, ]
2019-06-10 04:28:29,412 INFO org.apache.hadoop.yarn.server.resourcemanager.rmapp.attempt.RMAppAttemptImpl: appattempt_1560150672880_0003_000001 State change from SCHEDULED to ALLOCATED_SAVING
2019-06-10 04:28:29,412 INFO org.apache.hadoop.yarn.server.resourcemanager.rmapp.attempt.RMAppAttemptImpl: appattempt_1560150672880_0003_000001 State change from ALLOCATED_SAVING to ALLOCATED
2019-06-10 04:28:29,414 INFO org.apache.hadoop.yarn.server.resourcemanager.amlauncher.AMLauncher: Launching masterappattempt_1560150672880_0003_000001
2019-06-10 04:28:29,429 INFO org.apache.hadoop.yarn.server.resourcemanager.amlauncher.AMLauncher: Setting up container Container: [ContainerId: container_1560150672880_0003_01_000001, Version: 0, NodeId: ubuntu:40311, NodeHttpAddress: ubuntu:8042, Resource: <memory:2048, vCores:1>, Priority: 0, Token: Token { kind: ContainerToken, service: 127.0.1.1:40311 }, ] for AM appattempt_1560150672880_0003_000001
2019-06-10 04:28:29,433 INFO org.apache.hadoop.yarn.server.resourcemanager.security.AMRMTokenSecretManager: Create AMRMToken for ApplicationAttempt: appattempt_1560150672880_0003_000001
2019-06-10 04:28:29,433 INFO org.apache.hadoop.yarn.server.resourcemanager.security.AMRMTokenSecretManager: Creating password for appattempt_1560150672880_0003_000001
2019-06-10 04:28:29,516 INFO org.apache.hadoop.yarn.server.resourcemanager.amlauncher.AMLauncher: Done launching container Container: [ContainerId: container_1560150672880_0003_01_000001, Version: 0, NodeId: ubuntu:40311, NodeHttpAddress: ubuntu:8042, Resource: <memory:2048, vCores:1>, Priority: 0, Token: Token { kind: ContainerToken, service: 127.0.1.1:40311 }, ] for AM appattempt_1560150672880_0003_000001
2019-06-10 04:28:29,519 INFO org.apache.hadoop.yarn.server.resourcemanager.rmapp.attempt.RMAppAttemptImpl: appattempt_1560150672880_0003_000001 State change from ALLOCATED to LAUNCHED
2019-06-10 04:28:30,387 INFO org.apache.hadoop.yarn.server.resourcemanager.rmcontainer.RMContainerImpl: container_1560150672880_0003_01_000001 Container Transitioned from ACQUIRED to RUNNING
2019-06-10 04:28:50,577 INFO SecurityLogger.org.apache.hadoop.ipc.Server: Auth successful for appattempt_1560150672880_0003_000001 (auth:SIMPLE)
2019-06-10 04:28:50,588 INFO org.apache.hadoop.yarn.server.resourcemanager.ApplicationMasterService: AM registration appattempt_1560150672880_0003_000001
2019-06-10 04:28:50,588 INFO org.apache.hadoop.yarn.server.resourcemanager.rmapp.attempt.RMAppAttemptImpl: appattempt_1560150672880_0003_000001 State change from LAUNCHED to RUNNING
2019-06-10 04:28:50,588 INFO org.apache.hadoop.yarn.server.resourcemanager.RMAuditLogger: USER=hduser	IP=127.0.0.1	OPERATION=Register App Master	TARGET=ApplicationMasterService	RESULT=SUCCESS	APPID=application_1560150672880_0003	APPATTEMPTID=appattempt_1560150672880_0003_000001
2019-06-10 04:28:50,588 INFO org.apache.hadoop.yarn.server.resourcemanager.rmapp.RMAppImpl: application_1560150672880_0003 State change from ACCEPTED to RUNNING on event=ATTEMPT_REGISTERED
2019-06-10 04:28:53,952 INFO org.apache.hadoop.yarn.server.resourcemanager.rmcontainer.RMContainerImpl: container_1560150672880_0003_01_000002 Container Transitioned from NEW to ALLOCATED
2019-06-10 04:28:53,957 INFO org.apache.hadoop.yarn.server.resourcemanager.RMAuditLogger: USER=hduser	OPERATION=AM Allocated Container	TARGET=SchedulerApp	RESULT=SUCCESS	APPID=application_1560150672880_0003	CONTAINERID=container_1560150672880_0003_01_000002
2019-06-10 04:28:53,958 INFO org.apache.hadoop.yarn.server.resourcemanager.scheduler.SchedulerNode: Assigned container container_1560150672880_0003_01_000002 of capacity <memory:1024, vCores:1> on host ubuntu:40311, which has 2 containers, <memory:3072, vCores:2> used and <memory:5120, vCores:6> available after allocation
2019-06-10 04:28:53,958 INFO org.apache.hadoop.yarn.server.resourcemanager.scheduler.capacity.allocator.AbstractContainerAllocator: assignedContainer application attempt=appattempt_1560150672880_0003_000001 container=container_1560150672880_0003_01_000002 queue=org.apache.hadoop.yarn.server.resourcemanager.scheduler.capacity.allocator.RegularContainerAllocator@2d9a25b0 clusterResource=<memory:8192, vCores:8> type=OFF_SWITCH requestedPartition=
2019-06-10 04:28:53,962 INFO org.apache.hadoop.yarn.server.resourcemanager.scheduler.capacity.ParentQueue: Re-sorting assigned queue: root.default stats: default: capacity=1.0, absoluteCapacity=1.0, usedResources=<memory:3072, vCores:2>, usedCapacity=0.375, absoluteUsedCapacity=0.375, numApps=1, numContainers=2
2019-06-10 04:28:53,963 INFO org.apache.hadoop.yarn.server.resourcemanager.scheduler.capacity.ParentQueue: assignedContainer queue=root usedCapacity=0.375 absoluteUsedCapacity=0.375 used=<memory:3072, vCores:2> cluster=<memory:8192, vCores:8>
2019-06-10 04:28:54,946 INFO org.apache.hadoop.yarn.server.resourcemanager.security.NMTokenSecretManagerInRM: Sending NMToken for nodeId : ubuntu:40311 for container : container_1560150672880_0003_01_000002
2019-06-10 04:28:54,994 INFO org.apache.hadoop.yarn.server.resourcemanager.rmcontainer.RMContainerImpl: container_1560150672880_0003_01_000002 Container Transitioned from ALLOCATED to ACQUIRED
2019-06-10 04:28:54,998 INFO org.apache.hadoop.yarn.server.resourcemanager.rmcontainer.RMContainerImpl: container_1560150672880_0003_01_000003 Container Transitioned from NEW to ALLOCATED
2019-06-10 04:28:54,998 INFO org.apache.hadoop.yarn.server.resourcemanager.RMAuditLogger: USER=hduser	OPERATION=AM Allocated Container	TARGET=SchedulerApp	RESULT=SUCCESS	APPID=application_1560150672880_0003	CONTAINERID=container_1560150672880_0003_01_000003
2019-06-10 04:28:54,999 INFO org.apache.hadoop.yarn.server.resourcemanager.scheduler.SchedulerNode: Assigned container container_1560150672880_0003_01_000003 of capacity <memory:1024, vCores:1> on host ubuntu:40311, which has 3 containers, <memory:4096, vCores:3> used and <memory:4096, vCores:5> available after allocation
2019-06-10 04:28:55,001 INFO org.apache.hadoop.yarn.server.resourcemanager.scheduler.capacity.allocator.AbstractContainerAllocator: assignedContainer application attempt=appattempt_1560150672880_0003_000001 container=container_1560150672880_0003_01_000003 queue=org.apache.hadoop.yarn.server.resourcemanager.scheduler.capacity.allocator.RegularContainerAllocator@2d9a25b0 clusterResource=<memory:8192, vCores:8> type=OFF_SWITCH requestedPartition=
2019-06-10 04:28:55,046 INFO org.apache.hadoop.yarn.server.resourcemanager.scheduler.capacity.ParentQueue: Re-sorting assigned queue: root.default stats: default: capacity=1.0, absoluteCapacity=1.0, usedResources=<memory:4096, vCores:3>, usedCapacity=0.5, absoluteUsedCapacity=0.5, numApps=1, numContainers=3
2019-06-10 04:28:55,047 INFO org.apache.hadoop.yarn.server.resourcemanager.scheduler.capacity.ParentQueue: assignedContainer queue=root usedCapacity=0.5 absoluteUsedCapacity=0.5 used=<memory:4096, vCores:3> cluster=<memory:8192, vCores:8>
2019-06-10 04:28:56,031 INFO org.apache.hadoop.yarn.server.resourcemanager.rmcontainer.RMContainerImpl: container_1560150672880_0003_01_000004 Container Transitioned from NEW to ALLOCATED
2019-06-10 04:28:56,035 INFO org.apache.hadoop.yarn.server.resourcemanager.RMAuditLogger: USER=hduser	OPERATION=AM Allocated Container	TARGET=SchedulerApp	RESULT=SUCCESS	APPID=application_1560150672880_0003	CONTAINERID=container_1560150672880_0003_01_000004
2019-06-10 04:28:56,036 INFO org.apache.hadoop.yarn.server.resourcemanager.scheduler.SchedulerNode: Assigned container container_1560150672880_0003_01_000004 of capacity <memory:1024, vCores:1> on host ubuntu:40311, which has 4 containers, <memory:5120, vCores:4> used and <memory:3072, vCores:4> available after allocation
2019-06-10 04:28:56,037 INFO org.apache.hadoop.yarn.server.resourcemanager.scheduler.capacity.allocator.AbstractContainerAllocator: assignedContainer application attempt=appattempt_1560150672880_0003_000001 container=container_1560150672880_0003_01_000004 queue=org.apache.hadoop.yarn.server.resourcemanager.scheduler.capacity.allocator.RegularContainerAllocator@2d9a25b0 clusterResource=<memory:8192, vCores:8> type=OFF_SWITCH requestedPartition=
2019-06-10 04:28:56,039 INFO org.apache.hadoop.yarn.server.resourcemanager.scheduler.capacity.ParentQueue: Re-sorting assigned queue: root.default stats: default: capacity=1.0, absoluteCapacity=1.0, usedResources=<memory:5120, vCores:4>, usedCapacity=0.625, absoluteUsedCapacity=0.625, numApps=1, numContainers=4
2019-06-10 04:28:56,041 INFO org.apache.hadoop.yarn.server.resourcemanager.scheduler.capacity.ParentQueue: assignedContainer queue=root usedCapacity=0.625 absoluteUsedCapacity=0.625 used=<memory:5120, vCores:4> cluster=<memory:8192, vCores:8>
2019-06-10 04:28:57,114 INFO org.apache.hadoop.yarn.server.resourcemanager.rmcontainer.RMContainerImpl: container_1560150672880_0003_01_000005 Container Transitioned from NEW to ALLOCATED
2019-06-10 04:28:57,118 INFO org.apache.hadoop.yarn.server.resourcemanager.RMAuditLogger: USER=hduser	OPERATION=AM Allocated Container	TARGET=SchedulerApp	RESULT=SUCCESS	APPID=application_1560150672880_0003	CONTAINERID=container_1560150672880_0003_01_000005
2019-06-10 04:28:57,119 INFO org.apache.hadoop.yarn.server.resourcemanager.scheduler.SchedulerNode: Assigned container container_1560150672880_0003_01_000005 of capacity <memory:1024, vCores:1> on host ubuntu:40311, which has 5 containers, <memory:6144, vCores:5> used and <memory:2048, vCores:3> available after allocation
2019-06-10 04:28:57,121 INFO org.apache.hadoop.yarn.server.resourcemanager.scheduler.capacity.allocator.AbstractContainerAllocator: assignedContainer application attempt=appattempt_1560150672880_0003_000001 container=container_1560150672880_0003_01_000005 queue=org.apache.hadoop.yarn.server.resourcemanager.scheduler.capacity.allocator.RegularContainerAllocator@2d9a25b0 clusterResource=<memory:8192, vCores:8> type=OFF_SWITCH requestedPartition=
2019-06-10 04:28:57,132 INFO org.apache.hadoop.yarn.server.resourcemanager.scheduler.capacity.ParentQueue: Re-sorting assigned queue: root.default stats: default: capacity=1.0, absoluteCapacity=1.0, usedResources=<memory:6144, vCores:5>, usedCapacity=0.75, absoluteUsedCapacity=0.75, numApps=1, numContainers=5
2019-06-10 04:28:57,134 INFO org.apache.hadoop.yarn.server.resourcemanager.scheduler.capacity.ParentQueue: assignedContainer queue=root usedCapacity=0.75 absoluteUsedCapacity=0.75 used=<memory:6144, vCores:5> cluster=<memory:8192, vCores:8>
2019-06-10 04:28:59,547 INFO org.apache.hadoop.yarn.server.resourcemanager.rmcontainer.RMContainerImpl: container_1560150672880_0003_01_000003 Container Transitioned from ALLOCATED to ACQUIRED
2019-06-10 04:28:59,575 INFO org.apache.hadoop.yarn.server.resourcemanager.rmcontainer.RMContainerImpl: container_1560150672880_0003_01_000004 Container Transitioned from ALLOCATED to ACQUIRED
2019-06-10 04:28:59,592 INFO org.apache.hadoop.yarn.server.resourcemanager.rmcontainer.RMContainerImpl: container_1560150672880_0003_01_000005 Container Transitioned from ALLOCATED to ACQUIRED
2019-06-10 04:29:00,102 INFO org.apache.hadoop.yarn.server.resourcemanager.rmcontainer.RMContainerImpl: container_1560150672880_0003_01_000006 Container Transitioned from NEW to ALLOCATED
2019-06-10 04:29:00,103 INFO org.apache.hadoop.yarn.server.resourcemanager.RMAuditLogger: USER=hduser	OPERATION=AM Allocated Container	TARGET=SchedulerApp	RESULT=SUCCESS	APPID=application_1560150672880_0003	CONTAINERID=container_1560150672880_0003_01_000006
2019-06-10 04:29:00,104 INFO org.apache.hadoop.yarn.server.resourcemanager.scheduler.SchedulerNode: Assigned container container_1560150672880_0003_01_000006 of capacity <memory:1024, vCores:1> on host ubuntu:40311, which has 6 containers, <memory:7168, vCores:6> used and <memory:1024, vCores:2> available after allocation
2019-06-10 04:29:00,107 INFO org.apache.hadoop.yarn.server.resourcemanager.scheduler.capacity.allocator.AbstractContainerAllocator: assignedContainer application attempt=appattempt_1560150672880_0003_000001 container=container_1560150672880_0003_01_000006 queue=org.apache.hadoop.yarn.server.resourcemanager.scheduler.capacity.allocator.RegularContainerAllocator@2d9a25b0 clusterResource=<memory:8192, vCores:8> type=OFF_SWITCH requestedPartition=
2019-06-10 04:29:00,110 INFO org.apache.hadoop.yarn.server.resourcemanager.scheduler.capacity.ParentQueue: Re-sorting assigned queue: root.default stats: default: capacity=1.0, absoluteCapacity=1.0, usedResources=<memory:7168, vCores:6>, usedCapacity=0.875, absoluteUsedCapacity=0.875, numApps=1, numContainers=6
2019-06-10 04:29:00,111 INFO org.apache.hadoop.yarn.server.resourcemanager.scheduler.capacity.ParentQueue: assignedContainer queue=root usedCapacity=0.875 absoluteUsedCapacity=0.875 used=<memory:7168, vCores:6> cluster=<memory:8192, vCores:8>
2019-06-10 04:29:00,629 INFO org.apache.hadoop.yarn.server.resourcemanager.scheduler.AppSchedulingInfo: checking for deactivate of application :application_1560150672880_0003
2019-06-10 04:29:00,639 INFO org.apache.hadoop.yarn.server.resourcemanager.rmcontainer.RMContainerImpl: container_1560150672880_0003_01_000006 Container Transitioned from ALLOCATED to ACQUIRED
2019-06-10 04:29:01,665 INFO org.apache.hadoop.yarn.server.resourcemanager.rmcontainer.RMContainerImpl: container_1560150672880_0003_01_000002 Container Transitioned from ACQUIRED to RELEASED
2019-06-10 04:29:01,669 INFO org.apache.hadoop.yarn.server.resourcemanager.RMAuditLogger: USER=hduser	IP=127.0.0.1	OPERATION=AM Released Container	TARGET=SchedulerApp	RESULT=SUCCESS	APPID=application_1560150672880_0003	CONTAINERID=container_1560150672880_0003_01_000002
2019-06-10 04:29:01,670 INFO org.apache.hadoop.yarn.server.resourcemanager.scheduler.SchedulerNode: Released container container_1560150672880_0003_01_000002 of capacity <memory:1024, vCores:1> on host ubuntu:40311, which currently has 5 containers, <memory:6144, vCores:5> used and <memory:2048, vCores:3> available, release resources=true
2019-06-10 04:29:01,676 INFO org.apache.hadoop.yarn.server.resourcemanager.rmcontainer.RMContainerImpl: container_1560150672880_0003_01_000003 Container Transitioned from ACQUIRED to RELEASED
2019-06-10 04:29:01,677 INFO org.apache.hadoop.yarn.server.resourcemanager.RMAuditLogger: USER=hduser	IP=127.0.0.1	OPERATION=AM Released Container	TARGET=SchedulerApp	RESULT=SUCCESS	APPID=application_1560150672880_0003	CONTAINERID=container_1560150672880_0003_01_000003
2019-06-10 04:29:01,679 INFO org.apache.hadoop.yarn.server.resourcemanager.scheduler.SchedulerNode: Released container container_1560150672880_0003_01_000003 of capacity <memory:1024, vCores:1> on host ubuntu:40311, which currently has 4 containers, <memory:5120, vCores:4> used and <memory:3072, vCores:4> available, release resources=true
2019-06-10 04:29:01,681 INFO org.apache.hadoop.yarn.server.resourcemanager.rmcontainer.RMContainerImpl: container_1560150672880_0003_01_000004 Container Transitioned from ACQUIRED to RELEASED
2019-06-10 04:29:01,682 INFO org.apache.hadoop.yarn.server.resourcemanager.RMAuditLogger: USER=hduser	IP=127.0.0.1	OPERATION=AM Released Container	TARGET=SchedulerApp	RESULT=SUCCESS	APPID=application_1560150672880_0003	CONTAINERID=container_1560150672880_0003_01_000004
2019-06-10 04:29:01,686 INFO org.apache.hadoop.yarn.server.resourcemanager.scheduler.SchedulerNode: Released container container_1560150672880_0003_01_000004 of capacity <memory:1024, vCores:1> on host ubuntu:40311, which currently has 3 containers, <memory:4096, vCores:3> used and <memory:4096, vCores:5> available, release resources=true
2019-06-10 04:29:01,709 INFO org.apache.hadoop.yarn.server.resourcemanager.rmcontainer.RMContainerImpl: container_1560150672880_0003_01_000005 Container Transitioned from ACQUIRED to RELEASED
2019-06-10 04:29:01,710 INFO org.apache.hadoop.yarn.server.resourcemanager.RMAuditLogger: USER=hduser	IP=127.0.0.1	OPERATION=AM Released Container	TARGET=SchedulerApp	RESULT=SUCCESS	APPID=application_1560150672880_0003	CONTAINERID=container_1560150672880_0003_01_000005
2019-06-10 04:29:01,711 INFO org.apache.hadoop.yarn.server.resourcemanager.scheduler.SchedulerNode: Released container container_1560150672880_0003_01_000005 of capacity <memory:1024, vCores:1> on host ubuntu:40311, which currently has 2 containers, <memory:3072, vCores:2> used and <memory:5120, vCores:6> available, release resources=true
2019-06-10 04:29:01,715 INFO org.apache.hadoop.yarn.server.resourcemanager.rmcontainer.RMContainerImpl: container_1560150672880_0003_01_000006 Container Transitioned from ACQUIRED to RELEASED
2019-06-10 04:29:01,715 INFO org.apache.hadoop.yarn.server.resourcemanager.RMAuditLogger: USER=hduser	IP=127.0.0.1	OPERATION=AM Released Container	TARGET=SchedulerApp	RESULT=SUCCESS	APPID=application_1560150672880_0003	CONTAINERID=container_1560150672880_0003_01_000006
2019-06-10 04:29:01,716 INFO org.apache.hadoop.yarn.server.resourcemanager.scheduler.SchedulerNode: Released container container_1560150672880_0003_01_000006 of capacity <memory:1024, vCores:1> on host ubuntu:40311, which currently has 1 containers, <memory:2048, vCores:1> used and <memory:6144, vCores:7> available, release resources=true
2019-06-10 04:29:01,742 INFO org.apache.hadoop.yarn.server.resourcemanager.ApplicationMasterService: blacklist are updated in Scheduler.blacklistAdditions: [ubuntu], blacklistRemovals: []
2019-06-10 04:29:02,867 INFO org.apache.hadoop.yarn.server.resourcemanager.ApplicationMasterService: blacklist are updated in Scheduler.blacklistAdditions: [], blacklistRemovals: [ubuntu]
2019-06-10 04:29:03,156 INFO org.apache.hadoop.yarn.server.resourcemanager.rmcontainer.RMContainerImpl: container_1560150672880_0003_01_000007 Container Transitioned from NEW to ALLOCATED
2019-06-10 04:29:03,157 INFO org.apache.hadoop.yarn.server.resourcemanager.RMAuditLogger: USER=hduser	OPERATION=AM Allocated Container	TARGET=SchedulerApp	RESULT=SUCCESS	APPID=application_1560150672880_0003	CONTAINERID=container_1560150672880_0003_01_000007
2019-06-10 04:29:03,159 INFO org.apache.hadoop.yarn.server.resourcemanager.scheduler.SchedulerNode: Assigned container container_1560150672880_0003_01_000007 of capacity <memory:1024, vCores:1> on host ubuntu:40311, which has 2 containers, <memory:3072, vCores:2> used and <memory:5120, vCores:6> available after allocation
2019-06-10 04:29:03,160 INFO org.apache.hadoop.yarn.server.resourcemanager.scheduler.capacity.allocator.AbstractContainerAllocator: assignedContainer application attempt=appattempt_1560150672880_0003_000001 container=container_1560150672880_0003_01_000007 queue=org.apache.hadoop.yarn.server.resourcemanager.scheduler.capacity.allocator.RegularContainerAllocator@2d9a25b0 clusterResource=<memory:8192, vCores:8> type=OFF_SWITCH requestedPartition=
2019-06-10 04:29:03,163 INFO org.apache.hadoop.yarn.server.resourcemanager.scheduler.capacity.ParentQueue: Re-sorting assigned queue: root.default stats: default: capacity=1.0, absoluteCapacity=1.0, usedResources=<memory:3072, vCores:2>, usedCapacity=0.375, absoluteUsedCapacity=0.375, numApps=1, numContainers=2
2019-06-10 04:29:03,166 INFO org.apache.hadoop.yarn.server.resourcemanager.scheduler.capacity.ParentQueue: assignedContainer queue=root usedCapacity=0.375 absoluteUsedCapacity=0.375 used=<memory:3072, vCores:2> cluster=<memory:8192, vCores:8>
2019-06-10 04:29:03,948 INFO org.apache.hadoop.yarn.server.resourcemanager.rmcontainer.RMContainerImpl: container_1560150672880_0003_01_000007 Container Transitioned from ALLOCATED to ACQUIRED
2019-06-10 04:29:04,148 INFO org.apache.hadoop.yarn.server.resourcemanager.rmcontainer.RMContainerImpl: container_1560150672880_0003_01_000008 Container Transitioned from NEW to ALLOCATED
2019-06-10 04:29:04,149 INFO org.apache.hadoop.yarn.server.resourcemanager.RMAuditLogger: USER=hduser	OPERATION=AM Allocated Container	TARGET=SchedulerApp	RESULT=SUCCESS	APPID=application_1560150672880_0003	CONTAINERID=container_1560150672880_0003_01_000008
2019-06-10 04:29:04,150 INFO org.apache.hadoop.yarn.server.resourcemanager.scheduler.SchedulerNode: Assigned container container_1560150672880_0003_01_000008 of capacity <memory:1024, vCores:1> on host ubuntu:40311, which has 3 containers, <memory:4096, vCores:3> used and <memory:4096, vCores:5> available after allocation
2019-06-10 04:29:04,152 INFO org.apache.hadoop.yarn.server.resourcemanager.scheduler.capacity.allocator.AbstractContainerAllocator: assignedContainer application attempt=appattempt_1560150672880_0003_000001 container=container_1560150672880_0003_01_000008 queue=org.apache.hadoop.yarn.server.resourcemanager.scheduler.capacity.allocator.RegularContainerAllocator@2d9a25b0 clusterResource=<memory:8192, vCores:8> type=OFF_SWITCH requestedPartition=
2019-06-10 04:29:04,156 INFO org.apache.hadoop.yarn.server.resourcemanager.scheduler.capacity.ParentQueue: Re-sorting assigned queue: root.default stats: default: capacity=1.0, absoluteCapacity=1.0, usedResources=<memory:4096, vCores:3>, usedCapacity=0.5, absoluteUsedCapacity=0.5, numApps=1, numContainers=3
2019-06-10 04:29:04,158 INFO org.apache.hadoop.yarn.server.resourcemanager.scheduler.capacity.ParentQueue: assignedContainer queue=root usedCapacity=0.5 absoluteUsedCapacity=0.5 used=<memory:4096, vCores:3> cluster=<memory:8192, vCores:8>
2019-06-10 04:29:05,013 INFO org.apache.hadoop.yarn.server.resourcemanager.rmcontainer.RMContainerImpl: container_1560150672880_0003_01_000007 Container Transitioned from ACQUIRED to RELEASED
2019-06-10 04:29:05,014 INFO org.apache.hadoop.yarn.server.resourcemanager.RMAuditLogger: USER=hduser	IP=127.0.0.1	OPERATION=AM Released Container	TARGET=SchedulerApp	RESULT=SUCCESS	APPID=application_1560150672880_0003	CONTAINERID=container_1560150672880_0003_01_000007
2019-06-10 04:29:05,020 INFO org.apache.hadoop.yarn.server.resourcemanager.scheduler.SchedulerNode: Released container container_1560150672880_0003_01_000007 of capacity <memory:1024, vCores:1> on host ubuntu:40311, which currently has 2 containers, <memory:3072, vCores:2> used and <memory:5120, vCores:6> available, release resources=true
2019-06-10 04:29:05,079 INFO org.apache.hadoop.yarn.server.resourcemanager.rmcontainer.RMContainerImpl: container_1560150672880_0003_01_000008 Container Transitioned from ALLOCATED to ACQUIRED
2019-06-10 04:29:05,172 INFO org.apache.hadoop.yarn.server.resourcemanager.rmcontainer.RMContainerImpl: container_1560150672880_0003_01_000009 Container Transitioned from NEW to ALLOCATED
2019-06-10 04:29:05,174 INFO org.apache.hadoop.yarn.server.resourcemanager.RMAuditLogger: USER=hduser	OPERATION=AM Allocated Container	TARGET=SchedulerApp	RESULT=SUCCESS	APPID=application_1560150672880_0003	CONTAINERID=container_1560150672880_0003_01_000009
2019-06-10 04:29:05,176 INFO org.apache.hadoop.yarn.server.resourcemanager.scheduler.SchedulerNode: Assigned container container_1560150672880_0003_01_000009 of capacity <memory:1024, vCores:1> on host ubuntu:40311, which has 3 containers, <memory:4096, vCores:3> used and <memory:4096, vCores:5> available after allocation
2019-06-10 04:29:05,181 INFO org.apache.hadoop.yarn.server.resourcemanager.scheduler.capacity.allocator.AbstractContainerAllocator: assignedContainer application attempt=appattempt_1560150672880_0003_000001 container=container_1560150672880_0003_01_000009 queue=org.apache.hadoop.yarn.server.resourcemanager.scheduler.capacity.allocator.RegularContainerAllocator@2d9a25b0 clusterResource=<memory:8192, vCores:8> type=OFF_SWITCH requestedPartition=
2019-06-10 04:29:05,191 INFO org.apache.hadoop.yarn.server.resourcemanager.scheduler.capacity.ParentQueue: Re-sorting assigned queue: root.default stats: default: capacity=1.0, absoluteCapacity=1.0, usedResources=<memory:4096, vCores:3>, usedCapacity=0.5, absoluteUsedCapacity=0.5, numApps=1, numContainers=3
2019-06-10 04:29:05,195 INFO org.apache.hadoop.yarn.server.resourcemanager.scheduler.capacity.ParentQueue: assignedContainer queue=root usedCapacity=0.5 absoluteUsedCapacity=0.5 used=<memory:4096, vCores:3> cluster=<memory:8192, vCores:8>
2019-06-10 04:29:06,195 INFO org.apache.hadoop.yarn.server.resourcemanager.rmcontainer.RMContainerImpl: container_1560150672880_0003_01_000010 Container Transitioned from NEW to ALLOCATED
2019-06-10 04:29:06,196 INFO org.apache.hadoop.yarn.server.resourcemanager.RMAuditLogger: USER=hduser	OPERATION=AM Allocated Container	TARGET=SchedulerApp	RESULT=SUCCESS	APPID=application_1560150672880_0003	CONTAINERID=container_1560150672880_0003_01_000010
2019-06-10 04:29:06,197 INFO org.apache.hadoop.yarn.server.resourcemanager.scheduler.SchedulerNode: Assigned container container_1560150672880_0003_01_000010 of capacity <memory:1024, vCores:1> on host ubuntu:40311, which has 4 containers, <memory:5120, vCores:4> used and <memory:3072, vCores:4> available after allocation
2019-06-10 04:29:06,205 INFO org.apache.hadoop.yarn.server.resourcemanager.scheduler.capacity.allocator.AbstractContainerAllocator: assignedContainer application attempt=appattempt_1560150672880_0003_000001 container=container_1560150672880_0003_01_000010 queue=org.apache.hadoop.yarn.server.resourcemanager.scheduler.capacity.allocator.RegularContainerAllocator@2d9a25b0 clusterResource=<memory:8192, vCores:8> type=OFF_SWITCH requestedPartition=
2019-06-10 04:29:06,210 INFO org.apache.hadoop.yarn.server.resourcemanager.rmcontainer.RMContainerImpl: container_1560150672880_0003_01_000008 Container Transitioned from ACQUIRED to RELEASED
2019-06-10 04:29:06,215 INFO org.apache.hadoop.yarn.server.resourcemanager.RMAuditLogger: USER=hduser	IP=127.0.0.1	OPERATION=AM Released Container	TARGET=SchedulerApp	RESULT=SUCCESS	APPID=application_1560150672880_0003	CONTAINERID=container_1560150672880_0003_01_000008
2019-06-10 04:29:06,217 INFO org.apache.hadoop.yarn.server.resourcemanager.scheduler.SchedulerNode: Released container container_1560150672880_0003_01_000008 of capacity <memory:1024, vCores:1> on host ubuntu:40311, which currently has 3 containers, <memory:4096, vCores:3> used and <memory:4096, vCores:5> available, release resources=true
2019-06-10 04:29:06,211 INFO org.apache.hadoop.yarn.server.resourcemanager.scheduler.capacity.ParentQueue: Re-sorting assigned queue: root.default stats: default: capacity=1.0, absoluteCapacity=1.0, usedResources=<memory:5120, vCores:4>, usedCapacity=0.625, absoluteUsedCapacity=0.625, numApps=1, numContainers=4
2019-06-10 04:29:06,225 INFO org.apache.hadoop.yarn.server.resourcemanager.scheduler.capacity.ParentQueue: assignedContainer queue=root usedCapacity=0.625 absoluteUsedCapacity=0.625 used=<memory:5120, vCores:4> cluster=<memory:8192, vCores:8>
2019-06-10 04:29:06,261 INFO org.apache.hadoop.yarn.server.resourcemanager.rmcontainer.RMContainerImpl: container_1560150672880_0003_01_000009 Container Transitioned from ALLOCATED to ACQUIRED
2019-06-10 04:29:06,276 INFO org.apache.hadoop.yarn.server.resourcemanager.rmcontainer.RMContainerImpl: container_1560150672880_0003_01_000010 Container Transitioned from ALLOCATED to ACQUIRED
2019-06-10 04:29:07,243 INFO org.apache.hadoop.yarn.server.resourcemanager.rmcontainer.RMContainerImpl: container_1560150672880_0003_01_000011 Container Transitioned from NEW to ALLOCATED
2019-06-10 04:29:07,246 INFO org.apache.hadoop.yarn.server.resourcemanager.RMAuditLogger: USER=hduser	OPERATION=AM Allocated Container	TARGET=SchedulerApp	RESULT=SUCCESS	APPID=application_1560150672880_0003	CONTAINERID=container_1560150672880_0003_01_000011
2019-06-10 04:29:07,247 INFO org.apache.hadoop.yarn.server.resourcemanager.scheduler.SchedulerNode: Assigned container container_1560150672880_0003_01_000011 of capacity <memory:1024, vCores:1> on host ubuntu:40311, which has 4 containers, <memory:5120, vCores:4> used and <memory:3072, vCores:4> available after allocation
2019-06-10 04:29:07,252 INFO org.apache.hadoop.yarn.server.resourcemanager.scheduler.capacity.allocator.AbstractContainerAllocator: assignedContainer application attempt=appattempt_1560150672880_0003_000001 container=container_1560150672880_0003_01_000011 queue=org.apache.hadoop.yarn.server.resourcemanager.scheduler.capacity.allocator.RegularContainerAllocator@2d9a25b0 clusterResource=<memory:8192, vCores:8> type=OFF_SWITCH requestedPartition=
2019-06-10 04:29:07,257 INFO org.apache.hadoop.yarn.server.resourcemanager.scheduler.capacity.ParentQueue: Re-sorting assigned queue: root.default stats: default: capacity=1.0, absoluteCapacity=1.0, usedResources=<memory:5120, vCores:4>, usedCapacity=0.625, absoluteUsedCapacity=0.625, numApps=1, numContainers=4
2019-06-10 04:29:07,258 INFO org.apache.hadoop.yarn.server.resourcemanager.scheduler.capacity.ParentQueue: assignedContainer queue=root usedCapacity=0.625 absoluteUsedCapacity=0.625 used=<memory:5120, vCores:4> cluster=<memory:8192, vCores:8>
2019-06-10 04:29:07,314 INFO org.apache.hadoop.yarn.server.resourcemanager.rmcontainer.RMContainerImpl: container_1560150672880_0003_01_000009 Container Transitioned from ACQUIRED to RELEASED
2019-06-10 04:29:07,316 INFO org.apache.hadoop.yarn.server.resourcemanager.RMAuditLogger: USER=hduser	IP=127.0.0.1	OPERATION=AM Released Container	TARGET=SchedulerApp	RESULT=SUCCESS	APPID=application_1560150672880_0003	CONTAINERID=container_1560150672880_0003_01_000009
2019-06-10 04:29:07,317 INFO org.apache.hadoop.yarn.server.resourcemanager.scheduler.SchedulerNode: Released container container_1560150672880_0003_01_000009 of capacity <memory:1024, vCores:1> on host ubuntu:40311, which currently has 3 containers, <memory:4096, vCores:3> used and <memory:4096, vCores:5> available, release resources=true
2019-06-10 04:29:07,321 INFO org.apache.hadoop.yarn.server.resourcemanager.rmcontainer.RMContainerImpl: container_1560150672880_0003_01_000010 Container Transitioned from ACQUIRED to RELEASED
2019-06-10 04:29:07,329 INFO org.apache.hadoop.yarn.server.resourcemanager.RMAuditLogger: USER=hduser	IP=127.0.0.1	OPERATION=AM Released Container	TARGET=SchedulerApp	RESULT=SUCCESS	APPID=application_1560150672880_0003	CONTAINERID=container_1560150672880_0003_01_000010
2019-06-10 04:29:07,333 INFO org.apache.hadoop.yarn.server.resourcemanager.scheduler.SchedulerNode: Released container container_1560150672880_0003_01_000010 of capacity <memory:1024, vCores:1> on host ubuntu:40311, which currently has 2 containers, <memory:3072, vCores:2> used and <memory:5120, vCores:6> available, release resources=true
2019-06-10 04:29:07,365 INFO org.apache.hadoop.yarn.server.resourcemanager.rmcontainer.RMContainerImpl: container_1560150672880_0003_01_000011 Container Transitioned from ALLOCATED to ACQUIRED
2019-06-10 04:29:08,304 INFO org.apache.hadoop.yarn.server.resourcemanager.rmcontainer.RMContainerImpl: container_1560150672880_0003_01_000012 Container Transitioned from NEW to ALLOCATED
2019-06-10 04:29:08,306 INFO org.apache.hadoop.yarn.server.resourcemanager.RMAuditLogger: USER=hduser	OPERATION=AM Allocated Container	TARGET=SchedulerApp	RESULT=SUCCESS	APPID=application_1560150672880_0003	CONTAINERID=container_1560150672880_0003_01_000012
2019-06-10 04:29:08,307 INFO org.apache.hadoop.yarn.server.resourcemanager.scheduler.SchedulerNode: Assigned container container_1560150672880_0003_01_000012 of capacity <memory:1024, vCores:1> on host ubuntu:40311, which has 3 containers, <memory:4096, vCores:3> used and <memory:4096, vCores:5> available after allocation
2019-06-10 04:29:08,309 INFO org.apache.hadoop.yarn.server.resourcemanager.scheduler.capacity.allocator.AbstractContainerAllocator: assignedContainer application attempt=appattempt_1560150672880_0003_000001 container=container_1560150672880_0003_01_000012 queue=org.apache.hadoop.yarn.server.resourcemanager.scheduler.capacity.allocator.RegularContainerAllocator@2d9a25b0 clusterResource=<memory:8192, vCores:8> type=OFF_SWITCH requestedPartition=
2019-06-10 04:29:08,313 INFO org.apache.hadoop.yarn.server.resourcemanager.scheduler.capacity.ParentQueue: Re-sorting assigned queue: root.default stats: default: capacity=1.0, absoluteCapacity=1.0, usedResources=<memory:4096, vCores:3>, usedCapacity=0.5, absoluteUsedCapacity=0.5, numApps=1, numContainers=3
2019-06-10 04:29:08,314 INFO org.apache.hadoop.yarn.server.resourcemanager.scheduler.capacity.ParentQueue: assignedContainer queue=root usedCapacity=0.5 absoluteUsedCapacity=0.5 used=<memory:4096, vCores:3> cluster=<memory:8192, vCores:8>
2019-06-10 04:29:08,420 INFO org.apache.hadoop.yarn.server.resourcemanager.rmcontainer.RMContainerImpl: container_1560150672880_0003_01_000011 Container Transitioned from ACQUIRED to RELEASED
2019-06-10 04:29:08,423 INFO org.apache.hadoop.yarn.server.resourcemanager.RMAuditLogger: USER=hduser	IP=127.0.0.1	OPERATION=AM Released Container	TARGET=SchedulerApp	RESULT=SUCCESS	APPID=application_1560150672880_0003	CONTAINERID=container_1560150672880_0003_01_000011
2019-06-10 04:29:08,424 INFO org.apache.hadoop.yarn.server.resourcemanager.scheduler.SchedulerNode: Released container container_1560150672880_0003_01_000011 of capacity <memory:1024, vCores:1> on host ubuntu:40311, which currently has 2 containers, <memory:3072, vCores:2> used and <memory:5120, vCores:6> available, release resources=true
2019-06-10 04:29:08,439 INFO org.apache.hadoop.yarn.server.resourcemanager.rmcontainer.RMContainerImpl: container_1560150672880_0003_01_000012 Container Transitioned from ALLOCATED to ACQUIRED
2019-06-10 04:29:09,523 INFO org.apache.hadoop.yarn.server.resourcemanager.rmcontainer.RMContainerImpl: container_1560150672880_0003_01_000013 Container Transitioned from NEW to ALLOCATED
2019-06-10 04:29:09,526 INFO org.apache.hadoop.yarn.server.resourcemanager.RMAuditLogger: USER=hduser	OPERATION=AM Allocated Container	TARGET=SchedulerApp	RESULT=SUCCESS	APPID=application_1560150672880_0003	CONTAINERID=container_1560150672880_0003_01_000013
2019-06-10 04:29:09,528 INFO org.apache.hadoop.yarn.server.resourcemanager.scheduler.SchedulerNode: Assigned container container_1560150672880_0003_01_000013 of capacity <memory:1024, vCores:1> on host ubuntu:40311, which has 3 containers, <memory:4096, vCores:3> used and <memory:4096, vCores:5> available after allocation
2019-06-10 04:29:09,537 INFO org.apache.hadoop.yarn.server.resourcemanager.scheduler.capacity.allocator.AbstractContainerAllocator: assignedContainer application attempt=appattempt_1560150672880_0003_000001 container=container_1560150672880_0003_01_000013 queue=org.apache.hadoop.yarn.server.resourcemanager.scheduler.capacity.allocator.RegularContainerAllocator@2d9a25b0 clusterResource=<memory:8192, vCores:8> type=OFF_SWITCH requestedPartition=
2019-06-10 04:29:09,545 INFO org.apache.hadoop.yarn.server.resourcemanager.scheduler.capacity.ParentQueue: Re-sorting assigned queue: root.default stats: default: capacity=1.0, absoluteCapacity=1.0, usedResources=<memory:4096, vCores:3>, usedCapacity=0.5, absoluteUsedCapacity=0.5, numApps=1, numContainers=3
2019-06-10 04:29:09,550 INFO org.apache.hadoop.yarn.server.resourcemanager.scheduler.capacity.ParentQueue: assignedContainer queue=root usedCapacity=0.5 absoluteUsedCapacity=0.5 used=<memory:4096, vCores:3> cluster=<memory:8192, vCores:8>
2019-06-10 04:29:09,589 INFO org.apache.hadoop.yarn.server.resourcemanager.rmcontainer.RMContainerImpl: container_1560150672880_0003_01_000012 Container Transitioned from ACQUIRED to RELEASED
2019-06-10 04:29:09,593 INFO org.apache.hadoop.yarn.server.resourcemanager.RMAuditLogger: USER=hduser	IP=127.0.0.1	OPERATION=AM Released Container	TARGET=SchedulerApp	RESULT=SUCCESS	APPID=application_1560150672880_0003	CONTAINERID=container_1560150672880_0003_01_000012
2019-06-10 04:29:09,597 INFO org.apache.hadoop.yarn.server.resourcemanager.scheduler.SchedulerNode: Released container container_1560150672880_0003_01_000012 of capacity <memory:1024, vCores:1> on host ubuntu:40311, which currently has 2 containers, <memory:3072, vCores:2> used and <memory:5120, vCores:6> available, release resources=true
2019-06-10 04:29:09,626 INFO org.apache.hadoop.yarn.server.resourcemanager.rmcontainer.RMContainerImpl: container_1560150672880_0003_01_000013 Container Transitioned from ALLOCATED to ACQUIRED
2019-06-10 04:29:10,488 INFO org.apache.hadoop.yarn.server.resourcemanager.rmcontainer.RMContainerImpl: container_1560150672880_0003_01_000014 Container Transitioned from NEW to ALLOCATED
2019-06-10 04:29:10,489 INFO org.apache.hadoop.yarn.server.resourcemanager.RMAuditLogger: USER=hduser	OPERATION=AM Allocated Container	TARGET=SchedulerApp	RESULT=SUCCESS	APPID=application_1560150672880_0003	CONTAINERID=container_1560150672880_0003_01_000014
2019-06-10 04:29:10,490 INFO org.apache.hadoop.yarn.server.resourcemanager.scheduler.SchedulerNode: Assigned container container_1560150672880_0003_01_000014 of capacity <memory:1024, vCores:1> on host ubuntu:40311, which has 3 containers, <memory:4096, vCores:3> used and <memory:4096, vCores:5> available after allocation
2019-06-10 04:29:10,492 INFO org.apache.hadoop.yarn.server.resourcemanager.scheduler.capacity.allocator.AbstractContainerAllocator: assignedContainer application attempt=appattempt_1560150672880_0003_000001 container=container_1560150672880_0003_01_000014 queue=org.apache.hadoop.yarn.server.resourcemanager.scheduler.capacity.allocator.RegularContainerAllocator@2d9a25b0 clusterResource=<memory:8192, vCores:8> type=OFF_SWITCH requestedPartition=
2019-06-10 04:29:10,495 INFO org.apache.hadoop.yarn.server.resourcemanager.scheduler.capacity.ParentQueue: Re-sorting assigned queue: root.default stats: default: capacity=1.0, absoluteCapacity=1.0, usedResources=<memory:4096, vCores:3>, usedCapacity=0.5, absoluteUsedCapacity=0.5, numApps=1, numContainers=3
2019-06-10 04:29:10,496 INFO org.apache.hadoop.yarn.server.resourcemanager.scheduler.capacity.ParentQueue: assignedContainer queue=root usedCapacity=0.5 absoluteUsedCapacity=0.5 used=<memory:4096, vCores:3> cluster=<memory:8192, vCores:8>
2019-06-10 04:29:10,684 INFO org.apache.hadoop.yarn.server.resourcemanager.rmcontainer.RMContainerImpl: container_1560150672880_0003_01_000013 Container Transitioned from ACQUIRED to RELEASED
2019-06-10 04:29:10,684 INFO org.apache.hadoop.yarn.server.resourcemanager.RMAuditLogger: USER=hduser	IP=127.0.0.1	OPERATION=AM Released Container	TARGET=SchedulerApp	RESULT=SUCCESS	APPID=application_1560150672880_0003	CONTAINERID=container_1560150672880_0003_01_000013
2019-06-10 04:29:10,686 INFO org.apache.hadoop.yarn.server.resourcemanager.scheduler.SchedulerNode: Released container container_1560150672880_0003_01_000013 of capacity <memory:1024, vCores:1> on host ubuntu:40311, which currently has 2 containers, <memory:3072, vCores:2> used and <memory:5120, vCores:6> available, release resources=true
2019-06-10 04:29:10,700 INFO org.apache.hadoop.yarn.server.resourcemanager.rmcontainer.RMContainerImpl: container_1560150672880_0003_01_000014 Container Transitioned from ALLOCATED to ACQUIRED
2019-06-10 04:29:11,544 INFO org.apache.hadoop.yarn.server.resourcemanager.rmcontainer.RMContainerImpl: container_1560150672880_0003_01_000015 Container Transitioned from NEW to ALLOCATED
2019-06-10 04:29:11,545 INFO org.apache.hadoop.yarn.server.resourcemanager.RMAuditLogger: USER=hduser	OPERATION=AM Allocated Container	TARGET=SchedulerApp	RESULT=SUCCESS	APPID=application_1560150672880_0003	CONTAINERID=container_1560150672880_0003_01_000015
2019-06-10 04:29:11,546 INFO org.apache.hadoop.yarn.server.resourcemanager.scheduler.SchedulerNode: Assigned container container_1560150672880_0003_01_000015 of capacity <memory:1024, vCores:1> on host ubuntu:40311, which has 3 containers, <memory:4096, vCores:3> used and <memory:4096, vCores:5> available after allocation
2019-06-10 04:29:11,547 INFO org.apache.hadoop.yarn.server.resourcemanager.scheduler.capacity.allocator.AbstractContainerAllocator: assignedContainer application attempt=appattempt_1560150672880_0003_000001 container=container_1560150672880_0003_01_000015 queue=org.apache.hadoop.yarn.server.resourcemanager.scheduler.capacity.allocator.RegularContainerAllocator@2d9a25b0 clusterResource=<memory:8192, vCores:8> type=OFF_SWITCH requestedPartition=
2019-06-10 04:29:11,549 INFO org.apache.hadoop.yarn.server.resourcemanager.scheduler.capacity.ParentQueue: Re-sorting assigned queue: root.default stats: default: capacity=1.0, absoluteCapacity=1.0, usedResources=<memory:4096, vCores:3>, usedCapacity=0.5, absoluteUsedCapacity=0.5, numApps=1, numContainers=3
2019-06-10 04:29:11,551 INFO org.apache.hadoop.yarn.server.resourcemanager.scheduler.capacity.ParentQueue: assignedContainer queue=root usedCapacity=0.5 absoluteUsedCapacity=0.5 used=<memory:4096, vCores:3> cluster=<memory:8192, vCores:8>
2019-06-10 04:29:11,750 INFO org.apache.hadoop.yarn.server.resourcemanager.rmcontainer.RMContainerImpl: container_1560150672880_0003_01_000014 Container Transitioned from ACQUIRED to RELEASED
2019-06-10 04:29:11,753 INFO org.apache.hadoop.yarn.server.resourcemanager.RMAuditLogger: USER=hduser	IP=127.0.0.1	OPERATION=AM Released Container	TARGET=SchedulerApp	RESULT=SUCCESS	APPID=application_1560150672880_0003	CONTAINERID=container_1560150672880_0003_01_000014
2019-06-10 04:29:11,754 INFO org.apache.hadoop.yarn.server.resourcemanager.scheduler.SchedulerNode: Released container container_1560150672880_0003_01_000014 of capacity <memory:1024, vCores:1> on host ubuntu:40311, which currently has 2 containers, <memory:3072, vCores:2> used and <memory:5120, vCores:6> available, release resources=true
2019-06-10 04:29:11,767 INFO org.apache.hadoop.yarn.server.resourcemanager.rmcontainer.RMContainerImpl: container_1560150672880_0003_01_000015 Container Transitioned from ALLOCATED to ACQUIRED
2019-06-10 04:29:12,543 INFO org.apache.hadoop.yarn.server.resourcemanager.rmcontainer.RMContainerImpl: container_1560150672880_0003_01_000016 Container Transitioned from NEW to ALLOCATED
2019-06-10 04:29:12,547 INFO org.apache.hadoop.yarn.server.resourcemanager.RMAuditLogger: USER=hduser	OPERATION=AM Allocated Container	TARGET=SchedulerApp	RESULT=SUCCESS	APPID=application_1560150672880_0003	CONTAINERID=container_1560150672880_0003_01_000016
2019-06-10 04:29:12,548 INFO org.apache.hadoop.yarn.server.resourcemanager.scheduler.SchedulerNode: Assigned container container_1560150672880_0003_01_000016 of capacity <memory:1024, vCores:1> on host ubuntu:40311, which has 3 containers, <memory:4096, vCores:3> used and <memory:4096, vCores:5> available after allocation
2019-06-10 04:29:12,549 INFO org.apache.hadoop.yarn.server.resourcemanager.scheduler.capacity.allocator.AbstractContainerAllocator: assignedContainer application attempt=appattempt_1560150672880_0003_000001 container=container_1560150672880_0003_01_000016 queue=org.apache.hadoop.yarn.server.resourcemanager.scheduler.capacity.allocator.RegularContainerAllocator@2d9a25b0 clusterResource=<memory:8192, vCores:8> type=OFF_SWITCH requestedPartition=
2019-06-10 04:29:12,554 INFO org.apache.hadoop.yarn.server.resourcemanager.scheduler.capacity.ParentQueue: Re-sorting assigned queue: root.default stats: default: capacity=1.0, absoluteCapacity=1.0, usedResources=<memory:4096, vCores:3>, usedCapacity=0.5, absoluteUsedCapacity=0.5, numApps=1, numContainers=3
2019-06-10 04:29:12,555 INFO org.apache.hadoop.yarn.server.resourcemanager.scheduler.capacity.ParentQueue: assignedContainer queue=root usedCapacity=0.5 absoluteUsedCapacity=0.5 used=<memory:4096, vCores:3> cluster=<memory:8192, vCores:8>
2019-06-10 04:29:12,871 INFO org.apache.hadoop.yarn.server.resourcemanager.rmcontainer.RMContainerImpl: container_1560150672880_0003_01_000015 Container Transitioned from ACQUIRED to RELEASED
2019-06-10 04:29:12,874 INFO org.apache.hadoop.yarn.server.resourcemanager.RMAuditLogger: USER=hduser	IP=127.0.0.1	OPERATION=AM Released Container	TARGET=SchedulerApp	RESULT=SUCCESS	APPID=application_1560150672880_0003	CONTAINERID=container_1560150672880_0003_01_000015
2019-06-10 04:29:12,875 INFO org.apache.hadoop.yarn.server.resourcemanager.scheduler.SchedulerNode: Released container container_1560150672880_0003_01_000015 of capacity <memory:1024, vCores:1> on host ubuntu:40311, which currently has 2 containers, <memory:3072, vCores:2> used and <memory:5120, vCores:6> available, release resources=true
2019-06-10 04:29:12,884 INFO org.apache.hadoop.yarn.server.resourcemanager.scheduler.AppSchedulingInfo: checking for deactivate of application :application_1560150672880_0003
2019-06-10 04:29:12,931 INFO org.apache.hadoop.yarn.server.resourcemanager.rmcontainer.RMContainerImpl: container_1560150672880_0003_01_000016 Container Transitioned from ALLOCATED to ACQUIRED
2019-06-10 04:29:13,324 INFO org.apache.hadoop.yarn.server.resourcemanager.rmapp.attempt.RMAppAttemptImpl: Updating application attempt appattempt_1560150672880_0003_000001 with final state: FINISHING, and exit status: -1000
2019-06-10 04:29:13,326 INFO org.apache.hadoop.yarn.server.resourcemanager.rmapp.attempt.RMAppAttemptImpl: appattempt_1560150672880_0003_000001 State change from RUNNING to FINAL_SAVING
2019-06-10 04:29:13,329 INFO org.apache.hadoop.yarn.server.resourcemanager.rmapp.RMAppImpl: Updating application application_1560150672880_0003 with final state: FINISHING
2019-06-10 04:29:13,329 INFO org.apache.hadoop.yarn.server.resourcemanager.rmapp.RMAppImpl: application_1560150672880_0003 State change from RUNNING to FINAL_SAVING on event=ATTEMPT_UNREGISTERED
2019-06-10 04:29:13,330 INFO org.apache.hadoop.yarn.server.resourcemanager.rmapp.attempt.RMAppAttemptImpl: appattempt_1560150672880_0003_000001 State change from FINAL_SAVING to FINISHING
2019-06-10 04:29:13,329 INFO org.apache.hadoop.yarn.server.resourcemanager.recovery.RMStateStore: Updating info for app: application_1560150672880_0003
2019-06-10 04:29:13,335 INFO org.apache.hadoop.yarn.server.resourcemanager.rmapp.RMAppImpl: application_1560150672880_0003 State change from FINAL_SAVING to FINISHING on event=APP_UPDATE_SAVED
2019-06-10 04:29:14,329 INFO org.apache.hadoop.yarn.server.resourcemanager.ApplicationMasterService: application_1560150672880_0003 unregistered successfully. 
2019-06-10 04:29:20,076 INFO org.apache.hadoop.yarn.server.resourcemanager.rmcontainer.RMContainerImpl: container_1560150672880_0003_01_000001 Container Transitioned from RUNNING to COMPLETED
2019-06-10 04:29:20,077 INFO org.apache.hadoop.yarn.server.resourcemanager.ApplicationMasterService: Unregistering app attempt : appattempt_1560150672880_0003_000001
2019-06-10 04:29:20,078 INFO org.apache.hadoop.yarn.server.resourcemanager.security.AMRMTokenSecretManager: Application finished, removing password for appattempt_1560150672880_0003_000001
2019-06-10 04:29:20,078 INFO org.apache.hadoop.yarn.server.resourcemanager.RMAuditLogger: USER=hduser	OPERATION=AM Released Container	TARGET=SchedulerApp	RESULT=SUCCESS	APPID=application_1560150672880_0003	CONTAINERID=container_1560150672880_0003_01_000001
2019-06-10 04:29:20,079 INFO org.apache.hadoop.yarn.server.resourcemanager.rmapp.attempt.RMAppAttemptImpl: appattempt_1560150672880_0003_000001 State change from FINISHING to FINISHED
2019-06-10 04:29:20,080 INFO org.apache.hadoop.yarn.server.resourcemanager.scheduler.SchedulerNode: Released container container_1560150672880_0003_01_000001 of capacity <memory:2048, vCores:1> on host ubuntu:40311, which currently has 1 containers, <memory:1024, vCores:1> used and <memory:7168, vCores:7> available, release resources=true
2019-06-10 04:29:20,080 INFO org.apache.hadoop.yarn.server.resourcemanager.rmapp.RMAppImpl: application_1560150672880_0003 State change from FINISHING to FINISHED on event=ATTEMPT_FINISHED
2019-06-10 04:29:20,081 INFO org.apache.hadoop.yarn.server.resourcemanager.scheduler.capacity.CapacityScheduler: Application Attempt appattempt_1560150672880_0003_000001 is done. finalState=FINISHED
2019-06-10 04:29:20,081 INFO org.apache.hadoop.yarn.server.resourcemanager.rmcontainer.RMContainerImpl: container_1560150672880_0003_01_000016 Container Transitioned from ACQUIRED to KILLED
2019-06-10 04:29:20,082 INFO org.apache.hadoop.yarn.server.resourcemanager.RMAuditLogger: USER=hduser	OPERATION=AM Released Container	TARGET=SchedulerApp	RESULT=SUCCESS	APPID=application_1560150672880_0003	CONTAINERID=container_1560150672880_0003_01_000016
2019-06-10 04:29:20,082 INFO org.apache.hadoop.yarn.server.resourcemanager.RMAuditLogger: USER=hduser	OPERATION=Application Finished - Succeeded	TARGET=RMAppManager	RESULT=SUCCESS	APPID=application_1560150672880_0003
2019-06-10 04:29:20,082 INFO org.apache.hadoop.yarn.server.resourcemanager.scheduler.SchedulerNode: Released container container_1560150672880_0003_01_000016 of capacity <memory:1024, vCores:1> on host ubuntu:40311, which currently has 0 containers, <memory:0, vCores:0> used and <memory:8192, vCores:8> available, release resources=true
2019-06-10 04:29:20,083 INFO org.apache.hadoop.yarn.server.resourcemanager.amlauncher.AMLauncher: Cleaning master appattempt_1560150672880_0003_000001
2019-06-10 04:29:20,095 INFO org.apache.hadoop.yarn.server.resourcemanager.RMAppManager$ApplicationSummary: appId=application_1560150672880_0003,name=categories.jar,user=hduser,queue=default,state=FINISHED,trackingUrl=http://ubuntu:8088/proxy/application_1560150672880_0003/,appMasterHost=ubuntu,startTime=1560166108741,finishTime=1560166153326,finalStatus=FAILED,memorySeconds=152135,vcoreSeconds=91,preemptedMemorySeconds=0,preemptedVcoreSeconds=0,preemptedAMContainers=0,preemptedNonAMContainers=0,preemptedResources=<memory:0\, vCores:0>,applicationType=MAPREDUCE
2019-06-10 04:29:20,097 INFO org.apache.hadoop.yarn.server.resourcemanager.scheduler.AppSchedulingInfo: Application application_1560150672880_0003 requests cleared
2019-06-10 04:29:20,097 INFO org.apache.hadoop.yarn.server.resourcemanager.scheduler.capacity.LeafQueue: Application removed - appId: application_1560150672880_0003 user: hduser queue: default #user-pending-applications: 0 #user-active-applications: 0 #queue-pending-applications: 0 #queue-active-applications: 0
2019-06-10 04:29:20,098 INFO org.apache.hadoop.yarn.server.resourcemanager.scheduler.capacity.ParentQueue: Application removed - appId: application_1560150672880_0003 user: hduser leaf-queue of parent: root #applications: 0
2019-06-10 04:32:10,312 INFO org.apache.hadoop.yarn.server.resourcemanager.ClientRMService: Allocated new applicationId: 4
2019-06-10 04:32:15,623 INFO org.apache.hadoop.yarn.server.resourcemanager.scheduler.capacity.CapacityScheduler: Application 'application_1560150672880_0004' is submitted without priority hence considering default queue/cluster priority: 0
2019-06-10 04:32:15,623 INFO org.apache.hadoop.yarn.server.resourcemanager.scheduler.capacity.CapacityScheduler: Priority '0' is acceptable in queue : default for application: application_1560150672880_0004 for the user: hduser
2019-06-10 04:32:15,626 INFO org.apache.hadoop.yarn.server.resourcemanager.ClientRMService: Application with id 4 submitted by user hduser
2019-06-10 04:32:15,626 INFO org.apache.hadoop.yarn.server.resourcemanager.rmapp.RMAppImpl: Storing application with id application_1560150672880_0004
2019-06-10 04:32:15,626 INFO org.apache.hadoop.yarn.server.resourcemanager.RMAuditLogger: USER=hduser	IP=127.0.0.1	OPERATION=Submit Application Request	TARGET=ClientRMService	RESULT=SUCCESS	APPID=application_1560150672880_0004	CALLERCONTEXT=CLI
2019-06-10 04:32:15,626 INFO org.apache.hadoop.yarn.server.resourcemanager.rmapp.RMAppImpl: application_1560150672880_0004 State change from NEW to NEW_SAVING on event=START
2019-06-10 04:32:15,627 INFO org.apache.hadoop.yarn.server.resourcemanager.recovery.RMStateStore: Storing info for app: application_1560150672880_0004
2019-06-10 04:32:15,628 INFO org.apache.hadoop.yarn.server.resourcemanager.rmapp.RMAppImpl: application_1560150672880_0004 State change from NEW_SAVING to SUBMITTED on event=APP_NEW_SAVED
2019-06-10 04:32:15,628 INFO org.apache.hadoop.yarn.server.resourcemanager.scheduler.capacity.ParentQueue: Application added - appId: application_1560150672880_0004 user: hduser leaf-queue of parent: root #applications: 1
2019-06-10 04:32:15,629 INFO org.apache.hadoop.yarn.server.resourcemanager.scheduler.capacity.CapacityScheduler: Accepted application application_1560150672880_0004 from user: hduser, in queue: default
2019-06-10 04:32:15,631 INFO org.apache.hadoop.yarn.server.resourcemanager.rmapp.RMAppImpl: application_1560150672880_0004 State change from SUBMITTED to ACCEPTED on event=APP_ACCEPTED
2019-06-10 04:32:15,631 INFO org.apache.hadoop.yarn.server.resourcemanager.ApplicationMasterService: Registering app attempt : appattempt_1560150672880_0004_000001
2019-06-10 04:32:15,631 INFO org.apache.hadoop.yarn.server.resourcemanager.rmapp.attempt.RMAppAttemptImpl: appattempt_1560150672880_0004_000001 State change from NEW to SUBMITTED
2019-06-10 04:32:15,632 WARN org.apache.hadoop.yarn.server.resourcemanager.scheduler.capacity.LeafQueue: maximum-am-resource-percent is insufficient to start a single application in queue, it is likely set too low. skipping enforcement to allow at least one application to start
2019-06-10 04:32:15,632 WARN org.apache.hadoop.yarn.server.resourcemanager.scheduler.capacity.LeafQueue: maximum-am-resource-percent is insufficient to start a single application in queue for user, it is likely set too low. skipping enforcement to allow at least one application to start
2019-06-10 04:32:15,634 INFO org.apache.hadoop.yarn.server.resourcemanager.scheduler.capacity.LeafQueue: Application application_1560150672880_0004 from user: hduser activated in queue: default
2019-06-10 04:32:15,634 INFO org.apache.hadoop.yarn.server.resourcemanager.scheduler.capacity.LeafQueue: Application added - appId: application_1560150672880_0004 user: hduser, leaf-queue: default #user-pending-applications: 0 #user-active-applications: 1 #queue-pending-applications: 0 #queue-active-applications: 1
2019-06-10 04:32:15,635 INFO org.apache.hadoop.yarn.server.resourcemanager.scheduler.capacity.CapacityScheduler: Added Application Attempt appattempt_1560150672880_0004_000001 to scheduler from user hduser in queue default
2019-06-10 04:32:15,637 INFO org.apache.hadoop.yarn.server.resourcemanager.rmapp.attempt.RMAppAttemptImpl: appattempt_1560150672880_0004_000001 State change from SUBMITTED to SCHEDULED
2019-06-10 04:32:16,586 INFO org.apache.hadoop.yarn.server.resourcemanager.rmcontainer.RMContainerImpl: container_1560150672880_0004_01_000001 Container Transitioned from NEW to ALLOCATED
2019-06-10 04:32:16,586 INFO org.apache.hadoop.yarn.server.resourcemanager.RMAuditLogger: USER=hduser	OPERATION=AM Allocated Container	TARGET=SchedulerApp	RESULT=SUCCESS	APPID=application_1560150672880_0004	CONTAINERID=container_1560150672880_0004_01_000001
2019-06-10 04:32:16,587 INFO org.apache.hadoop.yarn.server.resourcemanager.scheduler.SchedulerNode: Assigned container container_1560150672880_0004_01_000001 of capacity <memory:2048, vCores:1> on host ubuntu:40311, which has 1 containers, <memory:2048, vCores:1> used and <memory:6144, vCores:7> available after allocation
2019-06-10 04:32:16,588 INFO org.apache.hadoop.yarn.server.resourcemanager.scheduler.capacity.allocator.AbstractContainerAllocator: assignedContainer application attempt=appattempt_1560150672880_0004_000001 container=container_1560150672880_0004_01_000001 queue=org.apache.hadoop.yarn.server.resourcemanager.scheduler.capacity.allocator.RegularContainerAllocator@770a28a8 clusterResource=<memory:8192, vCores:8> type=OFF_SWITCH requestedPartition=
2019-06-10 04:32:16,593 INFO org.apache.hadoop.yarn.server.resourcemanager.security.NMTokenSecretManagerInRM: Sending NMToken for nodeId : ubuntu:40311 for container : container_1560150672880_0004_01_000001
2019-06-10 04:32:16,597 INFO org.apache.hadoop.yarn.server.resourcemanager.rmcontainer.RMContainerImpl: container_1560150672880_0004_01_000001 Container Transitioned from ALLOCATED to ACQUIRED
2019-06-10 04:32:16,597 INFO org.apache.hadoop.yarn.server.resourcemanager.security.NMTokenSecretManagerInRM: Clear node set for appattempt_1560150672880_0004_000001
2019-06-10 04:32:16,598 INFO org.apache.hadoop.yarn.server.resourcemanager.scheduler.capacity.ParentQueue: Re-sorting assigned queue: root.default stats: default: capacity=1.0, absoluteCapacity=1.0, usedResources=<memory:2048, vCores:1>, usedCapacity=0.25, absoluteUsedCapacity=0.25, numApps=1, numContainers=1
2019-06-10 04:32:16,598 INFO org.apache.hadoop.yarn.server.resourcemanager.rmapp.attempt.RMAppAttemptImpl: Storing attempt: AppId: application_1560150672880_0004 AttemptId: appattempt_1560150672880_0004_000001 MasterContainer: Container: [ContainerId: container_1560150672880_0004_01_000001, Version: 0, NodeId: ubuntu:40311, NodeHttpAddress: ubuntu:8042, Resource: <memory:2048, vCores:1>, Priority: 0, Token: Token { kind: ContainerToken, service: 127.0.1.1:40311 }, ]
2019-06-10 04:32:16,599 INFO org.apache.hadoop.yarn.server.resourcemanager.scheduler.capacity.ParentQueue: assignedContainer queue=root usedCapacity=0.25 absoluteUsedCapacity=0.25 used=<memory:2048, vCores:1> cluster=<memory:8192, vCores:8>
2019-06-10 04:32:16,599 INFO org.apache.hadoop.yarn.server.resourcemanager.rmapp.attempt.RMAppAttemptImpl: appattempt_1560150672880_0004_000001 State change from SCHEDULED to ALLOCATED_SAVING
2019-06-10 04:32:16,600 INFO org.apache.hadoop.yarn.server.resourcemanager.rmapp.attempt.RMAppAttemptImpl: appattempt_1560150672880_0004_000001 State change from ALLOCATED_SAVING to ALLOCATED
2019-06-10 04:32:16,601 INFO org.apache.hadoop.yarn.server.resourcemanager.amlauncher.AMLauncher: Launching masterappattempt_1560150672880_0004_000001
2019-06-10 04:32:16,610 INFO org.apache.hadoop.yarn.server.resourcemanager.amlauncher.AMLauncher: Setting up container Container: [ContainerId: container_1560150672880_0004_01_000001, Version: 0, NodeId: ubuntu:40311, NodeHttpAddress: ubuntu:8042, Resource: <memory:2048, vCores:1>, Priority: 0, Token: Token { kind: ContainerToken, service: 127.0.1.1:40311 }, ] for AM appattempt_1560150672880_0004_000001
2019-06-10 04:32:16,614 INFO org.apache.hadoop.yarn.server.resourcemanager.security.AMRMTokenSecretManager: Create AMRMToken for ApplicationAttempt: appattempt_1560150672880_0004_000001
2019-06-10 04:32:16,614 INFO org.apache.hadoop.yarn.server.resourcemanager.security.AMRMTokenSecretManager: Creating password for appattempt_1560150672880_0004_000001
2019-06-10 04:32:16,664 INFO org.apache.hadoop.yarn.server.resourcemanager.amlauncher.AMLauncher: Done launching container Container: [ContainerId: container_1560150672880_0004_01_000001, Version: 0, NodeId: ubuntu:40311, NodeHttpAddress: ubuntu:8042, Resource: <memory:2048, vCores:1>, Priority: 0, Token: Token { kind: ContainerToken, service: 127.0.1.1:40311 }, ] for AM appattempt_1560150672880_0004_000001
2019-06-10 04:32:16,665 INFO org.apache.hadoop.yarn.server.resourcemanager.rmapp.attempt.RMAppAttemptImpl: appattempt_1560150672880_0004_000001 State change from ALLOCATED to LAUNCHED
2019-06-10 04:32:17,587 INFO org.apache.hadoop.yarn.server.resourcemanager.rmcontainer.RMContainerImpl: container_1560150672880_0004_01_000001 Container Transitioned from ACQUIRED to RUNNING
2019-06-10 04:32:25,395 INFO SecurityLogger.org.apache.hadoop.ipc.Server: Auth successful for appattempt_1560150672880_0004_000001 (auth:SIMPLE)
2019-06-10 04:32:25,429 INFO org.apache.hadoop.yarn.server.resourcemanager.ApplicationMasterService: AM registration appattempt_1560150672880_0004_000001
2019-06-10 04:32:25,430 INFO org.apache.hadoop.yarn.server.resourcemanager.rmapp.attempt.RMAppAttemptImpl: appattempt_1560150672880_0004_000001 State change from LAUNCHED to RUNNING
2019-06-10 04:32:25,430 INFO org.apache.hadoop.yarn.server.resourcemanager.RMAuditLogger: USER=hduser	IP=127.0.0.1	OPERATION=Register App Master	TARGET=ApplicationMasterService	RESULT=SUCCESS	APPID=application_1560150672880_0004	APPATTEMPTID=appattempt_1560150672880_0004_000001
2019-06-10 04:32:25,431 INFO org.apache.hadoop.yarn.server.resourcemanager.rmapp.RMAppImpl: application_1560150672880_0004 State change from ACCEPTED to RUNNING on event=ATTEMPT_REGISTERED
2019-06-10 04:32:26,613 INFO org.apache.hadoop.yarn.server.resourcemanager.rmcontainer.RMContainerImpl: container_1560150672880_0004_01_000002 Container Transitioned from NEW to ALLOCATED
2019-06-10 04:32:26,613 INFO org.apache.hadoop.yarn.server.resourcemanager.RMAuditLogger: USER=hduser	OPERATION=AM Allocated Container	TARGET=SchedulerApp	RESULT=SUCCESS	APPID=application_1560150672880_0004	CONTAINERID=container_1560150672880_0004_01_000002
2019-06-10 04:32:26,614 INFO org.apache.hadoop.yarn.server.resourcemanager.scheduler.SchedulerNode: Assigned container container_1560150672880_0004_01_000002 of capacity <memory:1024, vCores:1> on host ubuntu:40311, which has 2 containers, <memory:3072, vCores:2> used and <memory:5120, vCores:6> available after allocation
2019-06-10 04:32:26,615 INFO org.apache.hadoop.yarn.server.resourcemanager.scheduler.capacity.allocator.AbstractContainerAllocator: assignedContainer application attempt=appattempt_1560150672880_0004_000001 container=container_1560150672880_0004_01_000002 queue=org.apache.hadoop.yarn.server.resourcemanager.scheduler.capacity.allocator.RegularContainerAllocator@770a28a8 clusterResource=<memory:8192, vCores:8> type=OFF_SWITCH requestedPartition=
2019-06-10 04:32:26,616 INFO org.apache.hadoop.yarn.server.resourcemanager.scheduler.capacity.ParentQueue: Re-sorting assigned queue: root.default stats: default: capacity=1.0, absoluteCapacity=1.0, usedResources=<memory:3072, vCores:2>, usedCapacity=0.375, absoluteUsedCapacity=0.375, numApps=1, numContainers=2
2019-06-10 04:32:26,616 INFO org.apache.hadoop.yarn.server.resourcemanager.scheduler.capacity.ParentQueue: assignedContainer queue=root usedCapacity=0.375 absoluteUsedCapacity=0.375 used=<memory:3072, vCores:2> cluster=<memory:8192, vCores:8>
2019-06-10 04:32:27,541 INFO org.apache.hadoop.yarn.server.resourcemanager.security.NMTokenSecretManagerInRM: Sending NMToken for nodeId : ubuntu:40311 for container : container_1560150672880_0004_01_000002
2019-06-10 04:32:27,545 INFO org.apache.hadoop.yarn.server.resourcemanager.rmcontainer.RMContainerImpl: container_1560150672880_0004_01_000002 Container Transitioned from ALLOCATED to ACQUIRED
2019-06-10 04:32:27,615 INFO org.apache.hadoop.yarn.server.resourcemanager.rmcontainer.RMContainerImpl: container_1560150672880_0004_01_000003 Container Transitioned from NEW to ALLOCATED
2019-06-10 04:32:27,616 INFO org.apache.hadoop.yarn.server.resourcemanager.RMAuditLogger: USER=hduser	OPERATION=AM Allocated Container	TARGET=SchedulerApp	RESULT=SUCCESS	APPID=application_1560150672880_0004	CONTAINERID=container_1560150672880_0004_01_000003
2019-06-10 04:32:27,616 INFO org.apache.hadoop.yarn.server.resourcemanager.scheduler.SchedulerNode: Assigned container container_1560150672880_0004_01_000003 of capacity <memory:1024, vCores:1> on host ubuntu:40311, which has 3 containers, <memory:4096, vCores:3> used and <memory:4096, vCores:5> available after allocation
2019-06-10 04:32:27,617 INFO org.apache.hadoop.yarn.server.resourcemanager.scheduler.capacity.allocator.AbstractContainerAllocator: assignedContainer application attempt=appattempt_1560150672880_0004_000001 container=container_1560150672880_0004_01_000003 queue=org.apache.hadoop.yarn.server.resourcemanager.scheduler.capacity.allocator.RegularContainerAllocator@770a28a8 clusterResource=<memory:8192, vCores:8> type=OFF_SWITCH requestedPartition=
2019-06-10 04:32:27,619 INFO org.apache.hadoop.yarn.server.resourcemanager.scheduler.capacity.ParentQueue: Re-sorting assigned queue: root.default stats: default: capacity=1.0, absoluteCapacity=1.0, usedResources=<memory:4096, vCores:3>, usedCapacity=0.5, absoluteUsedCapacity=0.5, numApps=1, numContainers=3
2019-06-10 04:32:27,619 INFO org.apache.hadoop.yarn.server.resourcemanager.scheduler.capacity.ParentQueue: assignedContainer queue=root usedCapacity=0.5 absoluteUsedCapacity=0.5 used=<memory:4096, vCores:3> cluster=<memory:8192, vCores:8>
2019-06-10 04:32:28,610 INFO org.apache.hadoop.yarn.server.resourcemanager.rmcontainer.RMContainerImpl: container_1560150672880_0004_01_000003 Container Transitioned from ALLOCATED to ACQUIRED
2019-06-10 04:32:28,638 INFO org.apache.hadoop.yarn.server.resourcemanager.rmcontainer.RMContainerImpl: container_1560150672880_0004_01_000004 Container Transitioned from NEW to ALLOCATED
2019-06-10 04:32:28,639 INFO org.apache.hadoop.yarn.server.resourcemanager.RMAuditLogger: USER=hduser	OPERATION=AM Allocated Container	TARGET=SchedulerApp	RESULT=SUCCESS	APPID=application_1560150672880_0004	CONTAINERID=container_1560150672880_0004_01_000004
2019-06-10 04:32:28,641 INFO org.apache.hadoop.yarn.server.resourcemanager.scheduler.SchedulerNode: Assigned container container_1560150672880_0004_01_000004 of capacity <memory:1024, vCores:1> on host ubuntu:40311, which has 4 containers, <memory:5120, vCores:4> used and <memory:3072, vCores:4> available after allocation
2019-06-10 04:32:28,645 INFO org.apache.hadoop.yarn.server.resourcemanager.scheduler.capacity.allocator.AbstractContainerAllocator: assignedContainer application attempt=appattempt_1560150672880_0004_000001 container=container_1560150672880_0004_01_000004 queue=org.apache.hadoop.yarn.server.resourcemanager.scheduler.capacity.allocator.RegularContainerAllocator@770a28a8 clusterResource=<memory:8192, vCores:8> type=OFF_SWITCH requestedPartition=
2019-06-10 04:32:28,647 INFO org.apache.hadoop.yarn.server.resourcemanager.scheduler.capacity.ParentQueue: Re-sorting assigned queue: root.default stats: default: capacity=1.0, absoluteCapacity=1.0, usedResources=<memory:5120, vCores:4>, usedCapacity=0.625, absoluteUsedCapacity=0.625, numApps=1, numContainers=4
2019-06-10 04:32:28,650 INFO org.apache.hadoop.yarn.server.resourcemanager.scheduler.capacity.ParentQueue: assignedContainer queue=root usedCapacity=0.625 absoluteUsedCapacity=0.625 used=<memory:5120, vCores:4> cluster=<memory:8192, vCores:8>
2019-06-10 04:32:29,626 INFO org.apache.hadoop.yarn.server.resourcemanager.rmcontainer.RMContainerImpl: container_1560150672880_0004_01_000005 Container Transitioned from NEW to ALLOCATED
2019-06-10 04:32:29,628 INFO org.apache.hadoop.yarn.server.resourcemanager.RMAuditLogger: USER=hduser	OPERATION=AM Allocated Container	TARGET=SchedulerApp	RESULT=SUCCESS	APPID=application_1560150672880_0004	CONTAINERID=container_1560150672880_0004_01_000005
2019-06-10 04:32:29,629 INFO org.apache.hadoop.yarn.server.resourcemanager.scheduler.SchedulerNode: Assigned container container_1560150672880_0004_01_000005 of capacity <memory:1024, vCores:1> on host ubuntu:40311, which has 5 containers, <memory:6144, vCores:5> used and <memory:2048, vCores:3> available after allocation
2019-06-10 04:32:29,632 INFO org.apache.hadoop.yarn.server.resourcemanager.scheduler.capacity.allocator.AbstractContainerAllocator: assignedContainer application attempt=appattempt_1560150672880_0004_000001 container=container_1560150672880_0004_01_000005 queue=org.apache.hadoop.yarn.server.resourcemanager.scheduler.capacity.allocator.RegularContainerAllocator@770a28a8 clusterResource=<memory:8192, vCores:8> type=OFF_SWITCH requestedPartition=
2019-06-10 04:32:29,635 INFO org.apache.hadoop.yarn.server.resourcemanager.scheduler.capacity.ParentQueue: Re-sorting assigned queue: root.default stats: default: capacity=1.0, absoluteCapacity=1.0, usedResources=<memory:6144, vCores:5>, usedCapacity=0.75, absoluteUsedCapacity=0.75, numApps=1, numContainers=5
2019-06-10 04:32:29,636 INFO org.apache.hadoop.yarn.server.resourcemanager.scheduler.capacity.ParentQueue: assignedContainer queue=root usedCapacity=0.75 absoluteUsedCapacity=0.75 used=<memory:6144, vCores:5> cluster=<memory:8192, vCores:8>
2019-06-10 04:32:29,649 INFO org.apache.hadoop.yarn.server.resourcemanager.rmcontainer.RMContainerImpl: container_1560150672880_0004_01_000002 Container Transitioned from ACQUIRED to RELEASED
2019-06-10 04:32:29,650 INFO org.apache.hadoop.yarn.server.resourcemanager.RMAuditLogger: USER=hduser	IP=127.0.0.1	OPERATION=AM Released Container	TARGET=SchedulerApp	RESULT=SUCCESS	APPID=application_1560150672880_0004	CONTAINERID=container_1560150672880_0004_01_000002
2019-06-10 04:32:29,650 INFO org.apache.hadoop.yarn.server.resourcemanager.scheduler.SchedulerNode: Released container container_1560150672880_0004_01_000002 of capacity <memory:1024, vCores:1> on host ubuntu:40311, which currently has 4 containers, <memory:5120, vCores:4> used and <memory:3072, vCores:4> available, release resources=true
2019-06-10 04:32:29,656 INFO org.apache.hadoop.yarn.server.resourcemanager.rmcontainer.RMContainerImpl: container_1560150672880_0004_01_000003 Container Transitioned from ACQUIRED to RELEASED
2019-06-10 04:32:29,667 INFO org.apache.hadoop.yarn.server.resourcemanager.RMAuditLogger: USER=hduser	IP=127.0.0.1	OPERATION=AM Released Container	TARGET=SchedulerApp	RESULT=SUCCESS	APPID=application_1560150672880_0004	CONTAINERID=container_1560150672880_0004_01_000003
2019-06-10 04:32:29,668 INFO org.apache.hadoop.yarn.server.resourcemanager.scheduler.SchedulerNode: Released container container_1560150672880_0004_01_000003 of capacity <memory:1024, vCores:1> on host ubuntu:40311, which currently has 3 containers, <memory:4096, vCores:3> used and <memory:4096, vCores:5> available, release resources=true
2019-06-10 04:32:29,687 INFO org.apache.hadoop.yarn.server.resourcemanager.rmcontainer.RMContainerImpl: container_1560150672880_0004_01_000004 Container Transitioned from ALLOCATED to ACQUIRED
2019-06-10 04:32:29,697 INFO org.apache.hadoop.yarn.server.resourcemanager.rmcontainer.RMContainerImpl: container_1560150672880_0004_01_000005 Container Transitioned from ALLOCATED to ACQUIRED
2019-06-10 04:32:30,632 INFO org.apache.hadoop.yarn.server.resourcemanager.rmcontainer.RMContainerImpl: container_1560150672880_0004_01_000006 Container Transitioned from NEW to ALLOCATED
2019-06-10 04:32:30,632 INFO org.apache.hadoop.yarn.server.resourcemanager.RMAuditLogger: USER=hduser	OPERATION=AM Allocated Container	TARGET=SchedulerApp	RESULT=SUCCESS	APPID=application_1560150672880_0004	CONTAINERID=container_1560150672880_0004_01_000006
2019-06-10 04:32:30,632 INFO org.apache.hadoop.yarn.server.resourcemanager.scheduler.SchedulerNode: Assigned container container_1560150672880_0004_01_000006 of capacity <memory:1024, vCores:1> on host ubuntu:40311, which has 4 containers, <memory:5120, vCores:4> used and <memory:3072, vCores:4> available after allocation
2019-06-10 04:32:30,634 INFO org.apache.hadoop.yarn.server.resourcemanager.scheduler.capacity.allocator.AbstractContainerAllocator: assignedContainer application attempt=appattempt_1560150672880_0004_000001 container=container_1560150672880_0004_01_000006 queue=org.apache.hadoop.yarn.server.resourcemanager.scheduler.capacity.allocator.RegularContainerAllocator@770a28a8 clusterResource=<memory:8192, vCores:8> type=OFF_SWITCH requestedPartition=
2019-06-10 04:32:30,636 INFO org.apache.hadoop.yarn.server.resourcemanager.scheduler.capacity.ParentQueue: Re-sorting assigned queue: root.default stats: default: capacity=1.0, absoluteCapacity=1.0, usedResources=<memory:5120, vCores:4>, usedCapacity=0.625, absoluteUsedCapacity=0.625, numApps=1, numContainers=4
2019-06-10 04:32:30,637 INFO org.apache.hadoop.yarn.server.resourcemanager.scheduler.capacity.ParentQueue: assignedContainer queue=root usedCapacity=0.625 absoluteUsedCapacity=0.625 used=<memory:5120, vCores:4> cluster=<memory:8192, vCores:8>
2019-06-10 04:32:30,736 INFO org.apache.hadoop.yarn.server.resourcemanager.rmcontainer.RMContainerImpl: container_1560150672880_0004_01_000004 Container Transitioned from ACQUIRED to RELEASED
2019-06-10 04:32:30,748 INFO org.apache.hadoop.yarn.server.resourcemanager.RMAuditLogger: USER=hduser	IP=127.0.0.1	OPERATION=AM Released Container	TARGET=SchedulerApp	RESULT=SUCCESS	APPID=application_1560150672880_0004	CONTAINERID=container_1560150672880_0004_01_000004
2019-06-10 04:32:30,749 INFO org.apache.hadoop.yarn.server.resourcemanager.scheduler.SchedulerNode: Released container container_1560150672880_0004_01_000004 of capacity <memory:1024, vCores:1> on host ubuntu:40311, which currently has 3 containers, <memory:4096, vCores:3> used and <memory:4096, vCores:5> available, release resources=true
2019-06-10 04:32:30,753 INFO org.apache.hadoop.yarn.server.resourcemanager.rmcontainer.RMContainerImpl: container_1560150672880_0004_01_000005 Container Transitioned from ACQUIRED to RELEASED
2019-06-10 04:32:30,754 INFO org.apache.hadoop.yarn.server.resourcemanager.RMAuditLogger: USER=hduser	IP=127.0.0.1	OPERATION=AM Released Container	TARGET=SchedulerApp	RESULT=SUCCESS	APPID=application_1560150672880_0004	CONTAINERID=container_1560150672880_0004_01_000005
2019-06-10 04:32:30,755 INFO org.apache.hadoop.yarn.server.resourcemanager.scheduler.SchedulerNode: Released container container_1560150672880_0004_01_000005 of capacity <memory:1024, vCores:1> on host ubuntu:40311, which currently has 2 containers, <memory:3072, vCores:2> used and <memory:5120, vCores:6> available, release resources=true
2019-06-10 04:32:30,757 INFO org.apache.hadoop.yarn.server.resourcemanager.scheduler.AppSchedulingInfo: checking for deactivate of application :application_1560150672880_0004
2019-06-10 04:32:30,765 INFO org.apache.hadoop.yarn.server.resourcemanager.rmcontainer.RMContainerImpl: container_1560150672880_0004_01_000006 Container Transitioned from ALLOCATED to ACQUIRED
2019-06-10 04:32:30,766 INFO org.apache.hadoop.yarn.server.resourcemanager.ApplicationMasterService: blacklist are updated in Scheduler.blacklistAdditions: [ubuntu], blacklistRemovals: []
2019-06-10 04:32:31,783 INFO org.apache.hadoop.yarn.server.resourcemanager.rmcontainer.RMContainerImpl: container_1560150672880_0004_01_000006 Container Transitioned from ACQUIRED to RELEASED
2019-06-10 04:32:31,785 INFO org.apache.hadoop.yarn.server.resourcemanager.RMAuditLogger: USER=hduser	IP=127.0.0.1	OPERATION=AM Released Container	TARGET=SchedulerApp	RESULT=SUCCESS	APPID=application_1560150672880_0004	CONTAINERID=container_1560150672880_0004_01_000006
2019-06-10 04:32:31,786 INFO org.apache.hadoop.yarn.server.resourcemanager.scheduler.SchedulerNode: Released container container_1560150672880_0004_01_000006 of capacity <memory:1024, vCores:1> on host ubuntu:40311, which currently has 1 containers, <memory:2048, vCores:1> used and <memory:6144, vCores:7> available, release resources=true
2019-06-10 04:32:31,788 INFO org.apache.hadoop.yarn.server.resourcemanager.ApplicationMasterService: blacklist are updated in Scheduler.blacklistAdditions: [], blacklistRemovals: [ubuntu]
2019-06-10 04:32:32,642 INFO org.apache.hadoop.yarn.server.resourcemanager.rmcontainer.RMContainerImpl: container_1560150672880_0004_01_000007 Container Transitioned from NEW to ALLOCATED
2019-06-10 04:32:32,644 INFO org.apache.hadoop.yarn.server.resourcemanager.RMAuditLogger: USER=hduser	OPERATION=AM Allocated Container	TARGET=SchedulerApp	RESULT=SUCCESS	APPID=application_1560150672880_0004	CONTAINERID=container_1560150672880_0004_01_000007
2019-06-10 04:32:32,644 INFO org.apache.hadoop.yarn.server.resourcemanager.scheduler.SchedulerNode: Assigned container container_1560150672880_0004_01_000007 of capacity <memory:1024, vCores:1> on host ubuntu:40311, which has 2 containers, <memory:3072, vCores:2> used and <memory:5120, vCores:6> available after allocation
2019-06-10 04:32:32,645 INFO org.apache.hadoop.yarn.server.resourcemanager.scheduler.capacity.allocator.AbstractContainerAllocator: assignedContainer application attempt=appattempt_1560150672880_0004_000001 container=container_1560150672880_0004_01_000007 queue=org.apache.hadoop.yarn.server.resourcemanager.scheduler.capacity.allocator.RegularContainerAllocator@770a28a8 clusterResource=<memory:8192, vCores:8> type=OFF_SWITCH requestedPartition=
2019-06-10 04:32:32,647 INFO org.apache.hadoop.yarn.server.resourcemanager.scheduler.capacity.ParentQueue: Re-sorting assigned queue: root.default stats: default: capacity=1.0, absoluteCapacity=1.0, usedResources=<memory:3072, vCores:2>, usedCapacity=0.375, absoluteUsedCapacity=0.375, numApps=1, numContainers=2
2019-06-10 04:32:32,647 INFO org.apache.hadoop.yarn.server.resourcemanager.scheduler.capacity.ParentQueue: assignedContainer queue=root usedCapacity=0.375 absoluteUsedCapacity=0.375 used=<memory:3072, vCores:2> cluster=<memory:8192, vCores:8>
2019-06-10 04:32:32,800 INFO org.apache.hadoop.yarn.server.resourcemanager.rmcontainer.RMContainerImpl: container_1560150672880_0004_01_000007 Container Transitioned from ALLOCATED to ACQUIRED
2019-06-10 04:32:33,645 INFO org.apache.hadoop.yarn.server.resourcemanager.rmcontainer.RMContainerImpl: container_1560150672880_0004_01_000008 Container Transitioned from NEW to ALLOCATED
2019-06-10 04:32:33,646 INFO org.apache.hadoop.yarn.server.resourcemanager.RMAuditLogger: USER=hduser	OPERATION=AM Allocated Container	TARGET=SchedulerApp	RESULT=SUCCESS	APPID=application_1560150672880_0004	CONTAINERID=container_1560150672880_0004_01_000008
2019-06-10 04:32:33,647 INFO org.apache.hadoop.yarn.server.resourcemanager.scheduler.SchedulerNode: Assigned container container_1560150672880_0004_01_000008 of capacity <memory:1024, vCores:1> on host ubuntu:40311, which has 3 containers, <memory:4096, vCores:3> used and <memory:4096, vCores:5> available after allocation
2019-06-10 04:32:33,649 INFO org.apache.hadoop.yarn.server.resourcemanager.scheduler.capacity.allocator.AbstractContainerAllocator: assignedContainer application attempt=appattempt_1560150672880_0004_000001 container=container_1560150672880_0004_01_000008 queue=org.apache.hadoop.yarn.server.resourcemanager.scheduler.capacity.allocator.RegularContainerAllocator@770a28a8 clusterResource=<memory:8192, vCores:8> type=OFF_SWITCH requestedPartition=
2019-06-10 04:32:33,650 INFO org.apache.hadoop.yarn.server.resourcemanager.scheduler.capacity.ParentQueue: Re-sorting assigned queue: root.default stats: default: capacity=1.0, absoluteCapacity=1.0, usedResources=<memory:4096, vCores:3>, usedCapacity=0.5, absoluteUsedCapacity=0.5, numApps=1, numContainers=3
2019-06-10 04:32:33,652 INFO org.apache.hadoop.yarn.server.resourcemanager.scheduler.capacity.ParentQueue: assignedContainer queue=root usedCapacity=0.5 absoluteUsedCapacity=0.5 used=<memory:4096, vCores:3> cluster=<memory:8192, vCores:8>
2019-06-10 04:32:33,811 INFO org.apache.hadoop.yarn.server.resourcemanager.rmcontainer.RMContainerImpl: container_1560150672880_0004_01_000007 Container Transitioned from ACQUIRED to RELEASED
2019-06-10 04:32:33,811 INFO org.apache.hadoop.yarn.server.resourcemanager.RMAuditLogger: USER=hduser	IP=127.0.0.1	OPERATION=AM Released Container	TARGET=SchedulerApp	RESULT=SUCCESS	APPID=application_1560150672880_0004	CONTAINERID=container_1560150672880_0004_01_000007
2019-06-10 04:32:33,814 INFO org.apache.hadoop.yarn.server.resourcemanager.scheduler.SchedulerNode: Released container container_1560150672880_0004_01_000007 of capacity <memory:1024, vCores:1> on host ubuntu:40311, which currently has 2 containers, <memory:3072, vCores:2> used and <memory:5120, vCores:6> available, release resources=true
2019-06-10 04:32:33,828 INFO org.apache.hadoop.yarn.server.resourcemanager.rmcontainer.RMContainerImpl: container_1560150672880_0004_01_000008 Container Transitioned from ALLOCATED to ACQUIRED
2019-06-10 04:32:34,652 INFO org.apache.hadoop.yarn.server.resourcemanager.rmcontainer.RMContainerImpl: container_1560150672880_0004_01_000009 Container Transitioned from NEW to ALLOCATED
2019-06-10 04:32:34,652 INFO org.apache.hadoop.yarn.server.resourcemanager.RMAuditLogger: USER=hduser	OPERATION=AM Allocated Container	TARGET=SchedulerApp	RESULT=SUCCESS	APPID=application_1560150672880_0004	CONTAINERID=container_1560150672880_0004_01_000009
2019-06-10 04:32:34,653 INFO org.apache.hadoop.yarn.server.resourcemanager.scheduler.SchedulerNode: Assigned container container_1560150672880_0004_01_000009 of capacity <memory:1024, vCores:1> on host ubuntu:40311, which has 3 containers, <memory:4096, vCores:3> used and <memory:4096, vCores:5> available after allocation
2019-06-10 04:32:34,654 INFO org.apache.hadoop.yarn.server.resourcemanager.scheduler.capacity.allocator.AbstractContainerAllocator: assignedContainer application attempt=appattempt_1560150672880_0004_000001 container=container_1560150672880_0004_01_000009 queue=org.apache.hadoop.yarn.server.resourcemanager.scheduler.capacity.allocator.RegularContainerAllocator@770a28a8 clusterResource=<memory:8192, vCores:8> type=OFF_SWITCH requestedPartition=
2019-06-10 04:32:34,655 INFO org.apache.hadoop.yarn.server.resourcemanager.scheduler.capacity.ParentQueue: Re-sorting assigned queue: root.default stats: default: capacity=1.0, absoluteCapacity=1.0, usedResources=<memory:4096, vCores:3>, usedCapacity=0.5, absoluteUsedCapacity=0.5, numApps=1, numContainers=3
2019-06-10 04:32:34,656 INFO org.apache.hadoop.yarn.server.resourcemanager.scheduler.capacity.ParentQueue: assignedContainer queue=root usedCapacity=0.5 absoluteUsedCapacity=0.5 used=<memory:4096, vCores:3> cluster=<memory:8192, vCores:8>
2019-06-10 04:32:34,844 INFO org.apache.hadoop.yarn.server.resourcemanager.rmcontainer.RMContainerImpl: container_1560150672880_0004_01_000008 Container Transitioned from ACQUIRED to RELEASED
2019-06-10 04:32:34,844 INFO org.apache.hadoop.yarn.server.resourcemanager.RMAuditLogger: USER=hduser	IP=127.0.0.1	OPERATION=AM Released Container	TARGET=SchedulerApp	RESULT=SUCCESS	APPID=application_1560150672880_0004	CONTAINERID=container_1560150672880_0004_01_000008
2019-06-10 04:32:34,845 INFO org.apache.hadoop.yarn.server.resourcemanager.scheduler.SchedulerNode: Released container container_1560150672880_0004_01_000008 of capacity <memory:1024, vCores:1> on host ubuntu:40311, which currently has 2 containers, <memory:3072, vCores:2> used and <memory:5120, vCores:6> available, release resources=true
2019-06-10 04:32:34,851 INFO org.apache.hadoop.yarn.server.resourcemanager.rmcontainer.RMContainerImpl: container_1560150672880_0004_01_000009 Container Transitioned from ALLOCATED to ACQUIRED
2019-06-10 04:32:35,673 INFO org.apache.hadoop.yarn.server.resourcemanager.rmcontainer.RMContainerImpl: container_1560150672880_0004_01_000010 Container Transitioned from NEW to ALLOCATED
2019-06-10 04:32:35,674 INFO org.apache.hadoop.yarn.server.resourcemanager.RMAuditLogger: USER=hduser	OPERATION=AM Allocated Container	TARGET=SchedulerApp	RESULT=SUCCESS	APPID=application_1560150672880_0004	CONTAINERID=container_1560150672880_0004_01_000010
2019-06-10 04:32:35,674 INFO org.apache.hadoop.yarn.server.resourcemanager.scheduler.SchedulerNode: Assigned container container_1560150672880_0004_01_000010 of capacity <memory:1024, vCores:1> on host ubuntu:40311, which has 3 containers, <memory:4096, vCores:3> used and <memory:4096, vCores:5> available after allocation
2019-06-10 04:32:35,676 INFO org.apache.hadoop.yarn.server.resourcemanager.scheduler.capacity.allocator.AbstractContainerAllocator: assignedContainer application attempt=appattempt_1560150672880_0004_000001 container=container_1560150672880_0004_01_000010 queue=org.apache.hadoop.yarn.server.resourcemanager.scheduler.capacity.allocator.RegularContainerAllocator@770a28a8 clusterResource=<memory:8192, vCores:8> type=OFF_SWITCH requestedPartition=
2019-06-10 04:32:35,680 INFO org.apache.hadoop.yarn.server.resourcemanager.scheduler.capacity.ParentQueue: Re-sorting assigned queue: root.default stats: default: capacity=1.0, absoluteCapacity=1.0, usedResources=<memory:4096, vCores:3>, usedCapacity=0.5, absoluteUsedCapacity=0.5, numApps=1, numContainers=3
2019-06-10 04:32:35,682 INFO org.apache.hadoop.yarn.server.resourcemanager.scheduler.capacity.ParentQueue: assignedContainer queue=root usedCapacity=0.5 absoluteUsedCapacity=0.5 used=<memory:4096, vCores:3> cluster=<memory:8192, vCores:8>
2019-06-10 04:32:35,858 INFO org.apache.hadoop.yarn.server.resourcemanager.rmcontainer.RMContainerImpl: container_1560150672880_0004_01_000009 Container Transitioned from ACQUIRED to RELEASED
2019-06-10 04:32:35,860 INFO org.apache.hadoop.yarn.server.resourcemanager.RMAuditLogger: USER=hduser	IP=127.0.0.1	OPERATION=AM Released Container	TARGET=SchedulerApp	RESULT=SUCCESS	APPID=application_1560150672880_0004	CONTAINERID=container_1560150672880_0004_01_000009
2019-06-10 04:32:35,860 INFO org.apache.hadoop.yarn.server.resourcemanager.scheduler.SchedulerNode: Released container container_1560150672880_0004_01_000009 of capacity <memory:1024, vCores:1> on host ubuntu:40311, which currently has 2 containers, <memory:3072, vCores:2> used and <memory:5120, vCores:6> available, release resources=true
2019-06-10 04:32:35,867 INFO org.apache.hadoop.yarn.server.resourcemanager.rmcontainer.RMContainerImpl: container_1560150672880_0004_01_000010 Container Transitioned from ALLOCATED to ACQUIRED
2019-06-10 04:32:36,704 INFO org.apache.hadoop.yarn.server.resourcemanager.rmcontainer.RMContainerImpl: container_1560150672880_0004_01_000011 Container Transitioned from NEW to ALLOCATED
2019-06-10 04:32:36,704 INFO org.apache.hadoop.yarn.server.resourcemanager.RMAuditLogger: USER=hduser	OPERATION=AM Allocated Container	TARGET=SchedulerApp	RESULT=SUCCESS	APPID=application_1560150672880_0004	CONTAINERID=container_1560150672880_0004_01_000011
2019-06-10 04:32:36,707 INFO org.apache.hadoop.yarn.server.resourcemanager.scheduler.SchedulerNode: Assigned container container_1560150672880_0004_01_000011 of capacity <memory:1024, vCores:1> on host ubuntu:40311, which has 3 containers, <memory:4096, vCores:3> used and <memory:4096, vCores:5> available after allocation
2019-06-10 04:32:36,709 INFO org.apache.hadoop.yarn.server.resourcemanager.scheduler.capacity.allocator.AbstractContainerAllocator: assignedContainer application attempt=appattempt_1560150672880_0004_000001 container=container_1560150672880_0004_01_000011 queue=org.apache.hadoop.yarn.server.resourcemanager.scheduler.capacity.allocator.RegularContainerAllocator@770a28a8 clusterResource=<memory:8192, vCores:8> type=OFF_SWITCH requestedPartition=
2019-06-10 04:32:36,710 INFO org.apache.hadoop.yarn.server.resourcemanager.scheduler.capacity.ParentQueue: Re-sorting assigned queue: root.default stats: default: capacity=1.0, absoluteCapacity=1.0, usedResources=<memory:4096, vCores:3>, usedCapacity=0.5, absoluteUsedCapacity=0.5, numApps=1, numContainers=3
2019-06-10 04:32:36,711 INFO org.apache.hadoop.yarn.server.resourcemanager.scheduler.capacity.ParentQueue: assignedContainer queue=root usedCapacity=0.5 absoluteUsedCapacity=0.5 used=<memory:4096, vCores:3> cluster=<memory:8192, vCores:8>
2019-06-10 04:32:36,874 INFO org.apache.hadoop.yarn.server.resourcemanager.rmcontainer.RMContainerImpl: container_1560150672880_0004_01_000010 Container Transitioned from ACQUIRED to RELEASED
2019-06-10 04:32:36,875 INFO org.apache.hadoop.yarn.server.resourcemanager.RMAuditLogger: USER=hduser	IP=127.0.0.1	OPERATION=AM Released Container	TARGET=SchedulerApp	RESULT=SUCCESS	APPID=application_1560150672880_0004	CONTAINERID=container_1560150672880_0004_01_000010
2019-06-10 04:32:36,876 INFO org.apache.hadoop.yarn.server.resourcemanager.scheduler.SchedulerNode: Released container container_1560150672880_0004_01_000010 of capacity <memory:1024, vCores:1> on host ubuntu:40311, which currently has 2 containers, <memory:3072, vCores:2> used and <memory:5120, vCores:6> available, release resources=true
2019-06-10 04:32:36,884 INFO org.apache.hadoop.yarn.server.resourcemanager.rmcontainer.RMContainerImpl: container_1560150672880_0004_01_000011 Container Transitioned from ALLOCATED to ACQUIRED
2019-06-10 04:32:37,704 INFO org.apache.hadoop.yarn.server.resourcemanager.rmcontainer.RMContainerImpl: container_1560150672880_0004_01_000012 Container Transitioned from NEW to ALLOCATED
2019-06-10 04:32:37,705 INFO org.apache.hadoop.yarn.server.resourcemanager.RMAuditLogger: USER=hduser	OPERATION=AM Allocated Container	TARGET=SchedulerApp	RESULT=SUCCESS	APPID=application_1560150672880_0004	CONTAINERID=container_1560150672880_0004_01_000012
2019-06-10 04:32:37,705 INFO org.apache.hadoop.yarn.server.resourcemanager.scheduler.SchedulerNode: Assigned container container_1560150672880_0004_01_000012 of capacity <memory:1024, vCores:1> on host ubuntu:40311, which has 3 containers, <memory:4096, vCores:3> used and <memory:4096, vCores:5> available after allocation
2019-06-10 04:32:37,706 INFO org.apache.hadoop.yarn.server.resourcemanager.scheduler.capacity.allocator.AbstractContainerAllocator: assignedContainer application attempt=appattempt_1560150672880_0004_000001 container=container_1560150672880_0004_01_000012 queue=org.apache.hadoop.yarn.server.resourcemanager.scheduler.capacity.allocator.RegularContainerAllocator@770a28a8 clusterResource=<memory:8192, vCores:8> type=OFF_SWITCH requestedPartition=
2019-06-10 04:32:37,707 INFO org.apache.hadoop.yarn.server.resourcemanager.scheduler.capacity.ParentQueue: Re-sorting assigned queue: root.default stats: default: capacity=1.0, absoluteCapacity=1.0, usedResources=<memory:4096, vCores:3>, usedCapacity=0.5, absoluteUsedCapacity=0.5, numApps=1, numContainers=3
2019-06-10 04:32:37,708 INFO org.apache.hadoop.yarn.server.resourcemanager.scheduler.capacity.ParentQueue: assignedContainer queue=root usedCapacity=0.5 absoluteUsedCapacity=0.5 used=<memory:4096, vCores:3> cluster=<memory:8192, vCores:8>
2019-06-10 04:32:37,897 INFO org.apache.hadoop.yarn.server.resourcemanager.rmcontainer.RMContainerImpl: container_1560150672880_0004_01_000011 Container Transitioned from ACQUIRED to RELEASED
2019-06-10 04:32:37,898 INFO org.apache.hadoop.yarn.server.resourcemanager.RMAuditLogger: USER=hduser	IP=127.0.0.1	OPERATION=AM Released Container	TARGET=SchedulerApp	RESULT=SUCCESS	APPID=application_1560150672880_0004	CONTAINERID=container_1560150672880_0004_01_000011
2019-06-10 04:32:37,908 INFO org.apache.hadoop.yarn.server.resourcemanager.scheduler.SchedulerNode: Released container container_1560150672880_0004_01_000011 of capacity <memory:1024, vCores:1> on host ubuntu:40311, which currently has 2 containers, <memory:3072, vCores:2> used and <memory:5120, vCores:6> available, release resources=true
2019-06-10 04:32:37,951 INFO org.apache.hadoop.yarn.server.resourcemanager.rmcontainer.RMContainerImpl: container_1560150672880_0004_01_000012 Container Transitioned from ALLOCATED to ACQUIRED
2019-06-10 04:32:38,730 INFO org.apache.hadoop.yarn.server.resourcemanager.rmcontainer.RMContainerImpl: container_1560150672880_0004_01_000013 Container Transitioned from NEW to ALLOCATED
2019-06-10 04:32:38,730 INFO org.apache.hadoop.yarn.server.resourcemanager.RMAuditLogger: USER=hduser	OPERATION=AM Allocated Container	TARGET=SchedulerApp	RESULT=SUCCESS	APPID=application_1560150672880_0004	CONTAINERID=container_1560150672880_0004_01_000013
2019-06-10 04:32:38,732 INFO org.apache.hadoop.yarn.server.resourcemanager.scheduler.SchedulerNode: Assigned container container_1560150672880_0004_01_000013 of capacity <memory:1024, vCores:1> on host ubuntu:40311, which has 3 containers, <memory:4096, vCores:3> used and <memory:4096, vCores:5> available after allocation
2019-06-10 04:32:38,735 INFO org.apache.hadoop.yarn.server.resourcemanager.scheduler.capacity.allocator.AbstractContainerAllocator: assignedContainer application attempt=appattempt_1560150672880_0004_000001 container=container_1560150672880_0004_01_000013 queue=org.apache.hadoop.yarn.server.resourcemanager.scheduler.capacity.allocator.RegularContainerAllocator@770a28a8 clusterResource=<memory:8192, vCores:8> type=OFF_SWITCH requestedPartition=
2019-06-10 04:32:38,750 INFO org.apache.hadoop.yarn.server.resourcemanager.scheduler.capacity.ParentQueue: Re-sorting assigned queue: root.default stats: default: capacity=1.0, absoluteCapacity=1.0, usedResources=<memory:4096, vCores:3>, usedCapacity=0.5, absoluteUsedCapacity=0.5, numApps=1, numContainers=3
2019-06-10 04:32:38,755 INFO org.apache.hadoop.yarn.server.resourcemanager.scheduler.capacity.ParentQueue: assignedContainer queue=root usedCapacity=0.5 absoluteUsedCapacity=0.5 used=<memory:4096, vCores:3> cluster=<memory:8192, vCores:8>
2019-06-10 04:32:40,499 INFO org.apache.hadoop.yarn.server.resourcemanager.rmcontainer.RMContainerImpl: container_1560150672880_0004_01_000014 Container Transitioned from NEW to ALLOCATED
2019-06-10 04:32:40,504 INFO org.apache.hadoop.yarn.server.resourcemanager.RMAuditLogger: USER=hduser	OPERATION=AM Allocated Container	TARGET=SchedulerApp	RESULT=SUCCESS	APPID=application_1560150672880_0004	CONTAINERID=container_1560150672880_0004_01_000014
2019-06-10 04:32:40,508 INFO org.apache.hadoop.yarn.server.resourcemanager.scheduler.SchedulerNode: Assigned container container_1560150672880_0004_01_000014 of capacity <memory:1024, vCores:1> on host ubuntu:40311, which has 4 containers, <memory:5120, vCores:4> used and <memory:3072, vCores:4> available after allocation
2019-06-10 04:32:40,511 INFO org.apache.hadoop.yarn.server.resourcemanager.scheduler.capacity.allocator.AbstractContainerAllocator: assignedContainer application attempt=appattempt_1560150672880_0004_000001 container=container_1560150672880_0004_01_000014 queue=org.apache.hadoop.yarn.server.resourcemanager.scheduler.capacity.allocator.RegularContainerAllocator@770a28a8 clusterResource=<memory:8192, vCores:8> type=OFF_SWITCH requestedPartition=
2019-06-10 04:32:40,514 INFO org.apache.hadoop.yarn.server.resourcemanager.scheduler.capacity.ParentQueue: Re-sorting assigned queue: root.default stats: default: capacity=1.0, absoluteCapacity=1.0, usedResources=<memory:5120, vCores:4>, usedCapacity=0.625, absoluteUsedCapacity=0.625, numApps=1, numContainers=4
2019-06-10 04:32:40,515 INFO org.apache.hadoop.yarn.server.resourcemanager.scheduler.capacity.ParentQueue: assignedContainer queue=root usedCapacity=0.625 absoluteUsedCapacity=0.625 used=<memory:5120, vCores:4> cluster=<memory:8192, vCores:8>
2019-06-10 04:32:40,515 INFO org.apache.hadoop.yarn.server.resourcemanager.rmcontainer.RMContainerImpl: container_1560150672880_0004_01_000012 Container Transitioned from ACQUIRED to RELEASED
2019-06-10 04:32:40,533 INFO org.apache.hadoop.yarn.server.resourcemanager.RMAuditLogger: USER=hduser	IP=127.0.0.1	OPERATION=AM Released Container	TARGET=SchedulerApp	RESULT=SUCCESS	APPID=application_1560150672880_0004	CONTAINERID=container_1560150672880_0004_01_000012
2019-06-10 04:32:40,534 INFO org.apache.hadoop.yarn.server.resourcemanager.scheduler.SchedulerNode: Released container container_1560150672880_0004_01_000012 of capacity <memory:1024, vCores:1> on host ubuntu:40311, which currently has 3 containers, <memory:4096, vCores:3> used and <memory:4096, vCores:5> available, release resources=true
2019-06-10 04:32:40,562 INFO org.apache.hadoop.yarn.server.resourcemanager.rmcontainer.RMContainerImpl: container_1560150672880_0004_01_000013 Container Transitioned from ALLOCATED to ACQUIRED
2019-06-10 04:32:40,584 INFO org.apache.hadoop.yarn.server.resourcemanager.rmcontainer.RMContainerImpl: container_1560150672880_0004_01_000014 Container Transitioned from ALLOCATED to ACQUIRED
2019-06-10 04:32:41,481 INFO org.apache.hadoop.yarn.server.resourcemanager.rmcontainer.RMContainerImpl: container_1560150672880_0004_01_000015 Container Transitioned from NEW to ALLOCATED
2019-06-10 04:32:41,482 INFO org.apache.hadoop.yarn.server.resourcemanager.RMAuditLogger: USER=hduser	OPERATION=AM Allocated Container	TARGET=SchedulerApp	RESULT=SUCCESS	APPID=application_1560150672880_0004	CONTAINERID=container_1560150672880_0004_01_000015
2019-06-10 04:32:41,484 INFO org.apache.hadoop.yarn.server.resourcemanager.scheduler.SchedulerNode: Assigned container container_1560150672880_0004_01_000015 of capacity <memory:1024, vCores:1> on host ubuntu:40311, which has 4 containers, <memory:5120, vCores:4> used and <memory:3072, vCores:4> available after allocation
2019-06-10 04:32:41,486 INFO org.apache.hadoop.yarn.server.resourcemanager.scheduler.capacity.allocator.AbstractContainerAllocator: assignedContainer application attempt=appattempt_1560150672880_0004_000001 container=container_1560150672880_0004_01_000015 queue=org.apache.hadoop.yarn.server.resourcemanager.scheduler.capacity.allocator.RegularContainerAllocator@770a28a8 clusterResource=<memory:8192, vCores:8> type=OFF_SWITCH requestedPartition=
2019-06-10 04:32:41,489 INFO org.apache.hadoop.yarn.server.resourcemanager.scheduler.capacity.ParentQueue: Re-sorting assigned queue: root.default stats: default: capacity=1.0, absoluteCapacity=1.0, usedResources=<memory:5120, vCores:4>, usedCapacity=0.625, absoluteUsedCapacity=0.625, numApps=1, numContainers=4
2019-06-10 04:32:41,491 INFO org.apache.hadoop.yarn.server.resourcemanager.scheduler.capacity.ParentQueue: assignedContainer queue=root usedCapacity=0.625 absoluteUsedCapacity=0.625 used=<memory:5120, vCores:4> cluster=<memory:8192, vCores:8>
2019-06-10 04:32:41,649 INFO org.apache.hadoop.yarn.server.resourcemanager.rmcontainer.RMContainerImpl: container_1560150672880_0004_01_000013 Container Transitioned from ACQUIRED to RELEASED
2019-06-10 04:32:41,649 INFO org.apache.hadoop.yarn.server.resourcemanager.RMAuditLogger: USER=hduser	IP=127.0.0.1	OPERATION=AM Released Container	TARGET=SchedulerApp	RESULT=SUCCESS	APPID=application_1560150672880_0004	CONTAINERID=container_1560150672880_0004_01_000013
2019-06-10 04:32:41,658 INFO org.apache.hadoop.yarn.server.resourcemanager.scheduler.SchedulerNode: Released container container_1560150672880_0004_01_000013 of capacity <memory:1024, vCores:1> on host ubuntu:40311, which currently has 3 containers, <memory:4096, vCores:3> used and <memory:4096, vCores:5> available, release resources=true
2019-06-10 04:32:41,662 INFO org.apache.hadoop.yarn.server.resourcemanager.rmcontainer.RMContainerImpl: container_1560150672880_0004_01_000014 Container Transitioned from ACQUIRED to RELEASED
2019-06-10 04:32:41,668 INFO org.apache.hadoop.yarn.server.resourcemanager.RMAuditLogger: USER=hduser	IP=127.0.0.1	OPERATION=AM Released Container	TARGET=SchedulerApp	RESULT=SUCCESS	APPID=application_1560150672880_0004	CONTAINERID=container_1560150672880_0004_01_000014
2019-06-10 04:32:41,674 INFO org.apache.hadoop.yarn.server.resourcemanager.scheduler.SchedulerNode: Released container container_1560150672880_0004_01_000014 of capacity <memory:1024, vCores:1> on host ubuntu:40311, which currently has 2 containers, <memory:3072, vCores:2> used and <memory:5120, vCores:6> available, release resources=true
2019-06-10 04:32:41,683 INFO org.apache.hadoop.yarn.server.resourcemanager.scheduler.AppSchedulingInfo: checking for deactivate of application :application_1560150672880_0004
2019-06-10 04:32:41,712 INFO org.apache.hadoop.yarn.server.resourcemanager.rmcontainer.RMContainerImpl: container_1560150672880_0004_01_000015 Container Transitioned from ALLOCATED to ACQUIRED
2019-06-10 04:32:41,744 INFO org.apache.hadoop.yarn.server.resourcemanager.rmapp.attempt.RMAppAttemptImpl: Updating application attempt appattempt_1560150672880_0004_000001 with final state: FINISHING, and exit status: -1000
2019-06-10 04:32:41,744 INFO org.apache.hadoop.yarn.server.resourcemanager.rmapp.attempt.RMAppAttemptImpl: appattempt_1560150672880_0004_000001 State change from RUNNING to FINAL_SAVING
2019-06-10 04:32:41,745 INFO org.apache.hadoop.yarn.server.resourcemanager.rmapp.RMAppImpl: Updating application application_1560150672880_0004 with final state: FINISHING
2019-06-10 04:32:41,748 INFO org.apache.hadoop.yarn.server.resourcemanager.rmapp.RMAppImpl: application_1560150672880_0004 State change from RUNNING to FINAL_SAVING on event=ATTEMPT_UNREGISTERED
2019-06-10 04:32:41,749 INFO org.apache.hadoop.yarn.server.resourcemanager.recovery.RMStateStore: Updating info for app: application_1560150672880_0004
2019-06-10 04:32:41,749 INFO org.apache.hadoop.yarn.server.resourcemanager.rmapp.attempt.RMAppAttemptImpl: appattempt_1560150672880_0004_000001 State change from FINAL_SAVING to FINISHING
2019-06-10 04:32:41,750 INFO org.apache.hadoop.yarn.server.resourcemanager.rmapp.RMAppImpl: application_1560150672880_0004 State change from FINAL_SAVING to FINISHING on event=APP_UPDATE_SAVED
2019-06-10 04:32:42,758 INFO org.apache.hadoop.yarn.server.resourcemanager.ApplicationMasterService: application_1560150672880_0004 unregistered successfully. 
2019-06-10 04:32:48,377 INFO org.apache.hadoop.yarn.server.resourcemanager.rmcontainer.RMContainerImpl: container_1560150672880_0004_01_000001 Container Transitioned from RUNNING to COMPLETED
2019-06-10 04:32:48,378 INFO org.apache.hadoop.yarn.server.resourcemanager.ApplicationMasterService: Unregistering app attempt : appattempt_1560150672880_0004_000001
2019-06-10 04:32:48,378 INFO org.apache.hadoop.yarn.server.resourcemanager.RMAuditLogger: USER=hduser	OPERATION=AM Released Container	TARGET=SchedulerApp	RESULT=SUCCESS	APPID=application_1560150672880_0004	CONTAINERID=container_1560150672880_0004_01_000001
2019-06-10 04:32:48,378 INFO org.apache.hadoop.yarn.server.resourcemanager.security.AMRMTokenSecretManager: Application finished, removing password for appattempt_1560150672880_0004_000001
2019-06-10 04:32:48,379 INFO org.apache.hadoop.yarn.server.resourcemanager.rmapp.attempt.RMAppAttemptImpl: appattempt_1560150672880_0004_000001 State change from FINISHING to FINISHED
2019-06-10 04:32:48,379 INFO org.apache.hadoop.yarn.server.resourcemanager.rmapp.RMAppImpl: application_1560150672880_0004 State change from FINISHING to FINISHED on event=ATTEMPT_FINISHED
2019-06-10 04:32:48,379 INFO org.apache.hadoop.yarn.server.resourcemanager.scheduler.SchedulerNode: Released container container_1560150672880_0004_01_000001 of capacity <memory:2048, vCores:1> on host ubuntu:40311, which currently has 1 containers, <memory:1024, vCores:1> used and <memory:7168, vCores:7> available, release resources=true
2019-06-10 04:32:48,380 INFO org.apache.hadoop.yarn.server.resourcemanager.scheduler.capacity.CapacityScheduler: Application Attempt appattempt_1560150672880_0004_000001 is done. finalState=FINISHED
2019-06-10 04:32:48,381 INFO org.apache.hadoop.yarn.server.resourcemanager.rmcontainer.RMContainerImpl: container_1560150672880_0004_01_000015 Container Transitioned from ACQUIRED to KILLED
2019-06-10 04:32:48,381 INFO org.apache.hadoop.yarn.server.resourcemanager.RMAuditLogger: USER=hduser	OPERATION=Application Finished - Succeeded	TARGET=RMAppManager	RESULT=SUCCESS	APPID=application_1560150672880_0004
2019-06-10 04:32:48,382 INFO org.apache.hadoop.yarn.server.resourcemanager.RMAuditLogger: USER=hduser	OPERATION=AM Released Container	TARGET=SchedulerApp	RESULT=SUCCESS	APPID=application_1560150672880_0004	CONTAINERID=container_1560150672880_0004_01_000015
2019-06-10 04:32:48,381 INFO org.apache.hadoop.yarn.server.resourcemanager.amlauncher.AMLauncher: Cleaning master appattempt_1560150672880_0004_000001
2019-06-10 04:32:48,382 INFO org.apache.hadoop.yarn.server.resourcemanager.scheduler.SchedulerNode: Released container container_1560150672880_0004_01_000015 of capacity <memory:1024, vCores:1> on host ubuntu:40311, which currently has 0 containers, <memory:0, vCores:0> used and <memory:8192, vCores:8> available, release resources=true
2019-06-10 04:32:48,387 INFO org.apache.hadoop.yarn.server.resourcemanager.scheduler.AppSchedulingInfo: Application application_1560150672880_0004 requests cleared
2019-06-10 04:32:48,387 INFO org.apache.hadoop.yarn.server.resourcemanager.RMAppManager$ApplicationSummary: appId=application_1560150672880_0004,name=categories.jar,user=hduser,queue=default,state=FINISHED,trackingUrl=http://ubuntu:8088/proxy/application_1560150672880_0004/,appMasterHost=ubuntu,startTime=1560166335624,finishTime=1560166361745,finalStatus=FAILED,memorySeconds=95037,vcoreSeconds=56,preemptedMemorySeconds=0,preemptedVcoreSeconds=0,preemptedAMContainers=0,preemptedNonAMContainers=0,preemptedResources=<memory:0\, vCores:0>,applicationType=MAPREDUCE
2019-06-10 04:32:48,388 INFO org.apache.hadoop.yarn.server.resourcemanager.scheduler.capacity.LeafQueue: Application removed - appId: application_1560150672880_0004 user: hduser queue: default #user-pending-applications: 0 #user-active-applications: 0 #queue-pending-applications: 0 #queue-active-applications: 0
2019-06-10 04:32:48,389 INFO org.apache.hadoop.yarn.server.resourcemanager.scheduler.capacity.ParentQueue: Application removed - appId: application_1560150672880_0004 user: hduser leaf-queue of parent: root #applications: 0
2019-06-10 04:40:24,746 ERROR org.apache.hadoop.yarn.server.resourcemanager.ResourceManager: RECEIVED SIGNAL 15: SIGTERM
2019-06-10 04:40:25,818 ERROR org.apache.hadoop.security.token.delegation.AbstractDelegationTokenSecretManager: ExpiredTokenRemover received java.lang.InterruptedException: sleep interrupted
2019-06-10 04:40:25,932 INFO org.mortbay.log: Stopped HttpServer2$SelectChannelConnectorWithSafeStartup@0.0.0.0:8088
2019-06-10 04:40:25,949 INFO org.apache.hadoop.yarn.server.resourcemanager.ResourceTrackerService: Node with node id : ubuntu:40311 has shutdown, hence unregistering the node.
2019-06-10 04:40:26,075 INFO org.apache.hadoop.yarn.server.resourcemanager.rmnode.RMNodeImpl: Deactivating Node ubuntu:40311 as it is now SHUTDOWN
2019-06-10 04:40:26,075 INFO org.apache.hadoop.yarn.server.resourcemanager.rmnode.RMNodeImpl: ubuntu:40311 Node Transitioned from RUNNING to SHUTDOWN
2019-06-10 04:40:26,085 INFO org.apache.hadoop.yarn.server.resourcemanager.scheduler.capacity.CapacityScheduler: Removed node ubuntu:40311 clusterResource: <memory:0, vCores:0>
2019-06-10 04:40:26,142 INFO org.apache.hadoop.ipc.Server: Stopping server on 8032
2019-06-10 04:40:26,143 INFO org.apache.hadoop.ipc.Server: Stopping IPC Server listener on 8032
2019-06-10 04:40:26,156 INFO org.apache.hadoop.ipc.Server: Stopping IPC Server Responder
2019-06-10 04:40:26,176 INFO org.apache.hadoop.ipc.Server: Stopping server on 8033
2019-06-10 04:40:26,192 INFO org.apache.hadoop.ipc.Server: Stopping IPC Server Responder
2019-06-10 04:40:26,192 INFO org.apache.hadoop.ipc.Server: Stopping IPC Server listener on 8033
2019-06-10 04:40:26,210 INFO org.apache.hadoop.yarn.server.resourcemanager.ResourceManager: Transitioning to standby state
2019-06-10 04:40:26,214 WARN org.apache.hadoop.yarn.server.resourcemanager.amlauncher.ApplicationMasterLauncher: org.apache.hadoop.yarn.server.resourcemanager.amlauncher.ApplicationMasterLauncher$LauncherThread interrupted. Returning.
2019-06-10 04:40:26,218 INFO org.apache.hadoop.ipc.Server: Stopping server on 8030
2019-06-10 04:40:26,244 INFO org.apache.hadoop.ipc.Server: Stopping IPC Server listener on 8030
2019-06-10 04:40:26,245 INFO org.apache.hadoop.ipc.Server: Stopping IPC Server Responder
2019-06-10 04:40:26,281 INFO org.apache.hadoop.ipc.Server: Stopping server on 8031
2019-06-10 04:40:26,308 INFO org.apache.hadoop.ipc.Server: Stopping IPC Server listener on 8031
2019-06-10 04:40:26,318 INFO org.apache.hadoop.ipc.Server: Stopping IPC Server Responder
2019-06-10 04:40:26,320 ERROR org.apache.hadoop.yarn.server.resourcemanager.ResourceManager: Returning, interrupted : java.lang.InterruptedException
2019-06-10 04:40:26,347 INFO org.apache.hadoop.yarn.event.AsyncDispatcher: AsyncDispatcher is draining to stop, igonring any new events.
2019-06-10 04:40:26,348 INFO org.apache.hadoop.yarn.util.AbstractLivelinessMonitor: NMLivelinessMonitor thread interrupted
2019-06-10 04:40:26,369 INFO org.apache.hadoop.yarn.util.AbstractLivelinessMonitor: AMLivelinessMonitor thread interrupted
2019-06-10 04:40:26,376 INFO org.apache.hadoop.yarn.util.AbstractLivelinessMonitor: AMLivelinessMonitor thread interrupted
2019-06-10 04:40:26,384 INFO org.apache.hadoop.yarn.util.AbstractLivelinessMonitor: org.apache.hadoop.yarn.server.resourcemanager.rmcontainer.ContainerAllocationExpirer thread interrupted
2019-06-10 04:40:26,391 ERROR org.apache.hadoop.security.token.delegation.AbstractDelegationTokenSecretManager: ExpiredTokenRemover received java.lang.InterruptedException: sleep interrupted
2019-06-10 04:40:26,407 INFO org.apache.hadoop.metrics2.impl.MetricsSystemImpl: Stopping ResourceManager metrics system...
2019-06-10 04:40:26,447 INFO org.apache.hadoop.metrics2.impl.MetricsSystemImpl: ResourceManager metrics system stopped.
2019-06-10 04:40:26,452 INFO org.apache.hadoop.metrics2.impl.MetricsSystemImpl: ResourceManager metrics system shutdown complete.
2019-06-10 04:40:26,453 INFO org.apache.hadoop.yarn.event.AsyncDispatcher: AsyncDispatcher is draining to stop, igonring any new events.
2019-06-10 04:40:26,455 INFO org.apache.hadoop.yarn.server.resourcemanager.ResourceManager: Transitioned to standby state
2019-06-10 04:40:26,457 INFO org.apache.hadoop.yarn.server.resourcemanager.ResourceManager: SHUTDOWN_MSG: 
/************************************************************
SHUTDOWN_MSG: Shutting down ResourceManager at ubuntu/127.0.1.1
************************************************************/
2019-06-10 04:41:52,157 INFO org.apache.hadoop.yarn.server.resourcemanager.ResourceManager: STARTUP_MSG: 
/************************************************************
STARTUP_MSG: Starting ResourceManager
STARTUP_MSG:   user = hduser
STARTUP_MSG:   host = ubuntu/127.0.1.1
STARTUP_MSG:   args = []
STARTUP_MSG:   version = 2.8.5
STARTUP_MSG:   build = https://git-wip-us.apache.org/repos/asf/hadoop.git -r 0b8464d75227fcee2c6e7f2410377b3d53d3d5f8; compiled by 'jdu' on 2018-09-10T03:32Z
STARTUP_MSG:   java = 1.8.0_211
************************************************************/
2019-06-10 04:41:52,165 INFO org.apache.hadoop.yarn.server.resourcemanager.ResourceManager: registered UNIX signal handlers for [TERM, HUP, INT]
2019-06-10 04:41:52,471 INFO org.apache.hadoop.conf.Configuration: found resource core-site.xml at file:/opt/hadoop/etc/hadoop/core-site.xml
2019-06-10 04:41:52,543 WARN org.apache.hadoop.util.NativeCodeLoader: Unable to load native-hadoop library for your platform... using builtin-java classes where applicable
2019-06-10 04:41:52,563 INFO org.apache.hadoop.security.Groups: clearing userToGroupsMap cache
2019-06-10 04:41:52,632 INFO org.apache.hadoop.conf.Configuration: found resource yarn-site.xml at file:/opt/hadoop/etc/hadoop/yarn-site.xml
2019-06-10 04:41:52,774 INFO org.apache.hadoop.yarn.event.AsyncDispatcher: Registering class org.apache.hadoop.yarn.server.resourcemanager.RMFatalEventType for class org.apache.hadoop.yarn.server.resourcemanager.ResourceManager$RMFatalEventDispatcher
2019-06-10 04:41:53,198 INFO org.apache.hadoop.yarn.server.resourcemanager.security.NMTokenSecretManagerInRM: NMTokenKeyRollingInterval: 86400000ms and NMTokenKeyActivationDelay: 900000ms
2019-06-10 04:41:53,211 INFO org.apache.hadoop.yarn.server.resourcemanager.security.RMContainerTokenSecretManager: ContainerTokenKeyRollingInterval: 86400000ms and ContainerTokenKeyActivationDelay: 900000ms
2019-06-10 04:41:53,225 INFO org.apache.hadoop.yarn.server.resourcemanager.security.AMRMTokenSecretManager: AMRMTokenKeyRollingInterval: 86400000ms and AMRMTokenKeyActivationDelay: 900000 ms
2019-06-10 04:41:53,279 INFO org.apache.hadoop.yarn.event.AsyncDispatcher: Registering class org.apache.hadoop.yarn.server.resourcemanager.recovery.RMStateStoreEventType for class org.apache.hadoop.yarn.server.resourcemanager.recovery.RMStateStore$ForwardingEventHandler
2019-06-10 04:41:53,286 INFO org.apache.hadoop.yarn.event.AsyncDispatcher: Registering class org.apache.hadoop.yarn.server.resourcemanager.NodesListManagerEventType for class org.apache.hadoop.yarn.server.resourcemanager.NodesListManager
2019-06-10 04:41:53,286 INFO org.apache.hadoop.yarn.server.resourcemanager.ResourceManager: Using Scheduler: org.apache.hadoop.yarn.server.resourcemanager.scheduler.capacity.CapacityScheduler
2019-06-10 04:41:53,319 INFO org.apache.hadoop.yarn.event.AsyncDispatcher: Registering class org.apache.hadoop.yarn.server.resourcemanager.scheduler.event.SchedulerEventType for class org.apache.hadoop.yarn.server.resourcemanager.ResourceManager$SchedulerEventDispatcher
2019-06-10 04:41:53,320 INFO org.apache.hadoop.yarn.event.AsyncDispatcher: Registering class org.apache.hadoop.yarn.server.resourcemanager.rmapp.RMAppEventType for class org.apache.hadoop.yarn.server.resourcemanager.ResourceManager$ApplicationEventDispatcher
2019-06-10 04:41:53,321 INFO org.apache.hadoop.yarn.event.AsyncDispatcher: Registering class org.apache.hadoop.yarn.server.resourcemanager.rmapp.attempt.RMAppAttemptEventType for class org.apache.hadoop.yarn.server.resourcemanager.ResourceManager$ApplicationAttemptEventDispatcher
2019-06-10 04:41:53,323 INFO org.apache.hadoop.yarn.event.AsyncDispatcher: Registering class org.apache.hadoop.yarn.server.resourcemanager.rmnode.RMNodeEventType for class org.apache.hadoop.yarn.server.resourcemanager.ResourceManager$NodeEventDispatcher
2019-06-10 04:41:53,369 INFO org.apache.hadoop.metrics2.impl.MetricsConfig: loaded properties from hadoop-metrics2.properties
2019-06-10 04:41:53,439 INFO org.apache.hadoop.metrics2.impl.MetricsSystemImpl: Scheduled Metric snapshot period at 10 second(s).
2019-06-10 04:41:53,439 INFO org.apache.hadoop.metrics2.impl.MetricsSystemImpl: ResourceManager metrics system started
2019-06-10 04:41:53,458 INFO org.apache.hadoop.yarn.event.AsyncDispatcher: Registering class org.apache.hadoop.yarn.server.resourcemanager.RMAppManagerEventType for class org.apache.hadoop.yarn.server.resourcemanager.RMAppManager
2019-06-10 04:41:53,469 INFO org.apache.hadoop.yarn.event.AsyncDispatcher: Registering class org.apache.hadoop.yarn.server.resourcemanager.amlauncher.AMLauncherEventType for class org.apache.hadoop.yarn.server.resourcemanager.amlauncher.ApplicationMasterLauncher
2019-06-10 04:41:53,471 INFO org.apache.hadoop.yarn.server.resourcemanager.RMNMInfo: Registered RMNMInfo MBean
2019-06-10 04:41:53,480 INFO org.apache.hadoop.yarn.security.YarnAuthorizationProvider: org.apache.hadoop.yarn.security.ConfiguredYarnAuthorizer is instiantiated.
2019-06-10 04:41:53,483 INFO org.apache.hadoop.util.HostsFileReader: Refreshing hosts (include/exclude) list
2019-06-10 04:41:53,507 INFO org.apache.hadoop.conf.Configuration: found resource capacity-scheduler.xml at file:/opt/hadoop/etc/hadoop/capacity-scheduler.xml
2019-06-10 04:41:53,630 INFO org.apache.hadoop.yarn.server.resourcemanager.scheduler.capacity.CapacitySchedulerConfiguration: max alloc mb per queue for root is undefined
2019-06-10 04:41:53,630 INFO org.apache.hadoop.yarn.server.resourcemanager.scheduler.capacity.CapacitySchedulerConfiguration: max alloc vcore per queue for root is undefined
2019-06-10 04:41:53,647 INFO org.apache.hadoop.yarn.server.resourcemanager.scheduler.capacity.ParentQueue: root, capacity=1.0, asboluteCapacity=1.0, maxCapacity=1.0, asboluteMaxCapacity=1.0, state=RUNNING, acls=SUBMIT_APP:*ADMINISTER_QUEUE:*, labels=*,, offswitchPerHeartbeatLimit = 1, reservationsContinueLooking=true
2019-06-10 04:41:53,647 INFO org.apache.hadoop.yarn.server.resourcemanager.scheduler.capacity.ParentQueue: Initialized parent-queue root name=root, fullname=root
2019-06-10 04:41:53,666 INFO org.apache.hadoop.yarn.server.resourcemanager.scheduler.capacity.CapacitySchedulerConfiguration: max alloc mb per queue for root.default is undefined
2019-06-10 04:41:53,666 INFO org.apache.hadoop.yarn.server.resourcemanager.scheduler.capacity.CapacitySchedulerConfiguration: max alloc vcore per queue for root.default is undefined
2019-06-10 04:41:53,669 INFO org.apache.hadoop.yarn.server.resourcemanager.scheduler.capacity.LeafQueue: Initializing default
capacity = 1.0 [= (float) configuredCapacity / 100 ]
asboluteCapacity = 1.0 [= parentAbsoluteCapacity * capacity ]
maxCapacity = 1.0 [= configuredMaxCapacity ]
absoluteMaxCapacity = 1.0 [= 1.0 maximumCapacity undefined, (parentAbsoluteMaxCapacity * maximumCapacity) / 100 otherwise ]
userLimit = 100 [= configuredUserLimit ]
userLimitFactor = 1.0 [= configuredUserLimitFactor ]
maxApplications = 10000 [= configuredMaximumSystemApplicationsPerQueue or (int)(configuredMaximumSystemApplications * absoluteCapacity)]
maxApplicationsPerUser = 10000 [= (int)(maxApplications * (userLimit / 100.0f) * userLimitFactor) ]
usedCapacity = 0.0 [= usedResourcesMemory / (clusterResourceMemory * absoluteCapacity)]
absoluteUsedCapacity = 0.0 [= usedResourcesMemory / clusterResourceMemory]
maxAMResourcePerQueuePercent = 0.1 [= configuredMaximumAMResourcePercent ]
minimumAllocationFactor = 0.875 [= (float)(maximumAllocationMemory - minimumAllocationMemory) / maximumAllocationMemory ]
maximumAllocation = <memory:8192, vCores:4> [= configuredMaxAllocation ]
numContainers = 0 [= currentNumContainers ]
state = RUNNING [= configuredState ]
acls = SUBMIT_APP:*ADMINISTER_QUEUE:* [= configuredAcls ]
nodeLocalityDelay = 40
labels=*,
reservationsContinueLooking = true
preemptionDisabled = true
defaultAppPriorityPerQueue = 0
2019-06-10 04:41:53,669 INFO org.apache.hadoop.yarn.server.resourcemanager.scheduler.capacity.CapacityScheduler: Initialized queue: default: capacity=1.0, absoluteCapacity=1.0, usedResources=<memory:0, vCores:0>, usedCapacity=0.0, absoluteUsedCapacity=0.0, numApps=0, numContainers=0
2019-06-10 04:41:53,670 INFO org.apache.hadoop.yarn.server.resourcemanager.scheduler.capacity.CapacityScheduler: Initialized queue: root: numChildQueue= 1, capacity=1.0, absoluteCapacity=1.0, usedResources=<memory:0, vCores:0>usedCapacity=0.0, numApps=0, numContainers=0
2019-06-10 04:41:53,670 INFO org.apache.hadoop.yarn.server.resourcemanager.scheduler.capacity.CapacityScheduler: Initialized root queue root: numChildQueue= 1, capacity=1.0, absoluteCapacity=1.0, usedResources=<memory:0, vCores:0>usedCapacity=0.0, numApps=0, numContainers=0
2019-06-10 04:41:53,670 INFO org.apache.hadoop.yarn.server.resourcemanager.scheduler.capacity.CapacityScheduler: Initialized queue mappings, override: false
2019-06-10 04:41:53,671 INFO org.apache.hadoop.yarn.server.resourcemanager.scheduler.capacity.CapacityScheduler: Initialized CapacityScheduler with calculator=class org.apache.hadoop.yarn.util.resource.DefaultResourceCalculator, minimumAllocation=<<memory:1024, vCores:1>>, maximumAllocation=<<memory:8192, vCores:4>>, asynchronousScheduling=false, asyncScheduleInterval=5ms
2019-06-10 04:41:53,677 INFO org.apache.hadoop.conf.Configuration: dynamic-resources.xml not found
2019-06-10 04:41:53,710 INFO org.apache.hadoop.yarn.server.resourcemanager.metrics.SystemMetricsPublisher: YARN system metrics publishing service is not enabled
2019-06-10 04:41:53,710 INFO org.apache.hadoop.yarn.server.resourcemanager.ResourceManager: Transitioning to active state
2019-06-10 04:41:53,729 INFO org.apache.hadoop.util.JvmPauseMonitor: Starting JVM pause monitor
2019-06-10 04:41:53,765 INFO org.apache.hadoop.yarn.server.resourcemanager.recovery.RMStateStore: Updating AMRMToken
2019-06-10 04:41:53,765 INFO org.apache.hadoop.yarn.server.resourcemanager.security.RMContainerTokenSecretManager: Rolling master-key for container-tokens
2019-06-10 04:41:53,765 INFO org.apache.hadoop.yarn.server.resourcemanager.security.NMTokenSecretManagerInRM: Rolling master-key for nm-tokens
2019-06-10 04:41:53,766 INFO org.apache.hadoop.security.token.delegation.AbstractDelegationTokenSecretManager: Updating the current master key for generating delegation tokens
2019-06-10 04:41:53,766 INFO org.apache.hadoop.yarn.server.resourcemanager.security.RMDelegationTokenSecretManager: storing master key with keyID 1
2019-06-10 04:41:53,766 INFO org.apache.hadoop.yarn.server.resourcemanager.recovery.RMStateStore: Storing RMDTMasterKey.
2019-06-10 04:41:53,768 INFO org.apache.hadoop.security.token.delegation.AbstractDelegationTokenSecretManager: Starting expired delegation token remover thread, tokenRemoverScanInterval=60 min(s)
2019-06-10 04:41:53,768 INFO org.apache.hadoop.security.token.delegation.AbstractDelegationTokenSecretManager: Updating the current master key for generating delegation tokens
2019-06-10 04:41:53,768 INFO org.apache.hadoop.yarn.server.resourcemanager.security.RMDelegationTokenSecretManager: storing master key with keyID 2
2019-06-10 04:41:53,769 INFO org.apache.hadoop.yarn.server.resourcemanager.recovery.RMStateStore: Storing RMDTMasterKey.
2019-06-10 04:41:53,774 INFO org.apache.hadoop.yarn.event.AsyncDispatcher: Registering class org.apache.hadoop.yarn.nodelabels.event.NodeLabelsStoreEventType for class org.apache.hadoop.yarn.nodelabels.CommonNodeLabelsManager$ForwardingEventHandler
2019-06-10 04:41:53,822 INFO org.apache.hadoop.ipc.CallQueueManager: Using callQueue: class java.util.concurrent.LinkedBlockingQueue queueCapacity: 5000 scheduler: class org.apache.hadoop.ipc.DefaultRpcScheduler
2019-06-10 04:41:53,844 INFO org.apache.hadoop.ipc.Server: Starting Socket Reader #1 for port 8031
2019-06-10 04:41:54,090 INFO org.apache.hadoop.yarn.factories.impl.pb.RpcServerFactoryPBImpl: Adding protocol org.apache.hadoop.yarn.server.api.ResourceTrackerPB to the server
2019-06-10 04:41:54,092 INFO org.apache.hadoop.ipc.Server: IPC Server Responder: starting
2019-06-10 04:41:54,094 INFO org.apache.hadoop.ipc.Server: IPC Server listener on 8031: starting
2019-06-10 04:41:54,151 INFO org.apache.hadoop.ipc.CallQueueManager: Using callQueue: class java.util.concurrent.LinkedBlockingQueue queueCapacity: 5000 scheduler: class org.apache.hadoop.ipc.DefaultRpcScheduler
2019-06-10 04:41:54,158 INFO org.apache.hadoop.ipc.Server: Starting Socket Reader #1 for port 8030
2019-06-10 04:41:54,185 INFO org.apache.hadoop.yarn.factories.impl.pb.RpcServerFactoryPBImpl: Adding protocol org.apache.hadoop.yarn.api.ApplicationMasterProtocolPB to the server
2019-06-10 04:41:54,188 INFO org.apache.hadoop.ipc.Server: IPC Server Responder: starting
2019-06-10 04:41:54,189 INFO org.apache.hadoop.ipc.Server: IPC Server listener on 8030: starting
2019-06-10 04:41:54,498 INFO org.apache.hadoop.ipc.CallQueueManager: Using callQueue: class java.util.concurrent.LinkedBlockingQueue queueCapacity: 5000 scheduler: class org.apache.hadoop.ipc.DefaultRpcScheduler
2019-06-10 04:41:54,515 INFO org.apache.hadoop.ipc.Server: Starting Socket Reader #1 for port 8032
2019-06-10 04:41:54,519 INFO org.apache.hadoop.yarn.factories.impl.pb.RpcServerFactoryPBImpl: Adding protocol org.apache.hadoop.yarn.api.ApplicationClientProtocolPB to the server
2019-06-10 04:41:54,523 INFO org.apache.hadoop.ipc.Server: IPC Server Responder: starting
2019-06-10 04:41:54,524 INFO org.apache.hadoop.ipc.Server: IPC Server listener on 8032: starting
2019-06-10 04:41:54,535 INFO org.apache.hadoop.yarn.server.resourcemanager.ResourceManager: Transitioned to active state
2019-06-10 04:41:54,740 INFO org.mortbay.log: Logging to org.slf4j.impl.Log4jLoggerAdapter(org.mortbay.log) via org.mortbay.log.Slf4jLog
2019-06-10 04:41:54,747 INFO org.apache.hadoop.security.authentication.server.AuthenticationFilter: Unable to initialize FileSignerSecretProvider, falling back to use random secrets.
2019-06-10 04:41:54,755 INFO org.apache.hadoop.http.HttpRequestLog: Http request log for http.requests.resourcemanager is not defined
2019-06-10 04:41:54,771 INFO org.apache.hadoop.http.HttpServer2: Added global filter 'safety' (class=org.apache.hadoop.http.HttpServer2$QuotingInputFilter)
2019-06-10 04:41:54,780 INFO org.apache.hadoop.http.HttpServer2: Added filter RMAuthenticationFilter (class=org.apache.hadoop.yarn.server.security.http.RMAuthenticationFilter) to context cluster
2019-06-10 04:41:54,780 INFO org.apache.hadoop.http.HttpServer2: Added filter RMAuthenticationFilter (class=org.apache.hadoop.yarn.server.security.http.RMAuthenticationFilter) to context static
2019-06-10 04:41:54,780 INFO org.apache.hadoop.http.HttpServer2: Added filter RMAuthenticationFilter (class=org.apache.hadoop.yarn.server.security.http.RMAuthenticationFilter) to context logs
2019-06-10 04:41:54,781 INFO org.apache.hadoop.http.HttpServer2: Added filter static_user_filter (class=org.apache.hadoop.http.lib.StaticUserWebFilter$StaticUserFilter) to context cluster
2019-06-10 04:41:54,781 INFO org.apache.hadoop.http.HttpServer2: Added filter static_user_filter (class=org.apache.hadoop.http.lib.StaticUserWebFilter$StaticUserFilter) to context static
2019-06-10 04:41:54,781 INFO org.apache.hadoop.http.HttpServer2: Added filter static_user_filter (class=org.apache.hadoop.http.lib.StaticUserWebFilter$StaticUserFilter) to context logs
2019-06-10 04:41:54,791 INFO org.apache.hadoop.http.HttpServer2: adding path spec: /cluster/*
2019-06-10 04:41:54,791 INFO org.apache.hadoop.http.HttpServer2: adding path spec: /ws/*
2019-06-10 04:41:55,411 INFO org.apache.hadoop.yarn.webapp.WebApps: Registered webapp guice modules
2019-06-10 04:41:55,421 INFO org.apache.hadoop.http.HttpServer2: Jetty bound to port 8088
2019-06-10 04:41:55,421 INFO org.mortbay.log: jetty-6.1.26
2019-06-10 04:41:55,480 INFO org.mortbay.log: Extract jar:file:/opt/hadoop/share/hadoop/yarn/hadoop-yarn-common-2.8.5.jar!/webapps/cluster to /tmp/Jetty_0_0_0_0_8088_cluster____u0rgz3/webapp
2019-06-10 04:41:55,807 INFO org.apache.hadoop.security.token.delegation.AbstractDelegationTokenSecretManager: Updating the current master key for generating delegation tokens
2019-06-10 04:41:55,814 INFO org.apache.hadoop.security.token.delegation.AbstractDelegationTokenSecretManager: Starting expired delegation token remover thread, tokenRemoverScanInterval=60 min(s)
2019-06-10 04:41:55,817 INFO org.apache.hadoop.security.token.delegation.AbstractDelegationTokenSecretManager: Updating the current master key for generating delegation tokens
2019-06-10 04:41:57,978 INFO org.mortbay.log: Started HttpServer2$SelectChannelConnectorWithSafeStartup@0.0.0.0:8088
2019-06-10 04:41:57,978 INFO org.apache.hadoop.yarn.webapp.WebApps: Web app cluster started at 8088
2019-06-10 04:41:58,108 INFO org.apache.hadoop.ipc.CallQueueManager: Using callQueue: class java.util.concurrent.LinkedBlockingQueue queueCapacity: 100 scheduler: class org.apache.hadoop.ipc.DefaultRpcScheduler
2019-06-10 04:41:58,135 INFO org.apache.hadoop.ipc.Server: Starting Socket Reader #1 for port 8033
2019-06-10 04:41:58,167 INFO org.apache.hadoop.yarn.factories.impl.pb.RpcServerFactoryPBImpl: Adding protocol org.apache.hadoop.yarn.server.api.ResourceManagerAdministrationProtocolPB to the server
2019-06-10 04:41:58,172 INFO org.apache.hadoop.ipc.Server: IPC Server Responder: starting
2019-06-10 04:41:58,219 INFO org.apache.hadoop.ipc.Server: IPC Server listener on 8033: starting
2019-06-10 04:41:59,709 INFO org.apache.hadoop.yarn.server.resourcemanager.rmnode.RMNodeImpl: ubuntu:43547 Node Transitioned from NEW to RUNNING
2019-06-10 04:41:59,713 INFO org.apache.hadoop.yarn.server.resourcemanager.ResourceTrackerService: NodeManager from node ubuntu(cmPort: 43547 httpPort: 8042) registered with capability: <memory:8192, vCores:8>, assigned nodeId ubuntu:43547
2019-06-10 04:41:59,725 INFO org.apache.hadoop.yarn.server.resourcemanager.scheduler.capacity.CapacityScheduler: Added node ubuntu:43547 clusterResource: <memory:8192, vCores:8>
2019-06-10 04:42:33,460 INFO org.apache.hadoop.yarn.server.resourcemanager.ClientRMService: Allocated new applicationId: 1
2019-06-10 04:42:39,459 INFO org.apache.hadoop.yarn.server.resourcemanager.scheduler.capacity.CapacityScheduler: Application 'application_1560166913711_0001' is submitted without priority hence considering default queue/cluster priority: 0
2019-06-10 04:42:39,460 INFO org.apache.hadoop.yarn.server.resourcemanager.scheduler.capacity.CapacityScheduler: Priority '0' is acceptable in queue : default for application: application_1560166913711_0001 for the user: hduser
2019-06-10 04:42:39,490 INFO org.apache.hadoop.yarn.server.resourcemanager.ClientRMService: Application with id 1 submitted by user hduser
2019-06-10 04:42:39,490 INFO org.apache.hadoop.yarn.server.resourcemanager.rmapp.RMAppImpl: Storing application with id application_1560166913711_0001
2019-06-10 04:42:39,494 INFO org.apache.hadoop.yarn.server.resourcemanager.RMAuditLogger: USER=hduser	IP=127.0.0.1	OPERATION=Submit Application Request	TARGET=ClientRMService	RESULT=SUCCESS	APPID=application_1560166913711_0001	CALLERCONTEXT=CLI
2019-06-10 04:42:39,509 INFO org.apache.hadoop.yarn.server.resourcemanager.recovery.RMStateStore: Storing info for app: application_1560166913711_0001
2019-06-10 04:42:39,510 INFO org.apache.hadoop.yarn.server.resourcemanager.rmapp.RMAppImpl: application_1560166913711_0001 State change from NEW to NEW_SAVING on event=START
2019-06-10 04:42:39,603 INFO org.apache.hadoop.yarn.server.resourcemanager.rmapp.RMAppImpl: application_1560166913711_0001 State change from NEW_SAVING to SUBMITTED on event=APP_NEW_SAVED
2019-06-10 04:42:39,608 INFO org.apache.hadoop.yarn.server.resourcemanager.scheduler.capacity.ParentQueue: Application added - appId: application_1560166913711_0001 user: hduser leaf-queue of parent: root #applications: 1
2019-06-10 04:42:39,610 INFO org.apache.hadoop.yarn.server.resourcemanager.scheduler.capacity.CapacityScheduler: Accepted application application_1560166913711_0001 from user: hduser, in queue: default
2019-06-10 04:42:39,662 INFO org.apache.hadoop.yarn.server.resourcemanager.rmapp.RMAppImpl: application_1560166913711_0001 State change from SUBMITTED to ACCEPTED on event=APP_ACCEPTED
2019-06-10 04:42:39,709 INFO org.apache.hadoop.yarn.server.resourcemanager.ApplicationMasterService: Registering app attempt : appattempt_1560166913711_0001_000001
2019-06-10 04:42:39,709 INFO org.apache.hadoop.yarn.server.resourcemanager.rmapp.attempt.RMAppAttemptImpl: appattempt_1560166913711_0001_000001 State change from NEW to SUBMITTED
2019-06-10 04:42:39,747 WARN org.apache.hadoop.yarn.server.resourcemanager.scheduler.capacity.LeafQueue: maximum-am-resource-percent is insufficient to start a single application in queue, it is likely set too low. skipping enforcement to allow at least one application to start
2019-06-10 04:42:39,747 WARN org.apache.hadoop.yarn.server.resourcemanager.scheduler.capacity.LeafQueue: maximum-am-resource-percent is insufficient to start a single application in queue for user, it is likely set too low. skipping enforcement to allow at least one application to start
2019-06-10 04:42:39,749 INFO org.apache.hadoop.yarn.server.resourcemanager.scheduler.capacity.LeafQueue: Application application_1560166913711_0001 from user: hduser activated in queue: default
2019-06-10 04:42:39,749 INFO org.apache.hadoop.yarn.server.resourcemanager.scheduler.capacity.LeafQueue: Application added - appId: application_1560166913711_0001 user: hduser, leaf-queue: default #user-pending-applications: 0 #user-active-applications: 1 #queue-pending-applications: 0 #queue-active-applications: 1
2019-06-10 04:42:39,749 INFO org.apache.hadoop.yarn.server.resourcemanager.scheduler.capacity.CapacityScheduler: Added Application Attempt appattempt_1560166913711_0001_000001 to scheduler from user hduser in queue default
2019-06-10 04:42:39,755 INFO org.apache.hadoop.yarn.server.resourcemanager.rmapp.attempt.RMAppAttemptImpl: appattempt_1560166913711_0001_000001 State change from SUBMITTED to SCHEDULED
2019-06-10 04:42:39,985 INFO org.apache.hadoop.yarn.server.resourcemanager.rmcontainer.RMContainerImpl: container_1560166913711_0001_01_000001 Container Transitioned from NEW to ALLOCATED
2019-06-10 04:42:39,985 INFO org.apache.hadoop.yarn.server.resourcemanager.RMAuditLogger: USER=hduser	OPERATION=AM Allocated Container	TARGET=SchedulerApp	RESULT=SUCCESS	APPID=application_1560166913711_0001	CONTAINERID=container_1560166913711_0001_01_000001
2019-06-10 04:42:39,995 INFO org.apache.hadoop.yarn.server.resourcemanager.scheduler.SchedulerNode: Assigned container container_1560166913711_0001_01_000001 of capacity <memory:2048, vCores:1> on host ubuntu:43547, which has 1 containers, <memory:2048, vCores:1> used and <memory:6144, vCores:7> available after allocation
2019-06-10 04:42:39,996 INFO org.apache.hadoop.yarn.server.resourcemanager.scheduler.capacity.allocator.AbstractContainerAllocator: assignedContainer application attempt=appattempt_1560166913711_0001_000001 container=container_1560166913711_0001_01_000001 queue=org.apache.hadoop.yarn.server.resourcemanager.scheduler.capacity.allocator.RegularContainerAllocator@57c165ef clusterResource=<memory:8192, vCores:8> type=OFF_SWITCH requestedPartition=
2019-06-10 04:42:40,036 INFO org.apache.hadoop.yarn.server.resourcemanager.security.NMTokenSecretManagerInRM: Sending NMToken for nodeId : ubuntu:43547 for container : container_1560166913711_0001_01_000001
2019-06-10 04:42:40,053 INFO org.apache.hadoop.yarn.server.resourcemanager.rmcontainer.RMContainerImpl: container_1560166913711_0001_01_000001 Container Transitioned from ALLOCATED to ACQUIRED
2019-06-10 04:42:40,057 INFO org.apache.hadoop.yarn.server.resourcemanager.scheduler.capacity.ParentQueue: Re-sorting assigned queue: root.default stats: default: capacity=1.0, absoluteCapacity=1.0, usedResources=<memory:2048, vCores:1>, usedCapacity=0.25, absoluteUsedCapacity=0.25, numApps=1, numContainers=1
2019-06-10 04:42:40,058 INFO org.apache.hadoop.yarn.server.resourcemanager.scheduler.capacity.ParentQueue: assignedContainer queue=root usedCapacity=0.25 absoluteUsedCapacity=0.25 used=<memory:2048, vCores:1> cluster=<memory:8192, vCores:8>
2019-06-10 04:42:40,058 INFO org.apache.hadoop.yarn.server.resourcemanager.security.NMTokenSecretManagerInRM: Clear node set for appattempt_1560166913711_0001_000001
2019-06-10 04:42:40,058 INFO org.apache.hadoop.yarn.server.resourcemanager.rmapp.attempt.RMAppAttemptImpl: Storing attempt: AppId: application_1560166913711_0001 AttemptId: appattempt_1560166913711_0001_000001 MasterContainer: Container: [ContainerId: container_1560166913711_0001_01_000001, Version: 0, NodeId: ubuntu:43547, NodeHttpAddress: ubuntu:8042, Resource: <memory:2048, vCores:1>, Priority: 0, Token: Token { kind: ContainerToken, service: 127.0.1.1:43547 }, ]
2019-06-10 04:42:40,080 INFO org.apache.hadoop.yarn.server.resourcemanager.rmapp.attempt.RMAppAttemptImpl: appattempt_1560166913711_0001_000001 State change from SCHEDULED to ALLOCATED_SAVING
2019-06-10 04:42:40,091 INFO org.apache.hadoop.yarn.server.resourcemanager.rmapp.attempt.RMAppAttemptImpl: appattempt_1560166913711_0001_000001 State change from ALLOCATED_SAVING to ALLOCATED
2019-06-10 04:42:40,108 INFO org.apache.hadoop.yarn.server.resourcemanager.amlauncher.AMLauncher: Launching masterappattempt_1560166913711_0001_000001
2019-06-10 04:42:40,277 INFO org.apache.hadoop.yarn.server.resourcemanager.amlauncher.AMLauncher: Setting up container Container: [ContainerId: container_1560166913711_0001_01_000001, Version: 0, NodeId: ubuntu:43547, NodeHttpAddress: ubuntu:8042, Resource: <memory:2048, vCores:1>, Priority: 0, Token: Token { kind: ContainerToken, service: 127.0.1.1:43547 }, ] for AM appattempt_1560166913711_0001_000001
2019-06-10 04:42:40,277 INFO org.apache.hadoop.yarn.server.resourcemanager.security.AMRMTokenSecretManager: Create AMRMToken for ApplicationAttempt: appattempt_1560166913711_0001_000001
2019-06-10 04:42:40,282 INFO org.apache.hadoop.yarn.server.resourcemanager.security.AMRMTokenSecretManager: Creating password for appattempt_1560166913711_0001_000001
2019-06-10 04:42:40,688 INFO org.apache.hadoop.yarn.server.resourcemanager.amlauncher.AMLauncher: Done launching container Container: [ContainerId: container_1560166913711_0001_01_000001, Version: 0, NodeId: ubuntu:43547, NodeHttpAddress: ubuntu:8042, Resource: <memory:2048, vCores:1>, Priority: 0, Token: Token { kind: ContainerToken, service: 127.0.1.1:43547 }, ] for AM appattempt_1560166913711_0001_000001
2019-06-10 04:42:40,688 INFO org.apache.hadoop.yarn.server.resourcemanager.rmapp.attempt.RMAppAttemptImpl: appattempt_1560166913711_0001_000001 State change from ALLOCATED to LAUNCHED
2019-06-10 04:42:40,971 INFO org.apache.hadoop.yarn.server.resourcemanager.rmcontainer.RMContainerImpl: container_1560166913711_0001_01_000001 Container Transitioned from ACQUIRED to RUNNING
2019-06-10 04:42:50,610 INFO SecurityLogger.org.apache.hadoop.ipc.Server: Auth successful for appattempt_1560166913711_0001_000001 (auth:SIMPLE)
2019-06-10 04:42:50,626 INFO org.apache.hadoop.yarn.server.resourcemanager.ApplicationMasterService: AM registration appattempt_1560166913711_0001_000001
2019-06-10 04:42:50,628 INFO org.apache.hadoop.yarn.server.resourcemanager.rmapp.attempt.RMAppAttemptImpl: appattempt_1560166913711_0001_000001 State change from LAUNCHED to RUNNING
2019-06-10 04:42:50,628 INFO org.apache.hadoop.yarn.server.resourcemanager.rmapp.RMAppImpl: application_1560166913711_0001 State change from ACCEPTED to RUNNING on event=ATTEMPT_REGISTERED
2019-06-10 04:42:50,628 INFO org.apache.hadoop.yarn.server.resourcemanager.RMAuditLogger: USER=hduser	IP=127.0.0.1	OPERATION=Register App Master	TARGET=ApplicationMasterService	RESULT=SUCCESS	APPID=application_1560166913711_0001	APPATTEMPTID=appattempt_1560166913711_0001_000001
2019-06-10 04:42:52,012 INFO org.apache.hadoop.yarn.server.resourcemanager.rmcontainer.RMContainerImpl: container_1560166913711_0001_01_000002 Container Transitioned from NEW to ALLOCATED
2019-06-10 04:42:52,013 INFO org.apache.hadoop.yarn.server.resourcemanager.RMAuditLogger: USER=hduser	OPERATION=AM Allocated Container	TARGET=SchedulerApp	RESULT=SUCCESS	APPID=application_1560166913711_0001	CONTAINERID=container_1560166913711_0001_01_000002
2019-06-10 04:42:52,013 INFO org.apache.hadoop.yarn.server.resourcemanager.scheduler.SchedulerNode: Assigned container container_1560166913711_0001_01_000002 of capacity <memory:1024, vCores:1> on host ubuntu:43547, which has 2 containers, <memory:3072, vCores:2> used and <memory:5120, vCores:6> available after allocation
2019-06-10 04:42:52,014 INFO org.apache.hadoop.yarn.server.resourcemanager.scheduler.capacity.allocator.AbstractContainerAllocator: assignedContainer application attempt=appattempt_1560166913711_0001_000001 container=container_1560166913711_0001_01_000002 queue=org.apache.hadoop.yarn.server.resourcemanager.scheduler.capacity.allocator.RegularContainerAllocator@57c165ef clusterResource=<memory:8192, vCores:8> type=OFF_SWITCH requestedPartition=
2019-06-10 04:42:52,014 INFO org.apache.hadoop.yarn.server.resourcemanager.scheduler.capacity.ParentQueue: Re-sorting assigned queue: root.default stats: default: capacity=1.0, absoluteCapacity=1.0, usedResources=<memory:3072, vCores:2>, usedCapacity=0.375, absoluteUsedCapacity=0.375, numApps=1, numContainers=2
2019-06-10 04:42:52,014 INFO org.apache.hadoop.yarn.server.resourcemanager.scheduler.capacity.ParentQueue: assignedContainer queue=root usedCapacity=0.375 absoluteUsedCapacity=0.375 used=<memory:3072, vCores:2> cluster=<memory:8192, vCores:8>
2019-06-10 04:42:52,732 INFO org.apache.hadoop.yarn.server.resourcemanager.security.NMTokenSecretManagerInRM: Sending NMToken for nodeId : ubuntu:43547 for container : container_1560166913711_0001_01_000002
2019-06-10 04:42:52,733 INFO org.apache.hadoop.yarn.server.resourcemanager.rmcontainer.RMContainerImpl: container_1560166913711_0001_01_000002 Container Transitioned from ALLOCATED to ACQUIRED
2019-06-10 04:42:53,016 INFO org.apache.hadoop.yarn.server.resourcemanager.rmcontainer.RMContainerImpl: container_1560166913711_0001_01_000003 Container Transitioned from NEW to ALLOCATED
2019-06-10 04:42:53,016 INFO org.apache.hadoop.yarn.server.resourcemanager.RMAuditLogger: USER=hduser	OPERATION=AM Allocated Container	TARGET=SchedulerApp	RESULT=SUCCESS	APPID=application_1560166913711_0001	CONTAINERID=container_1560166913711_0001_01_000003
2019-06-10 04:42:53,016 INFO org.apache.hadoop.yarn.server.resourcemanager.scheduler.SchedulerNode: Assigned container container_1560166913711_0001_01_000003 of capacity <memory:1024, vCores:1> on host ubuntu:43547, which has 3 containers, <memory:4096, vCores:3> used and <memory:4096, vCores:5> available after allocation
2019-06-10 04:42:53,016 INFO org.apache.hadoop.yarn.server.resourcemanager.scheduler.capacity.allocator.AbstractContainerAllocator: assignedContainer application attempt=appattempt_1560166913711_0001_000001 container=container_1560166913711_0001_01_000003 queue=org.apache.hadoop.yarn.server.resourcemanager.scheduler.capacity.allocator.RegularContainerAllocator@57c165ef clusterResource=<memory:8192, vCores:8> type=OFF_SWITCH requestedPartition=
2019-06-10 04:42:53,016 INFO org.apache.hadoop.yarn.server.resourcemanager.scheduler.capacity.ParentQueue: Re-sorting assigned queue: root.default stats: default: capacity=1.0, absoluteCapacity=1.0, usedResources=<memory:4096, vCores:3>, usedCapacity=0.5, absoluteUsedCapacity=0.5, numApps=1, numContainers=3
2019-06-10 04:42:53,017 INFO org.apache.hadoop.yarn.server.resourcemanager.scheduler.capacity.ParentQueue: assignedContainer queue=root usedCapacity=0.5 absoluteUsedCapacity=0.5 used=<memory:4096, vCores:3> cluster=<memory:8192, vCores:8>
2019-06-10 04:42:53,752 INFO org.apache.hadoop.yarn.server.resourcemanager.rmcontainer.RMContainerImpl: container_1560166913711_0001_01_000003 Container Transitioned from ALLOCATED to ACQUIRED
2019-06-10 04:42:54,021 INFO org.apache.hadoop.yarn.server.resourcemanager.rmcontainer.RMContainerImpl: container_1560166913711_0001_01_000002 Container Transitioned from ACQUIRED to RUNNING
2019-06-10 04:42:54,022 INFO org.apache.hadoop.yarn.server.resourcemanager.rmcontainer.RMContainerImpl: container_1560166913711_0001_01_000003 Container Transitioned from ACQUIRED to RUNNING
2019-06-10 04:42:54,023 INFO org.apache.hadoop.yarn.server.resourcemanager.rmcontainer.RMContainerImpl: container_1560166913711_0001_01_000004 Container Transitioned from NEW to ALLOCATED
2019-06-10 04:42:54,023 INFO org.apache.hadoop.yarn.server.resourcemanager.RMAuditLogger: USER=hduser	OPERATION=AM Allocated Container	TARGET=SchedulerApp	RESULT=SUCCESS	APPID=application_1560166913711_0001	CONTAINERID=container_1560166913711_0001_01_000004
2019-06-10 04:42:54,023 INFO org.apache.hadoop.yarn.server.resourcemanager.scheduler.SchedulerNode: Assigned container container_1560166913711_0001_01_000004 of capacity <memory:1024, vCores:1> on host ubuntu:43547, which has 4 containers, <memory:5120, vCores:4> used and <memory:3072, vCores:4> available after allocation
2019-06-10 04:42:54,023 INFO org.apache.hadoop.yarn.server.resourcemanager.scheduler.capacity.allocator.AbstractContainerAllocator: assignedContainer application attempt=appattempt_1560166913711_0001_000001 container=container_1560166913711_0001_01_000004 queue=org.apache.hadoop.yarn.server.resourcemanager.scheduler.capacity.allocator.RegularContainerAllocator@57c165ef clusterResource=<memory:8192, vCores:8> type=OFF_SWITCH requestedPartition=
2019-06-10 04:42:54,024 INFO org.apache.hadoop.yarn.server.resourcemanager.scheduler.capacity.ParentQueue: Re-sorting assigned queue: root.default stats: default: capacity=1.0, absoluteCapacity=1.0, usedResources=<memory:5120, vCores:4>, usedCapacity=0.625, absoluteUsedCapacity=0.625, numApps=1, numContainers=4
2019-06-10 04:42:54,024 INFO org.apache.hadoop.yarn.server.resourcemanager.scheduler.capacity.ParentQueue: assignedContainer queue=root usedCapacity=0.625 absoluteUsedCapacity=0.625 used=<memory:5120, vCores:4> cluster=<memory:8192, vCores:8>
2019-06-10 04:42:54,756 INFO org.apache.hadoop.yarn.server.resourcemanager.rmcontainer.RMContainerImpl: container_1560166913711_0001_01_000004 Container Transitioned from ALLOCATED to ACQUIRED
2019-06-10 04:42:55,030 INFO org.apache.hadoop.yarn.server.resourcemanager.rmcontainer.RMContainerImpl: container_1560166913711_0001_01_000004 Container Transitioned from ACQUIRED to RUNNING
2019-06-10 04:42:55,035 INFO org.apache.hadoop.yarn.server.resourcemanager.rmcontainer.RMContainerImpl: container_1560166913711_0001_01_000005 Container Transitioned from NEW to ALLOCATED
2019-06-10 04:42:55,035 INFO org.apache.hadoop.yarn.server.resourcemanager.RMAuditLogger: USER=hduser	OPERATION=AM Allocated Container	TARGET=SchedulerApp	RESULT=SUCCESS	APPID=application_1560166913711_0001	CONTAINERID=container_1560166913711_0001_01_000005
2019-06-10 04:42:55,035 INFO org.apache.hadoop.yarn.server.resourcemanager.scheduler.SchedulerNode: Assigned container container_1560166913711_0001_01_000005 of capacity <memory:1024, vCores:1> on host ubuntu:43547, which has 5 containers, <memory:6144, vCores:5> used and <memory:2048, vCores:3> available after allocation
2019-06-10 04:42:55,035 INFO org.apache.hadoop.yarn.server.resourcemanager.scheduler.capacity.allocator.AbstractContainerAllocator: assignedContainer application attempt=appattempt_1560166913711_0001_000001 container=container_1560166913711_0001_01_000005 queue=org.apache.hadoop.yarn.server.resourcemanager.scheduler.capacity.allocator.RegularContainerAllocator@57c165ef clusterResource=<memory:8192, vCores:8> type=OFF_SWITCH requestedPartition=
2019-06-10 04:42:55,036 INFO org.apache.hadoop.yarn.server.resourcemanager.scheduler.capacity.ParentQueue: Re-sorting assigned queue: root.default stats: default: capacity=1.0, absoluteCapacity=1.0, usedResources=<memory:6144, vCores:5>, usedCapacity=0.75, absoluteUsedCapacity=0.75, numApps=1, numContainers=5
2019-06-10 04:42:55,036 INFO org.apache.hadoop.yarn.server.resourcemanager.scheduler.capacity.ParentQueue: assignedContainer queue=root usedCapacity=0.75 absoluteUsedCapacity=0.75 used=<memory:6144, vCores:5> cluster=<memory:8192, vCores:8>
2019-06-10 04:42:55,764 INFO org.apache.hadoop.yarn.server.resourcemanager.rmcontainer.RMContainerImpl: container_1560166913711_0001_01_000005 Container Transitioned from ALLOCATED to ACQUIRED
2019-06-10 04:42:56,035 INFO org.apache.hadoop.yarn.server.resourcemanager.rmcontainer.RMContainerImpl: container_1560166913711_0001_01_000005 Container Transitioned from ACQUIRED to RUNNING
2019-06-10 04:42:56,035 INFO org.apache.hadoop.yarn.server.resourcemanager.rmcontainer.RMContainerImpl: container_1560166913711_0001_01_000006 Container Transitioned from NEW to ALLOCATED
2019-06-10 04:42:56,036 INFO org.apache.hadoop.yarn.server.resourcemanager.RMAuditLogger: USER=hduser	OPERATION=AM Allocated Container	TARGET=SchedulerApp	RESULT=SUCCESS	APPID=application_1560166913711_0001	CONTAINERID=container_1560166913711_0001_01_000006
2019-06-10 04:42:56,036 INFO org.apache.hadoop.yarn.server.resourcemanager.scheduler.SchedulerNode: Assigned container container_1560166913711_0001_01_000006 of capacity <memory:1024, vCores:1> on host ubuntu:43547, which has 6 containers, <memory:7168, vCores:6> used and <memory:1024, vCores:2> available after allocation
2019-06-10 04:42:56,036 INFO org.apache.hadoop.yarn.server.resourcemanager.scheduler.capacity.allocator.AbstractContainerAllocator: assignedContainer application attempt=appattempt_1560166913711_0001_000001 container=container_1560166913711_0001_01_000006 queue=org.apache.hadoop.yarn.server.resourcemanager.scheduler.capacity.allocator.RegularContainerAllocator@57c165ef clusterResource=<memory:8192, vCores:8> type=OFF_SWITCH requestedPartition=
2019-06-10 04:42:56,036 INFO org.apache.hadoop.yarn.server.resourcemanager.scheduler.capacity.ParentQueue: Re-sorting assigned queue: root.default stats: default: capacity=1.0, absoluteCapacity=1.0, usedResources=<memory:7168, vCores:6>, usedCapacity=0.875, absoluteUsedCapacity=0.875, numApps=1, numContainers=6
2019-06-10 04:42:56,036 INFO org.apache.hadoop.yarn.server.resourcemanager.scheduler.capacity.ParentQueue: assignedContainer queue=root usedCapacity=0.875 absoluteUsedCapacity=0.875 used=<memory:7168, vCores:6> cluster=<memory:8192, vCores:8>
2019-06-10 04:42:56,768 INFO org.apache.hadoop.yarn.server.resourcemanager.scheduler.AppSchedulingInfo: checking for deactivate of application :application_1560166913711_0001
2019-06-10 04:42:56,771 INFO org.apache.hadoop.yarn.server.resourcemanager.rmcontainer.RMContainerImpl: container_1560166913711_0001_01_000006 Container Transitioned from ALLOCATED to ACQUIRED
2019-06-10 04:42:57,779 INFO org.apache.hadoop.yarn.server.resourcemanager.rmcontainer.RMContainerImpl: container_1560166913711_0001_01_000006 Container Transitioned from ACQUIRED to RELEASED
2019-06-10 04:42:57,780 INFO org.apache.hadoop.yarn.server.resourcemanager.RMAuditLogger: USER=hduser	IP=127.0.0.1	OPERATION=AM Released Container	TARGET=SchedulerApp	RESULT=SUCCESS	APPID=application_1560166913711_0001	CONTAINERID=container_1560166913711_0001_01_000006
2019-06-10 04:42:57,780 INFO org.apache.hadoop.yarn.server.resourcemanager.scheduler.SchedulerNode: Released container container_1560166913711_0001_01_000006 of capacity <memory:1024, vCores:1> on host ubuntu:43547, which currently has 5 containers, <memory:6144, vCores:5> used and <memory:2048, vCores:3> available, release resources=true
2019-06-10 04:43:08,599 INFO org.apache.hadoop.yarn.server.resourcemanager.rmcontainer.RMContainerImpl: container_1560166913711_0001_01_000002 Container Transitioned from RUNNING to COMPLETED
2019-06-10 04:43:08,600 INFO org.apache.hadoop.yarn.server.resourcemanager.RMAuditLogger: USER=hduser	OPERATION=AM Released Container	TARGET=SchedulerApp	RESULT=SUCCESS	APPID=application_1560166913711_0001	CONTAINERID=container_1560166913711_0001_01_000002
2019-06-10 04:43:12,401 INFO org.apache.hadoop.yarn.server.resourcemanager.scheduler.SchedulerNode: Released container container_1560166913711_0001_01_000002 of capacity <memory:1024, vCores:1> on host ubuntu:43547, which currently has 4 containers, <memory:5120, vCores:4> used and <memory:3072, vCores:4> available, release resources=true
2019-06-10 04:43:12,424 INFO org.apache.hadoop.yarn.server.resourcemanager.rmcontainer.RMContainerImpl: container_1560166913711_0001_01_000004 Container Transitioned from RUNNING to COMPLETED
2019-06-10 04:43:12,424 INFO org.apache.hadoop.yarn.server.resourcemanager.RMAuditLogger: USER=hduser	OPERATION=AM Released Container	TARGET=SchedulerApp	RESULT=SUCCESS	APPID=application_1560166913711_0001	CONTAINERID=container_1560166913711_0001_01_000004
2019-06-10 04:43:12,444 INFO org.apache.hadoop.yarn.server.resourcemanager.scheduler.SchedulerNode: Released container container_1560166913711_0001_01_000004 of capacity <memory:1024, vCores:1> on host ubuntu:43547, which currently has 3 containers, <memory:4096, vCores:3> used and <memory:4096, vCores:5> available, release resources=true
2019-06-10 04:43:12,450 INFO org.apache.hadoop.yarn.server.resourcemanager.rmcontainer.RMContainerImpl: container_1560166913711_0001_01_000003 Container Transitioned from RUNNING to COMPLETED
2019-06-10 04:43:12,451 INFO org.apache.hadoop.yarn.server.resourcemanager.RMAuditLogger: USER=hduser	OPERATION=AM Released Container	TARGET=SchedulerApp	RESULT=SUCCESS	APPID=application_1560166913711_0001	CONTAINERID=container_1560166913711_0001_01_000003
2019-06-10 04:43:12,453 INFO org.apache.hadoop.yarn.server.resourcemanager.scheduler.SchedulerNode: Released container container_1560166913711_0001_01_000003 of capacity <memory:1024, vCores:1> on host ubuntu:43547, which currently has 2 containers, <memory:3072, vCores:2> used and <memory:5120, vCores:6> available, release resources=true
2019-06-10 04:43:12,464 INFO org.apache.hadoop.yarn.server.resourcemanager.rmcontainer.RMContainerImpl: container_1560166913711_0001_01_000007 Container Transitioned from NEW to ALLOCATED
2019-06-10 04:43:12,464 INFO org.apache.hadoop.yarn.server.resourcemanager.RMAuditLogger: USER=hduser	OPERATION=AM Allocated Container	TARGET=SchedulerApp	RESULT=SUCCESS	APPID=application_1560166913711_0001	CONTAINERID=container_1560166913711_0001_01_000007
2019-06-10 04:43:12,465 INFO org.apache.hadoop.yarn.server.resourcemanager.scheduler.SchedulerNode: Assigned container container_1560166913711_0001_01_000007 of capacity <memory:1024, vCores:1> on host ubuntu:43547, which has 3 containers, <memory:4096, vCores:3> used and <memory:4096, vCores:5> available after allocation
2019-06-10 04:43:12,466 INFO org.apache.hadoop.yarn.server.resourcemanager.scheduler.capacity.allocator.AbstractContainerAllocator: assignedContainer application attempt=appattempt_1560166913711_0001_000001 container=container_1560166913711_0001_01_000007 queue=org.apache.hadoop.yarn.server.resourcemanager.scheduler.capacity.allocator.RegularContainerAllocator@57c165ef clusterResource=<memory:8192, vCores:8> type=OFF_SWITCH requestedPartition=
2019-06-10 04:43:12,468 INFO org.apache.hadoop.yarn.server.resourcemanager.scheduler.capacity.ParentQueue: Re-sorting assigned queue: root.default stats: default: capacity=1.0, absoluteCapacity=1.0, usedResources=<memory:4096, vCores:3>, usedCapacity=0.5, absoluteUsedCapacity=0.5, numApps=1, numContainers=3
2019-06-10 04:43:12,469 INFO org.apache.hadoop.yarn.server.resourcemanager.scheduler.capacity.ParentQueue: assignedContainer queue=root usedCapacity=0.5 absoluteUsedCapacity=0.5 used=<memory:4096, vCores:3> cluster=<memory:8192, vCores:8>
2019-06-10 04:43:13,082 INFO org.apache.hadoop.yarn.server.resourcemanager.rmcontainer.RMContainerImpl: container_1560166913711_0001_01_000005 Container Transitioned from RUNNING to COMPLETED
2019-06-10 04:43:13,082 INFO org.apache.hadoop.yarn.server.resourcemanager.RMAuditLogger: USER=hduser	OPERATION=AM Released Container	TARGET=SchedulerApp	RESULT=SUCCESS	APPID=application_1560166913711_0001	CONTAINERID=container_1560166913711_0001_01_000005
2019-06-10 04:43:13,084 INFO org.apache.hadoop.yarn.server.resourcemanager.scheduler.SchedulerNode: Released container container_1560166913711_0001_01_000005 of capacity <memory:1024, vCores:1> on host ubuntu:43547, which currently has 2 containers, <memory:3072, vCores:2> used and <memory:5120, vCores:6> available, release resources=true
2019-06-10 04:43:13,383 INFO org.apache.hadoop.yarn.server.resourcemanager.rmapp.attempt.RMAppAttemptImpl: Updating application attempt appattempt_1560166913711_0001_000001 with final state: FINISHING, and exit status: -1000
2019-06-10 04:43:13,387 INFO org.apache.hadoop.yarn.server.resourcemanager.rmapp.attempt.RMAppAttemptImpl: appattempt_1560166913711_0001_000001 State change from RUNNING to FINAL_SAVING
2019-06-10 04:43:13,389 INFO org.apache.hadoop.yarn.server.resourcemanager.rmapp.RMAppImpl: Updating application application_1560166913711_0001 with final state: FINISHING
2019-06-10 04:43:13,390 INFO org.apache.hadoop.yarn.server.resourcemanager.rmapp.RMAppImpl: application_1560166913711_0001 State change from RUNNING to FINAL_SAVING on event=ATTEMPT_UNREGISTERED
2019-06-10 04:43:13,390 INFO org.apache.hadoop.yarn.server.resourcemanager.recovery.RMStateStore: Updating info for app: application_1560166913711_0001
2019-06-10 04:43:13,391 INFO org.apache.hadoop.yarn.server.resourcemanager.rmapp.attempt.RMAppAttemptImpl: appattempt_1560166913711_0001_000001 State change from FINAL_SAVING to FINISHING
2019-06-10 04:43:13,392 INFO org.apache.hadoop.yarn.server.resourcemanager.rmapp.RMAppImpl: application_1560166913711_0001 State change from FINAL_SAVING to FINISHING on event=APP_UPDATE_SAVED
2019-06-10 04:43:14,411 INFO org.apache.hadoop.yarn.server.resourcemanager.ApplicationMasterService: application_1560166913711_0001 unregistered successfully. 
2019-06-10 04:43:19,949 INFO org.apache.hadoop.yarn.server.resourcemanager.rmcontainer.RMContainerImpl: container_1560166913711_0001_01_000001 Container Transitioned from RUNNING to COMPLETED
2019-06-10 04:43:19,949 INFO org.apache.hadoop.yarn.server.resourcemanager.RMAuditLogger: USER=hduser	OPERATION=AM Released Container	TARGET=SchedulerApp	RESULT=SUCCESS	APPID=application_1560166913711_0001	CONTAINERID=container_1560166913711_0001_01_000001
2019-06-10 04:43:19,950 INFO org.apache.hadoop.yarn.server.resourcemanager.ApplicationMasterService: Unregistering app attempt : appattempt_1560166913711_0001_000001
2019-06-10 04:43:19,950 INFO org.apache.hadoop.yarn.server.resourcemanager.scheduler.SchedulerNode: Released container container_1560166913711_0001_01_000001 of capacity <memory:2048, vCores:1> on host ubuntu:43547, which currently has 1 containers, <memory:1024, vCores:1> used and <memory:7168, vCores:7> available, release resources=true
2019-06-10 04:43:19,958 INFO org.apache.hadoop.yarn.server.resourcemanager.security.AMRMTokenSecretManager: Application finished, removing password for appattempt_1560166913711_0001_000001
2019-06-10 04:43:19,960 INFO org.apache.hadoop.yarn.server.resourcemanager.rmapp.attempt.RMAppAttemptImpl: appattempt_1560166913711_0001_000001 State change from FINISHING to FINISHED
2019-06-10 04:43:19,972 INFO org.apache.hadoop.yarn.server.resourcemanager.rmapp.RMAppImpl: application_1560166913711_0001 State change from FINISHING to FINISHED on event=ATTEMPT_FINISHED
2019-06-10 04:43:19,973 INFO org.apache.hadoop.yarn.server.resourcemanager.scheduler.capacity.CapacityScheduler: Application Attempt appattempt_1560166913711_0001_000001 is done. finalState=FINISHED
2019-06-10 04:43:19,974 INFO org.apache.hadoop.yarn.server.resourcemanager.rmcontainer.RMContainerImpl: container_1560166913711_0001_01_000007 Container Transitioned from ALLOCATED to KILLED
2019-06-10 04:43:19,974 INFO org.apache.hadoop.yarn.server.resourcemanager.RMAuditLogger: USER=hduser	OPERATION=AM Released Container	TARGET=SchedulerApp	RESULT=SUCCESS	APPID=application_1560166913711_0001	CONTAINERID=container_1560166913711_0001_01_000007
2019-06-10 04:43:19,974 INFO org.apache.hadoop.yarn.server.resourcemanager.scheduler.SchedulerNode: Released container container_1560166913711_0001_01_000007 of capacity <memory:1024, vCores:1> on host ubuntu:43547, which currently has 0 containers, <memory:0, vCores:0> used and <memory:8192, vCores:8> available, release resources=true
2019-06-10 04:43:19,976 INFO org.apache.hadoop.yarn.server.resourcemanager.scheduler.AppSchedulingInfo: Application application_1560166913711_0001 requests cleared
2019-06-10 04:43:19,982 INFO org.apache.hadoop.yarn.server.resourcemanager.scheduler.capacity.LeafQueue: Application removed - appId: application_1560166913711_0001 user: hduser queue: default #user-pending-applications: 0 #user-active-applications: 0 #queue-pending-applications: 0 #queue-active-applications: 0
2019-06-10 04:43:19,983 INFO org.apache.hadoop.yarn.server.resourcemanager.scheduler.capacity.ParentQueue: Application removed - appId: application_1560166913711_0001 user: hduser leaf-queue of parent: root #applications: 0
2019-06-10 04:43:19,984 INFO org.apache.hadoop.yarn.server.resourcemanager.RMAuditLogger: USER=hduser	OPERATION=Application Finished - Succeeded	TARGET=RMAppManager	RESULT=SUCCESS	APPID=application_1560166913711_0001
2019-06-10 04:43:19,994 INFO org.apache.hadoop.yarn.server.resourcemanager.amlauncher.AMLauncher: Cleaning master appattempt_1560166913711_0001_000001
2019-06-10 04:43:20,025 INFO org.apache.hadoop.yarn.server.resourcemanager.RMAppManager$ApplicationSummary: appId=application_1560166913711_0001,name=categories.jar,user=hduser,queue=default,state=FINISHED,trackingUrl=http://ubuntu:8088/proxy/application_1560166913711_0001/,appMasterHost=ubuntu,startTime=1560166959478,finishTime=1560166993389,finalStatus=SUCCEEDED,memorySeconds=165517,vcoreSeconds=118,preemptedMemorySeconds=0,preemptedVcoreSeconds=0,preemptedAMContainers=0,preemptedNonAMContainers=0,preemptedResources=<memory:0\, vCores:0>,applicationType=MAPREDUCE
2019-06-10 04:43:21,964 INFO org.apache.hadoop.yarn.server.resourcemanager.scheduler.AbstractYarnScheduler: Container container_1560166913711_0001_01_000005 completed with event FINISHED, but corresponding RMContainer doesn't exist.
2019-06-10 04:43:21,964 INFO org.apache.hadoop.yarn.server.resourcemanager.scheduler.AbstractYarnScheduler: Container container_1560166913711_0001_01_000003 completed with event FINISHED, but corresponding RMContainer doesn't exist.
2019-06-10 04:50:38,879 INFO org.apache.hadoop.yarn.server.resourcemanager.ClientRMService: Allocated new applicationId: 2
2019-06-10 04:50:41,306 INFO org.apache.hadoop.yarn.server.resourcemanager.scheduler.capacity.CapacityScheduler: Application 'application_1560166913711_0002' is submitted without priority hence considering default queue/cluster priority: 0
2019-06-10 04:50:41,306 INFO org.apache.hadoop.yarn.server.resourcemanager.scheduler.capacity.CapacityScheduler: Priority '0' is acceptable in queue : default for application: application_1560166913711_0002 for the user: hduser
2019-06-10 04:50:41,311 INFO org.apache.hadoop.yarn.server.resourcemanager.ClientRMService: Application with id 2 submitted by user hduser
2019-06-10 04:50:41,311 INFO org.apache.hadoop.yarn.server.resourcemanager.rmapp.RMAppImpl: Storing application with id application_1560166913711_0002
2019-06-10 04:50:41,311 INFO org.apache.hadoop.yarn.server.resourcemanager.RMAuditLogger: USER=hduser	IP=127.0.0.1	OPERATION=Submit Application Request	TARGET=ClientRMService	RESULT=SUCCESS	APPID=application_1560166913711_0002	CALLERCONTEXT=CLI
2019-06-10 04:50:41,312 INFO org.apache.hadoop.yarn.server.resourcemanager.rmapp.RMAppImpl: application_1560166913711_0002 State change from NEW to NEW_SAVING on event=START
2019-06-10 04:50:41,312 INFO org.apache.hadoop.yarn.server.resourcemanager.recovery.RMStateStore: Storing info for app: application_1560166913711_0002
2019-06-10 04:50:41,313 INFO org.apache.hadoop.yarn.server.resourcemanager.rmapp.RMAppImpl: application_1560166913711_0002 State change from NEW_SAVING to SUBMITTED on event=APP_NEW_SAVED
2019-06-10 04:50:41,315 INFO org.apache.hadoop.yarn.server.resourcemanager.scheduler.capacity.ParentQueue: Application added - appId: application_1560166913711_0002 user: hduser leaf-queue of parent: root #applications: 1
2019-06-10 04:50:41,315 INFO org.apache.hadoop.yarn.server.resourcemanager.scheduler.capacity.CapacityScheduler: Accepted application application_1560166913711_0002 from user: hduser, in queue: default
2019-06-10 04:50:41,319 INFO org.apache.hadoop.yarn.server.resourcemanager.rmapp.RMAppImpl: application_1560166913711_0002 State change from SUBMITTED to ACCEPTED on event=APP_ACCEPTED
2019-06-10 04:50:41,319 INFO org.apache.hadoop.yarn.server.resourcemanager.ApplicationMasterService: Registering app attempt : appattempt_1560166913711_0002_000001
2019-06-10 04:50:41,320 INFO org.apache.hadoop.yarn.server.resourcemanager.rmapp.attempt.RMAppAttemptImpl: appattempt_1560166913711_0002_000001 State change from NEW to SUBMITTED
2019-06-10 04:50:41,322 WARN org.apache.hadoop.yarn.server.resourcemanager.scheduler.capacity.LeafQueue: maximum-am-resource-percent is insufficient to start a single application in queue, it is likely set too low. skipping enforcement to allow at least one application to start
2019-06-10 04:50:41,322 WARN org.apache.hadoop.yarn.server.resourcemanager.scheduler.capacity.LeafQueue: maximum-am-resource-percent is insufficient to start a single application in queue for user, it is likely set too low. skipping enforcement to allow at least one application to start
2019-06-10 04:50:41,326 INFO org.apache.hadoop.yarn.server.resourcemanager.scheduler.capacity.LeafQueue: Application application_1560166913711_0002 from user: hduser activated in queue: default
2019-06-10 04:50:41,326 INFO org.apache.hadoop.yarn.server.resourcemanager.scheduler.capacity.LeafQueue: Application added - appId: application_1560166913711_0002 user: hduser, leaf-queue: default #user-pending-applications: 0 #user-active-applications: 1 #queue-pending-applications: 0 #queue-active-applications: 1
2019-06-10 04:50:41,327 INFO org.apache.hadoop.yarn.server.resourcemanager.scheduler.capacity.CapacityScheduler: Added Application Attempt appattempt_1560166913711_0002_000001 to scheduler from user hduser in queue default
2019-06-10 04:50:41,334 INFO org.apache.hadoop.yarn.server.resourcemanager.rmapp.attempt.RMAppAttemptImpl: appattempt_1560166913711_0002_000001 State change from SUBMITTED to SCHEDULED
2019-06-10 04:50:41,427 INFO org.apache.hadoop.yarn.server.resourcemanager.rmcontainer.RMContainerImpl: container_1560166913711_0002_01_000001 Container Transitioned from NEW to ALLOCATED
2019-06-10 04:50:41,427 INFO org.apache.hadoop.yarn.server.resourcemanager.RMAuditLogger: USER=hduser	OPERATION=AM Allocated Container	TARGET=SchedulerApp	RESULT=SUCCESS	APPID=application_1560166913711_0002	CONTAINERID=container_1560166913711_0002_01_000001
2019-06-10 04:50:41,427 INFO org.apache.hadoop.yarn.server.resourcemanager.scheduler.SchedulerNode: Assigned container container_1560166913711_0002_01_000001 of capacity <memory:2048, vCores:1> on host ubuntu:43547, which has 1 containers, <memory:2048, vCores:1> used and <memory:6144, vCores:7> available after allocation
2019-06-10 04:50:41,428 INFO org.apache.hadoop.yarn.server.resourcemanager.scheduler.capacity.allocator.AbstractContainerAllocator: assignedContainer application attempt=appattempt_1560166913711_0002_000001 container=container_1560166913711_0002_01_000001 queue=org.apache.hadoop.yarn.server.resourcemanager.scheduler.capacity.allocator.RegularContainerAllocator@38b61cb4 clusterResource=<memory:8192, vCores:8> type=OFF_SWITCH requestedPartition=
2019-06-10 04:50:41,444 INFO org.apache.hadoop.yarn.server.resourcemanager.security.NMTokenSecretManagerInRM: Sending NMToken for nodeId : ubuntu:43547 for container : container_1560166913711_0002_01_000001
2019-06-10 04:50:41,449 INFO org.apache.hadoop.yarn.server.resourcemanager.rmcontainer.RMContainerImpl: container_1560166913711_0002_01_000001 Container Transitioned from ALLOCATED to ACQUIRED
2019-06-10 04:50:41,450 INFO org.apache.hadoop.yarn.server.resourcemanager.scheduler.capacity.ParentQueue: Re-sorting assigned queue: root.default stats: default: capacity=1.0, absoluteCapacity=1.0, usedResources=<memory:2048, vCores:1>, usedCapacity=0.25, absoluteUsedCapacity=0.25, numApps=1, numContainers=1
2019-06-10 04:50:41,450 INFO org.apache.hadoop.yarn.server.resourcemanager.scheduler.capacity.ParentQueue: assignedContainer queue=root usedCapacity=0.25 absoluteUsedCapacity=0.25 used=<memory:2048, vCores:1> cluster=<memory:8192, vCores:8>
2019-06-10 04:50:41,451 INFO org.apache.hadoop.yarn.server.resourcemanager.security.NMTokenSecretManagerInRM: Clear node set for appattempt_1560166913711_0002_000001
2019-06-10 04:50:41,452 INFO org.apache.hadoop.yarn.server.resourcemanager.rmapp.attempt.RMAppAttemptImpl: Storing attempt: AppId: application_1560166913711_0002 AttemptId: appattempt_1560166913711_0002_000001 MasterContainer: Container: [ContainerId: container_1560166913711_0002_01_000001, Version: 0, NodeId: ubuntu:43547, NodeHttpAddress: ubuntu:8042, Resource: <memory:2048, vCores:1>, Priority: 0, Token: Token { kind: ContainerToken, service: 127.0.1.1:43547 }, ]
2019-06-10 04:50:41,458 INFO org.apache.hadoop.yarn.server.resourcemanager.rmapp.attempt.RMAppAttemptImpl: appattempt_1560166913711_0002_000001 State change from SCHEDULED to ALLOCATED_SAVING
2019-06-10 04:50:41,459 INFO org.apache.hadoop.yarn.server.resourcemanager.rmapp.attempt.RMAppAttemptImpl: appattempt_1560166913711_0002_000001 State change from ALLOCATED_SAVING to ALLOCATED
2019-06-10 04:50:41,460 INFO org.apache.hadoop.yarn.server.resourcemanager.amlauncher.AMLauncher: Launching masterappattempt_1560166913711_0002_000001
2019-06-10 04:50:41,470 INFO org.apache.hadoop.yarn.server.resourcemanager.amlauncher.AMLauncher: Setting up container Container: [ContainerId: container_1560166913711_0002_01_000001, Version: 0, NodeId: ubuntu:43547, NodeHttpAddress: ubuntu:8042, Resource: <memory:2048, vCores:1>, Priority: 0, Token: Token { kind: ContainerToken, service: 127.0.1.1:43547 }, ] for AM appattempt_1560166913711_0002_000001
2019-06-10 04:50:41,471 INFO org.apache.hadoop.yarn.server.resourcemanager.security.AMRMTokenSecretManager: Create AMRMToken for ApplicationAttempt: appattempt_1560166913711_0002_000001
2019-06-10 04:50:41,472 INFO org.apache.hadoop.yarn.server.resourcemanager.security.AMRMTokenSecretManager: Creating password for appattempt_1560166913711_0002_000001
2019-06-10 04:50:41,512 INFO org.apache.hadoop.yarn.server.resourcemanager.amlauncher.AMLauncher: Done launching container Container: [ContainerId: container_1560166913711_0002_01_000001, Version: 0, NodeId: ubuntu:43547, NodeHttpAddress: ubuntu:8042, Resource: <memory:2048, vCores:1>, Priority: 0, Token: Token { kind: ContainerToken, service: 127.0.1.1:43547 }, ] for AM appattempt_1560166913711_0002_000001
2019-06-10 04:50:41,513 INFO org.apache.hadoop.yarn.server.resourcemanager.rmapp.attempt.RMAppAttemptImpl: appattempt_1560166913711_0002_000001 State change from ALLOCATED to LAUNCHED
2019-06-10 04:50:42,429 INFO org.apache.hadoop.yarn.server.resourcemanager.rmcontainer.RMContainerImpl: container_1560166913711_0002_01_000001 Container Transitioned from ACQUIRED to RUNNING
2019-06-10 04:50:47,116 INFO SecurityLogger.org.apache.hadoop.ipc.Server: Auth successful for appattempt_1560166913711_0002_000001 (auth:SIMPLE)
2019-06-10 04:50:47,133 INFO org.apache.hadoop.yarn.server.resourcemanager.ApplicationMasterService: AM registration appattempt_1560166913711_0002_000001
2019-06-10 04:50:47,133 INFO org.apache.hadoop.yarn.server.resourcemanager.rmapp.attempt.RMAppAttemptImpl: appattempt_1560166913711_0002_000001 State change from LAUNCHED to RUNNING
2019-06-10 04:50:47,133 INFO org.apache.hadoop.yarn.server.resourcemanager.rmapp.RMAppImpl: application_1560166913711_0002 State change from ACCEPTED to RUNNING on event=ATTEMPT_REGISTERED
2019-06-10 04:50:47,134 INFO org.apache.hadoop.yarn.server.resourcemanager.RMAuditLogger: USER=hduser	IP=127.0.0.1	OPERATION=Register App Master	TARGET=ApplicationMasterService	RESULT=SUCCESS	APPID=application_1560166913711_0002	APPATTEMPTID=appattempt_1560166913711_0002_000001
2019-06-10 04:50:48,446 INFO org.apache.hadoop.yarn.server.resourcemanager.rmcontainer.RMContainerImpl: container_1560166913711_0002_01_000002 Container Transitioned from NEW to ALLOCATED
2019-06-10 04:50:48,446 INFO org.apache.hadoop.yarn.server.resourcemanager.RMAuditLogger: USER=hduser	OPERATION=AM Allocated Container	TARGET=SchedulerApp	RESULT=SUCCESS	APPID=application_1560166913711_0002	CONTAINERID=container_1560166913711_0002_01_000002
2019-06-10 04:50:48,446 INFO org.apache.hadoop.yarn.server.resourcemanager.scheduler.SchedulerNode: Assigned container container_1560166913711_0002_01_000002 of capacity <memory:1024, vCores:1> on host ubuntu:43547, which has 2 containers, <memory:3072, vCores:2> used and <memory:5120, vCores:6> available after allocation
2019-06-10 04:50:48,447 INFO org.apache.hadoop.yarn.server.resourcemanager.scheduler.capacity.allocator.AbstractContainerAllocator: assignedContainer application attempt=appattempt_1560166913711_0002_000001 container=container_1560166913711_0002_01_000002 queue=org.apache.hadoop.yarn.server.resourcemanager.scheduler.capacity.allocator.RegularContainerAllocator@38b61cb4 clusterResource=<memory:8192, vCores:8> type=OFF_SWITCH requestedPartition=
2019-06-10 04:50:48,447 INFO org.apache.hadoop.yarn.server.resourcemanager.scheduler.capacity.ParentQueue: Re-sorting assigned queue: root.default stats: default: capacity=1.0, absoluteCapacity=1.0, usedResources=<memory:3072, vCores:2>, usedCapacity=0.375, absoluteUsedCapacity=0.375, numApps=1, numContainers=2
2019-06-10 04:50:48,448 INFO org.apache.hadoop.yarn.server.resourcemanager.scheduler.capacity.ParentQueue: assignedContainer queue=root usedCapacity=0.375 absoluteUsedCapacity=0.375 used=<memory:3072, vCores:2> cluster=<memory:8192, vCores:8>
2019-06-10 04:50:49,212 INFO org.apache.hadoop.yarn.server.resourcemanager.security.NMTokenSecretManagerInRM: Sending NMToken for nodeId : ubuntu:43547 for container : container_1560166913711_0002_01_000002
2019-06-10 04:50:49,213 INFO org.apache.hadoop.yarn.server.resourcemanager.rmcontainer.RMContainerImpl: container_1560166913711_0002_01_000002 Container Transitioned from ALLOCATED to ACQUIRED
2019-06-10 04:50:49,451 INFO org.apache.hadoop.yarn.server.resourcemanager.rmcontainer.RMContainerImpl: container_1560166913711_0002_01_000003 Container Transitioned from NEW to ALLOCATED
2019-06-10 04:50:49,451 INFO org.apache.hadoop.yarn.server.resourcemanager.RMAuditLogger: USER=hduser	OPERATION=AM Allocated Container	TARGET=SchedulerApp	RESULT=SUCCESS	APPID=application_1560166913711_0002	CONTAINERID=container_1560166913711_0002_01_000003
2019-06-10 04:50:49,452 INFO org.apache.hadoop.yarn.server.resourcemanager.scheduler.SchedulerNode: Assigned container container_1560166913711_0002_01_000003 of capacity <memory:1024, vCores:1> on host ubuntu:43547, which has 3 containers, <memory:4096, vCores:3> used and <memory:4096, vCores:5> available after allocation
2019-06-10 04:50:49,452 INFO org.apache.hadoop.yarn.server.resourcemanager.scheduler.capacity.allocator.AbstractContainerAllocator: assignedContainer application attempt=appattempt_1560166913711_0002_000001 container=container_1560166913711_0002_01_000003 queue=org.apache.hadoop.yarn.server.resourcemanager.scheduler.capacity.allocator.RegularContainerAllocator@38b61cb4 clusterResource=<memory:8192, vCores:8> type=OFF_SWITCH requestedPartition=
2019-06-10 04:50:49,453 INFO org.apache.hadoop.yarn.server.resourcemanager.scheduler.capacity.ParentQueue: Re-sorting assigned queue: root.default stats: default: capacity=1.0, absoluteCapacity=1.0, usedResources=<memory:4096, vCores:3>, usedCapacity=0.5, absoluteUsedCapacity=0.5, numApps=1, numContainers=3
2019-06-10 04:50:49,453 INFO org.apache.hadoop.yarn.server.resourcemanager.scheduler.capacity.ParentQueue: assignedContainer queue=root usedCapacity=0.5 absoluteUsedCapacity=0.5 used=<memory:4096, vCores:3> cluster=<memory:8192, vCores:8>
2019-06-10 04:50:50,233 INFO org.apache.hadoop.yarn.server.resourcemanager.rmcontainer.RMContainerImpl: container_1560166913711_0002_01_000003 Container Transitioned from ALLOCATED to ACQUIRED
2019-06-10 04:50:50,466 INFO org.apache.hadoop.yarn.server.resourcemanager.rmcontainer.RMContainerImpl: container_1560166913711_0002_01_000002 Container Transitioned from ACQUIRED to RUNNING
2019-06-10 04:50:50,471 INFO org.apache.hadoop.yarn.server.resourcemanager.rmcontainer.RMContainerImpl: container_1560166913711_0002_01_000003 Container Transitioned from ACQUIRED to RUNNING
2019-06-10 04:50:50,472 INFO org.apache.hadoop.yarn.server.resourcemanager.rmcontainer.RMContainerImpl: container_1560166913711_0002_01_000004 Container Transitioned from NEW to ALLOCATED
2019-06-10 04:50:50,472 INFO org.apache.hadoop.yarn.server.resourcemanager.RMAuditLogger: USER=hduser	OPERATION=AM Allocated Container	TARGET=SchedulerApp	RESULT=SUCCESS	APPID=application_1560166913711_0002	CONTAINERID=container_1560166913711_0002_01_000004
2019-06-10 04:50:50,472 INFO org.apache.hadoop.yarn.server.resourcemanager.scheduler.SchedulerNode: Assigned container container_1560166913711_0002_01_000004 of capacity <memory:1024, vCores:1> on host ubuntu:43547, which has 4 containers, <memory:5120, vCores:4> used and <memory:3072, vCores:4> available after allocation
2019-06-10 04:50:50,473 INFO org.apache.hadoop.yarn.server.resourcemanager.scheduler.capacity.allocator.AbstractContainerAllocator: assignedContainer application attempt=appattempt_1560166913711_0002_000001 container=container_1560166913711_0002_01_000004 queue=org.apache.hadoop.yarn.server.resourcemanager.scheduler.capacity.allocator.RegularContainerAllocator@38b61cb4 clusterResource=<memory:8192, vCores:8> type=OFF_SWITCH requestedPartition=
2019-06-10 04:50:50,473 INFO org.apache.hadoop.yarn.server.resourcemanager.scheduler.capacity.ParentQueue: Re-sorting assigned queue: root.default stats: default: capacity=1.0, absoluteCapacity=1.0, usedResources=<memory:5120, vCores:4>, usedCapacity=0.625, absoluteUsedCapacity=0.625, numApps=1, numContainers=4
2019-06-10 04:50:50,473 INFO org.apache.hadoop.yarn.server.resourcemanager.scheduler.capacity.ParentQueue: assignedContainer queue=root usedCapacity=0.625 absoluteUsedCapacity=0.625 used=<memory:5120, vCores:4> cluster=<memory:8192, vCores:8>
2019-06-10 04:50:51,241 INFO org.apache.hadoop.yarn.server.resourcemanager.rmcontainer.RMContainerImpl: container_1560166913711_0002_01_000004 Container Transitioned from ALLOCATED to ACQUIRED
2019-06-10 04:50:51,457 INFO org.apache.hadoop.yarn.server.resourcemanager.rmcontainer.RMContainerImpl: container_1560166913711_0002_01_000004 Container Transitioned from ACQUIRED to RUNNING
2019-06-10 04:50:51,458 INFO org.apache.hadoop.yarn.server.resourcemanager.rmcontainer.RMContainerImpl: container_1560166913711_0002_01_000005 Container Transitioned from NEW to ALLOCATED
2019-06-10 04:50:51,458 INFO org.apache.hadoop.yarn.server.resourcemanager.RMAuditLogger: USER=hduser	OPERATION=AM Allocated Container	TARGET=SchedulerApp	RESULT=SUCCESS	APPID=application_1560166913711_0002	CONTAINERID=container_1560166913711_0002_01_000005
2019-06-10 04:50:51,458 INFO org.apache.hadoop.yarn.server.resourcemanager.scheduler.SchedulerNode: Assigned container container_1560166913711_0002_01_000005 of capacity <memory:1024, vCores:1> on host ubuntu:43547, which has 5 containers, <memory:6144, vCores:5> used and <memory:2048, vCores:3> available after allocation
2019-06-10 04:50:51,458 INFO org.apache.hadoop.yarn.server.resourcemanager.scheduler.capacity.allocator.AbstractContainerAllocator: assignedContainer application attempt=appattempt_1560166913711_0002_000001 container=container_1560166913711_0002_01_000005 queue=org.apache.hadoop.yarn.server.resourcemanager.scheduler.capacity.allocator.RegularContainerAllocator@38b61cb4 clusterResource=<memory:8192, vCores:8> type=OFF_SWITCH requestedPartition=
2019-06-10 04:50:51,460 INFO org.apache.hadoop.yarn.server.resourcemanager.scheduler.capacity.ParentQueue: Re-sorting assigned queue: root.default stats: default: capacity=1.0, absoluteCapacity=1.0, usedResources=<memory:6144, vCores:5>, usedCapacity=0.75, absoluteUsedCapacity=0.75, numApps=1, numContainers=5
2019-06-10 04:50:51,460 INFO org.apache.hadoop.yarn.server.resourcemanager.scheduler.capacity.ParentQueue: assignedContainer queue=root usedCapacity=0.75 absoluteUsedCapacity=0.75 used=<memory:6144, vCores:5> cluster=<memory:8192, vCores:8>
2019-06-10 04:50:52,256 INFO org.apache.hadoop.yarn.server.resourcemanager.rmcontainer.RMContainerImpl: container_1560166913711_0002_01_000005 Container Transitioned from ALLOCATED to ACQUIRED
2019-06-10 04:50:52,459 INFO org.apache.hadoop.yarn.server.resourcemanager.rmcontainer.RMContainerImpl: container_1560166913711_0002_01_000005 Container Transitioned from ACQUIRED to RUNNING
2019-06-10 04:50:52,461 INFO org.apache.hadoop.yarn.server.resourcemanager.rmcontainer.RMContainerImpl: container_1560166913711_0002_01_000006 Container Transitioned from NEW to ALLOCATED
2019-06-10 04:50:52,462 INFO org.apache.hadoop.yarn.server.resourcemanager.RMAuditLogger: USER=hduser	OPERATION=AM Allocated Container	TARGET=SchedulerApp	RESULT=SUCCESS	APPID=application_1560166913711_0002	CONTAINERID=container_1560166913711_0002_01_000006
2019-06-10 04:50:52,462 INFO org.apache.hadoop.yarn.server.resourcemanager.scheduler.SchedulerNode: Assigned container container_1560166913711_0002_01_000006 of capacity <memory:1024, vCores:1> on host ubuntu:43547, which has 6 containers, <memory:7168, vCores:6> used and <memory:1024, vCores:2> available after allocation
2019-06-10 04:50:52,462 INFO org.apache.hadoop.yarn.server.resourcemanager.scheduler.capacity.allocator.AbstractContainerAllocator: assignedContainer application attempt=appattempt_1560166913711_0002_000001 container=container_1560166913711_0002_01_000006 queue=org.apache.hadoop.yarn.server.resourcemanager.scheduler.capacity.allocator.RegularContainerAllocator@38b61cb4 clusterResource=<memory:8192, vCores:8> type=OFF_SWITCH requestedPartition=
2019-06-10 04:50:52,463 INFO org.apache.hadoop.yarn.server.resourcemanager.scheduler.capacity.ParentQueue: Re-sorting assigned queue: root.default stats: default: capacity=1.0, absoluteCapacity=1.0, usedResources=<memory:7168, vCores:6>, usedCapacity=0.875, absoluteUsedCapacity=0.875, numApps=1, numContainers=6
2019-06-10 04:50:52,463 INFO org.apache.hadoop.yarn.server.resourcemanager.scheduler.capacity.ParentQueue: assignedContainer queue=root usedCapacity=0.875 absoluteUsedCapacity=0.875 used=<memory:7168, vCores:6> cluster=<memory:8192, vCores:8>
2019-06-10 04:50:53,263 INFO org.apache.hadoop.yarn.server.resourcemanager.scheduler.AppSchedulingInfo: checking for deactivate of application :application_1560166913711_0002
2019-06-10 04:50:53,270 INFO org.apache.hadoop.yarn.server.resourcemanager.rmcontainer.RMContainerImpl: container_1560166913711_0002_01_000006 Container Transitioned from ALLOCATED to ACQUIRED
2019-06-10 04:50:54,281 INFO org.apache.hadoop.yarn.server.resourcemanager.rmcontainer.RMContainerImpl: container_1560166913711_0002_01_000006 Container Transitioned from ACQUIRED to RELEASED
2019-06-10 04:50:54,281 INFO org.apache.hadoop.yarn.server.resourcemanager.RMAuditLogger: USER=hduser	IP=127.0.0.1	OPERATION=AM Released Container	TARGET=SchedulerApp	RESULT=SUCCESS	APPID=application_1560166913711_0002	CONTAINERID=container_1560166913711_0002_01_000006
2019-06-10 04:50:54,281 INFO org.apache.hadoop.yarn.server.resourcemanager.scheduler.SchedulerNode: Released container container_1560166913711_0002_01_000006 of capacity <memory:1024, vCores:1> on host ubuntu:43547, which currently has 5 containers, <memory:6144, vCores:5> used and <memory:2048, vCores:3> available, release resources=true
2019-06-10 04:51:00,580 INFO org.apache.hadoop.yarn.server.resourcemanager.rmcontainer.RMContainerImpl: container_1560166913711_0002_01_000002 Container Transitioned from RUNNING to COMPLETED
2019-06-10 04:51:00,582 INFO org.apache.hadoop.yarn.server.resourcemanager.RMAuditLogger: USER=hduser	OPERATION=AM Released Container	TARGET=SchedulerApp	RESULT=SUCCESS	APPID=application_1560166913711_0002	CONTAINERID=container_1560166913711_0002_01_000002
2019-06-10 04:51:00,583 INFO org.apache.hadoop.yarn.server.resourcemanager.scheduler.SchedulerNode: Released container container_1560166913711_0002_01_000002 of capacity <memory:1024, vCores:1> on host ubuntu:43547, which currently has 4 containers, <memory:5120, vCores:4> used and <memory:3072, vCores:4> available, release resources=true
2019-06-10 04:51:01,287 INFO org.apache.hadoop.yarn.server.resourcemanager.rmcontainer.RMContainerImpl: container_1560166913711_0002_01_000003 Container Transitioned from RUNNING to COMPLETED
2019-06-10 04:51:01,288 INFO org.apache.hadoop.yarn.server.resourcemanager.RMAuditLogger: USER=hduser	OPERATION=AM Released Container	TARGET=SchedulerApp	RESULT=SUCCESS	APPID=application_1560166913711_0002	CONTAINERID=container_1560166913711_0002_01_000003
2019-06-10 04:51:01,288 INFO org.apache.hadoop.yarn.server.resourcemanager.scheduler.SchedulerNode: Released container container_1560166913711_0002_01_000003 of capacity <memory:1024, vCores:1> on host ubuntu:43547, which currently has 3 containers, <memory:4096, vCores:3> used and <memory:4096, vCores:5> available, release resources=true
2019-06-10 04:51:02,939 INFO org.apache.hadoop.yarn.server.resourcemanager.rmcontainer.RMContainerImpl: container_1560166913711_0002_01_000004 Container Transitioned from RUNNING to COMPLETED
2019-06-10 04:51:02,939 INFO org.apache.hadoop.yarn.server.resourcemanager.RMAuditLogger: USER=hduser	OPERATION=AM Released Container	TARGET=SchedulerApp	RESULT=SUCCESS	APPID=application_1560166913711_0002	CONTAINERID=container_1560166913711_0002_01_000004
2019-06-10 04:51:02,940 INFO org.apache.hadoop.yarn.server.resourcemanager.scheduler.SchedulerNode: Released container container_1560166913711_0002_01_000004 of capacity <memory:1024, vCores:1> on host ubuntu:43547, which currently has 2 containers, <memory:3072, vCores:2> used and <memory:5120, vCores:6> available, release resources=true
2019-06-10 04:51:03,181 INFO org.apache.hadoop.yarn.server.resourcemanager.rmapp.attempt.RMAppAttemptImpl: Updating application attempt appattempt_1560166913711_0002_000001 with final state: FINISHING, and exit status: -1000
2019-06-10 04:51:03,182 INFO org.apache.hadoop.yarn.server.resourcemanager.rmapp.attempt.RMAppAttemptImpl: appattempt_1560166913711_0002_000001 State change from RUNNING to FINAL_SAVING
2019-06-10 04:51:03,182 INFO org.apache.hadoop.yarn.server.resourcemanager.rmapp.RMAppImpl: Updating application application_1560166913711_0002 with final state: FINISHING
2019-06-10 04:51:03,186 INFO org.apache.hadoop.yarn.server.resourcemanager.recovery.RMStateStore: Updating info for app: application_1560166913711_0002
2019-06-10 04:51:03,186 INFO org.apache.hadoop.yarn.server.resourcemanager.rmapp.RMAppImpl: application_1560166913711_0002 State change from RUNNING to FINAL_SAVING on event=ATTEMPT_UNREGISTERED
2019-06-10 04:51:03,187 INFO org.apache.hadoop.yarn.server.resourcemanager.rmapp.attempt.RMAppAttemptImpl: appattempt_1560166913711_0002_000001 State change from FINAL_SAVING to FINISHING
2019-06-10 04:51:03,187 INFO org.apache.hadoop.yarn.server.resourcemanager.rmapp.RMAppImpl: application_1560166913711_0002 State change from FINAL_SAVING to FINISHING on event=APP_UPDATE_SAVED
2019-06-10 04:51:03,213 INFO org.apache.hadoop.yarn.server.resourcemanager.rmcontainer.RMContainerImpl: container_1560166913711_0002_01_000005 Container Transitioned from RUNNING to COMPLETED
2019-06-10 04:51:03,213 INFO org.apache.hadoop.yarn.server.resourcemanager.RMAuditLogger: USER=hduser	OPERATION=AM Released Container	TARGET=SchedulerApp	RESULT=SUCCESS	APPID=application_1560166913711_0002	CONTAINERID=container_1560166913711_0002_01_000005
2019-06-10 04:51:03,213 INFO org.apache.hadoop.yarn.server.resourcemanager.scheduler.SchedulerNode: Released container container_1560166913711_0002_01_000005 of capacity <memory:1024, vCores:1> on host ubuntu:43547, which currently has 1 containers, <memory:2048, vCores:1> used and <memory:6144, vCores:7> available, release resources=true
2019-06-10 04:51:04,192 INFO org.apache.hadoop.yarn.server.resourcemanager.ApplicationMasterService: application_1560166913711_0002 unregistered successfully. 
2019-06-10 04:51:09,718 INFO org.apache.hadoop.yarn.server.resourcemanager.rmcontainer.RMContainerImpl: container_1560166913711_0002_01_000001 Container Transitioned from RUNNING to COMPLETED
2019-06-10 04:51:09,718 INFO org.apache.hadoop.yarn.server.resourcemanager.RMAuditLogger: USER=hduser	OPERATION=AM Released Container	TARGET=SchedulerApp	RESULT=SUCCESS	APPID=application_1560166913711_0002	CONTAINERID=container_1560166913711_0002_01_000001
2019-06-10 04:51:09,718 INFO org.apache.hadoop.yarn.server.resourcemanager.scheduler.SchedulerNode: Released container container_1560166913711_0002_01_000001 of capacity <memory:2048, vCores:1> on host ubuntu:43547, which currently has 0 containers, <memory:0, vCores:0> used and <memory:8192, vCores:8> available, release resources=true
2019-06-10 04:51:09,719 INFO org.apache.hadoop.yarn.server.resourcemanager.ApplicationMasterService: Unregistering app attempt : appattempt_1560166913711_0002_000001
2019-06-10 04:51:09,719 INFO org.apache.hadoop.yarn.server.resourcemanager.security.AMRMTokenSecretManager: Application finished, removing password for appattempt_1560166913711_0002_000001
2019-06-10 04:51:09,719 INFO org.apache.hadoop.yarn.server.resourcemanager.rmapp.attempt.RMAppAttemptImpl: appattempt_1560166913711_0002_000001 State change from FINISHING to FINISHED
2019-06-10 04:51:09,720 INFO org.apache.hadoop.yarn.server.resourcemanager.rmapp.RMAppImpl: application_1560166913711_0002 State change from FINISHING to FINISHED on event=ATTEMPT_FINISHED
2019-06-10 04:51:09,720 INFO org.apache.hadoop.yarn.server.resourcemanager.scheduler.capacity.CapacityScheduler: Application Attempt appattempt_1560166913711_0002_000001 is done. finalState=FINISHED
2019-06-10 04:51:09,721 INFO org.apache.hadoop.yarn.server.resourcemanager.RMAuditLogger: USER=hduser	OPERATION=Application Finished - Succeeded	TARGET=RMAppManager	RESULT=SUCCESS	APPID=application_1560166913711_0002
2019-06-10 04:51:09,722 INFO org.apache.hadoop.yarn.server.resourcemanager.scheduler.AppSchedulingInfo: Application application_1560166913711_0002 requests cleared
2019-06-10 04:51:09,722 INFO org.apache.hadoop.yarn.server.resourcemanager.scheduler.capacity.LeafQueue: Application removed - appId: application_1560166913711_0002 user: hduser queue: default #user-pending-applications: 0 #user-active-applications: 0 #queue-pending-applications: 0 #queue-active-applications: 0
2019-06-10 04:51:09,723 INFO org.apache.hadoop.yarn.server.resourcemanager.scheduler.capacity.ParentQueue: Application removed - appId: application_1560166913711_0002 user: hduser leaf-queue of parent: root #applications: 0
2019-06-10 04:51:09,723 INFO org.apache.hadoop.yarn.server.resourcemanager.RMAppManager$ApplicationSummary: appId=application_1560166913711_0002,name=QueryResult.jar,user=hduser,queue=default,state=FINISHED,trackingUrl=http://ubuntu:8088/proxy/application_1560166913711_0002/,appMasterHost=ubuntu,startTime=1560167441306,finishTime=1560167463182,finalStatus=SUCCEEDED,memorySeconds=109153,vcoreSeconds=75,preemptedMemorySeconds=0,preemptedVcoreSeconds=0,preemptedAMContainers=0,preemptedNonAMContainers=0,preemptedResources=<memory:0\, vCores:0>,applicationType=MAPREDUCE
2019-06-10 04:51:09,723 INFO org.apache.hadoop.yarn.server.resourcemanager.amlauncher.AMLauncher: Cleaning master appattempt_1560166913711_0002_000001
2019-06-10 04:51:11,729 INFO org.apache.hadoop.yarn.server.resourcemanager.scheduler.AbstractYarnScheduler: Container container_1560166913711_0002_01_000004 completed with event FINISHED, but corresponding RMContainer doesn't exist.
2019-06-10 04:51:11,730 INFO org.apache.hadoop.yarn.server.resourcemanager.scheduler.AbstractYarnScheduler: Container container_1560166913711_0002_01_000005 completed with event FINISHED, but corresponding RMContainer doesn't exist.
2019-06-10 04:51:53,511 INFO org.apache.hadoop.yarn.server.resourcemanager.scheduler.AbstractYarnScheduler: Release request cache is cleaned up
